Workbook

Sheet COVER
B12: Narayan Dairy Project
B13: =TODAY()-5 -> 46208
B24: Financial Model Worksheet
B25: FY2026 – FY 2030

Sheet ASSUMPTIONS
A1: =COVER!$B$12 -> Narayan Dairy Project
A2: Assumptions
D4: Particular | E4: Worst | F4: Base | G4: Best | H4: Active | J4: Product | K4: Product Category | L4: Milk Allocation | N4: Scenario
D7: Scenario Control | J7: Fresh Milk Category | K7: Whole Milk | L7: 1 | N7: Best
D8: Capacity Ramp | E8: 0.8 | F8: 1 | G8: 1.2 | H8: =IF($N$7="Worst",E8,IF($N$7="Base",F8,G8)) -> 1.2 | J8: Procured Milk Category
D9: Revenue Realisation | E9: 0.95 | F9: 1 | G9: 1.08 | H9: =IF($N$7="Worst",E9,IF($N$7="Base",F9,G9)) -> 1.08 | J9: Yogurt | K9: Value-added dairy | L9: 0.1
D10: Installed Capacity | H10: =IF($N$7="Worst",E10,IF($N$7="Base",F10,G10)) | J10: Thandai | K10: Value-added dairy | L10: 0.2
D11: Installed Capacity | E11: 120000 | F11: 120000 | G11: 120000 | H11: =IF($N$7="Worst",E11,IF($N$7="Base",F11,G11)) -> 120000 | J11: A2 Powder & Ghee | K11: Premium products | L11: 0.2
D12: Effective Usable Capacity | E12: 90000 | F12: 100000 | G12: 110000 | H12: =IF($N$7="Worst",E12,IF($N$7="Base",F12,G12)) -> 110000 | J12: SMP & Butter | K12: Value-added dairy | L12: 0.1
D13: Downtime % | E13: 0.12 | F13: 0.08 | G13: 0.05 | H13: =IF($N$7="Worst",E13,IF($N$7="Base",F13,G13)) -> 0.05 | J13: Curd | K13: Value-added dairy | L13: 0.2
D14: Spoilage % | E14: 0.03 | F14: 0.02 | G14: 0.01 | H14: =IF($N$7="Worst",E14,IF($N$7="Base",F14,G14)) -> 0.01 | J14: Peda | K14: Premium products | L14: 0.2
D15: Utilisation Ramp
D16: M1 | E16: 10000 | F16: 15000 | G16: 20000 | H16: =IF($N$7="Worst",E16,IF($N$7="Base",F16,G16)) -> 20000 | J16: Product | K16: Conversion Ratios | L16: Packaging Cost
D17: M3 | E17: 22000 | F17: 30000 | G17: 40000 | H17: =IF($N$7="Worst",E17,IF($N$7="Base",F17,G17)) -> 40000 | J17: Fresh Milk Category | K17: 1 | L17: 0.04
D18: M6 | E18: 40000 | F18: 50000 | G18: 65000 | H18: =IF($N$7="Worst",E18,IF($N$7="Base",F18,G18)) -> 65000 | J18: Procured Milk Category
D19: M9 | E19: 55000 | F19: 65000 | G19: 80000 | H19: =IF($N$7="Worst",E19,IF($N$7="Base",F19,G19)) -> 80000 | J19: Yogurt | K19: 0.96 | L19: 0.06
D20: M12 | E20: 65000 | F20: 80000 | G20: 95000 | H20: =IF($N$7="Worst",E20,IF($N$7="Base",F20,G20)) -> 95000 | J20: Thandai | K20: 0.9 | L20: 0.08
D21: Procured Milk | J21: SMP | K21: 0.125 | L21: 0.03
D22: Procurement Inflation | E22: 0.08 | F22: 0.06 | G22: 0.04 | H22: =IF($N$7="Worst",E22,IF($N$7="Base",F22,G22)) -> 0.04 | J22: Butter | K22: 0.06 | L22: 0.04
D23: Milk Sourcing | H23: =IF($N$7="Worst",E23,IF($N$7="Base",F23,G23)) | J23: A2 Powder | K23: 0.0825 | L23: 0.05
D24: Own Milk | H24: =IF($N$7="Worst",E25,IF($N$7="Base",F24,G24)) | J24: Ghee | K24: 0.04 | L24: 0.05
D25: Volume litre per day per cow | E25: 18 | F25: 22 | G25: 32 | H25: =IF($N$7="Worst",E25,IF($N$7="Base",F25,G25)) -> 32 | J25: Curd | K25: 0.96 | L25: 0.05
D26: Cost per litre | E26: 24 | F26: 23 | G26: 22 | H26: =IF($N$7="Worst",E26,IF($N$7="Base",F26,G26)) -> 22 | J26: Peda | K26: 0.18 | L26: 0.07
D27: Feed Cost per Cow per Month | E27: 9000 | F27: 10000 | G27: 11000 | H27: =IF($N$7="Worst",E27,IF($N$7="Base",F27,G27)) -> 11000
D28: Pricing | H28: =IF($N$7="Worst",E28,IF($N$7="Base",F28,G28))
D29: MRP per litre | E29: 60 | F29: 63 | G29: 65 | H29: =IF($N$7="Worst",E29,IF($N$7="Base",F29,G29)) -> 65
D30: Distributor Margin | E30: 0.06 | F30: 0.08 | G30: 0.1 | H30: =IF($N$7="Worst",E30,IF($N$7="Base",F30,G30)) -> 0.1
D31: Retail Margin | E31: 0.12 | F31: 0.16 | G31: 0.2 | H31: =IF($N$7="Worst",E31,IF($N$7="Base",F31,G31)) -> 0.2
D32: Sales Returns / Wastage | E32: 0.02 | F32: 0.015 | G32: 0.01 | H32: =IF($N$7="Worst",E32,IF($N$7="Base",F32,G32)) -> 0.01
D33: Freight & Distribution of Revenue | E33: 0.03 | F33: 0.04 | G33: 0.07 | H33: =IF($N$7="Worst",E33,IF($N$7="Base",F33,G33)) -> 0.07
D34: Processing Cost | E34: 4 | F34: 3 | G34: 2.5 | H34: =IF($N$7="Worst",E34,IF($N$7="Base",F34,G34)) -> 2.5
D35: Cost Inflation
D36: Milk Procurement | E36: 0.08 | F36: 0.06 | G36: 0.04 | H36: =IF($N$7="Worst",E36,IF($N$7="Base",F36,G36)) -> 0.04
D37: Packaging | E37: 0.07 | F37: 0.05 | G37: 0.03 | H37: =IF($N$7="Worst",E37,IF($N$7="Base",F37,G37)) -> 0.03
D38: Feed | E38: 0.1 | F38: 0.08 | G38: 0.06 | H38: =IF($N$7="Worst",E38,IF($N$7="Base",F38,G38)) -> 0.06
D39: Salaries | E39: 0.12 | F39: 0.1 | G39: 0.08 | H39: =IF($N$7="Worst",E39,IF($N$7="Base",F39,G39)) -> 0.08
D40: Freight | E40: 0.09 | F40: 0.07 | G40: 0.05 | H40: =IF($N$7="Worst",E40,IF($N$7="Base",F40,G40)) -> 0.05
D41: Distribution | E41: Y1 | F41: Y2 | G41: Y3
D42: Distributors | E42: 15 | F42: 40 | G42: 75 | H42: =IF($N$7="Worst",E42,IF($N$7="Base",F42,G42)) -> 75
D43: Retail Outlets | E43: 500 | F43: 2000 | G43: 5000 | H43: =IF($N$7="Worst",E43,IF($N$7="Base",F43,G43)) -> 5000
...

Sheet FUNDING REQUIREMENT
A1: =COVER!$B$12 -> Narayan Dairy Project
A2: Funding Requirement
D4: Name | E4: Amount (₹)
D7: Part 1
D8: Land | E8: 50000000
D9: Baundary wall - 400/ Sqft* 28160 sqft | E9: 11264000
D10: Borwell & Water Testing | E10: 500000
D11: Shed Construction - 400/ Sqft* 28160 sqft | E11: 20000000
D12: Stamp Duty Advocate Fees & Pollution NOC | E12: 5000000
D13: Bank Deposit | E13: 2500000
D14: Leveling & Compressing | E14: 5000000
D15: Part 1 Total | E15: =SUM(E8:E14) -> 94264000
D16: Part 2
D17: Plant & Building (Civil Work) | E17: 28736000
D18: Machinery Advnace | E18: 30000000
D19: Cow Mat | E19: 2500000
D20: Livestock Purchase | E20: 22500000
D21: Solar System | E21: 13000000
D22: Trasportation Vechile | E22: 5000000
D23: Salary | E23: 1500000
D24: Feed | E24: 4500000
D25: Part 2 Total | E25: =SUM(E17:E24) -> 107736000
D26: Part 3
D27: Plant & Machinery Dileviring & Erection | E27: 70000000
D28: Appartment Cart | E28: 500000
D29: Livestock | E29: 22500000
D30: Trasportation Vechile | E30: 5000000
D31: Part 3 Total | E31: =SUM(E27:E30) -> 98000000
D32: Total | E32: =SUM(E15,E25,E31) -> 300000000

Sheet MILK FLOW ENGINE
A1: =COVER!$B$12 -> Narayan Dairy Project
A2: Milk Flow Engine
D4: Particulars / Month | E4: 1 | F4: =E4+1 -> 2 | G4: =F4+1 -> 3 | H4: =G4+1 -> 4 | I4: =H4+1 -> 5 | J4: =I4+1 -> 6 | K4: =J4+1 -> 7 | L4: =K4+1 -> 8 | M4: =L4+1 -> 9 | ... BL4: =BK4+1 -> 60
D7: Section A – Milk Input
D8: Own Livestock (units) | E8: =MIN(IF(E4 < 5, 0, IF(E4 = 5, 50, IF(E4 <=36, (D$8 + 50), (D$8 + 150)))), 2800) -> 0 | F8: =MIN(IF(F4 < 5, 0, IF(F4 = 5, 50, IF(F4 <=36, (E$8 + 50), (E$8 + 150)))), 2800) -> 0 | G8: =MIN(IF(G4 < 5, 0, IF(G4 = 5, 50, IF(G4 <=36, (F$8 + 50), (F$8 + 150)))), 2800) -> 0 | H8: =MIN(IF(H4 < 5, 0, IF(H4 = 5, 50, IF(H4 <=36, (G$8 + 50), (G$8 + 150)))), 2800) -> 0 | I8: =MIN(IF(I4 < 5, 0, IF(I4 = 5, 50, IF(I4 <=36, (H$8 + 50), (H$8 + 150)))), 2800) -> 50 | J8: =MIN(IF(J4 < 5, 0, IF(J4 = 5, 50, IF(J4 <=36, (I$8 + 50), (I$8 + 150)))), 2800) -> 100 | K8: =MIN(IF(K4 < 5, 0, IF(K4 = 5, 50, IF(K4 <=36, (J$8 + 50), (J$8 + 150)))), 2800) -> 150 | L8: =MIN(IF(L4 < 5, 0, IF(L4 = 5, 50, IF(L4 <=36, (K$8 + 50), (K$8 + 150)))), 2800) -> 200 | ... BL8: =MIN(IF(BL4 < 5, 0, IF(BL4 = 5, 50, IF(BL4 <=36, (BK$8 + 50), (BK$8 + 150)))), 2800) -> 2800
D9: Avg Yield per Cow per Day (litre) | E9: =ASSUMPTIONS!$H$25 -> 32 | F9: =ASSUMPTIONS!$H$25 -> 32 | G9: =ASSUMPTIONS!$H$25 -> 32 | H9: =ASSUMPTIONS!$H$25 -> 32 | I9: =ASSUMPTIONS!$H$25 -> 32 | J9: =ASSUMPTIONS!$H$25 -> 32 | K9: =ASSUMPTIONS!$H$25 -> 32 | L9: =ASSUMPTIONS!$H$25 -> 32 | ... BL9: =ASSUMPTIONS!$H$25 -> 32
D10: Own Milk Production (litre) | E10: =E8 * E9 * 30 -> 0 | F10: =F8 * F9 * 30 -> 0 | G10: =G8 * G9 * 30 -> 0 | H10: =H8 * H9 * 30 -> 0 | I10: =I8 * I9 * 30 -> 48000 | J10: =J8 * J9 * 30 -> 96000 | K10: =K8 * K9 * 30 -> 144000 | L10: =L8 * L9 * 30 -> 192000 | ... BL10: =BL8 * BL9 * 30 -> 2688000
D11: Procured Milk (litre) | E11: =IF( E$4 <= 6, 0, IF( E$4 <= 24, ASSUMPTIONS!$H$51, IF(E$4 <=36, ASSUMPTIONS!$H$52, ASSUMPTIONS!$H$53))) -> 0 | F11: =IF( F$4 <= 6, 0, IF( F$4 <= 24, ASSUMPTIONS!$H$51, IF(F$4 <=36, ASSUMPTIONS!$H$52, ASSUMPTIONS!$H$53))) -> 0 | G11: =IF( G$4 <= 6, 0, IF( G$4 <= 24, ASSUMPTIONS!$H$51, IF(G$4 <=36, ASSUMPTIONS!$H$52, ASSUMPTIONS!$H$53))) -> 0 | H11: =IF( H$4 <= 6, 0, IF( H$4 <= 24, ASSUMPTIONS!$H$51, IF(H$4 <=36, ASSUMPTIONS!$H$52, ASSUMPTIONS!$H$53))) -> 0 | I11: =IF( I$4 <= 6, 0, IF( I$4 <= 24, ASSUMPTIONS!$H$51, IF(I$4 <=36, ASSUMPTIONS!$H$52, ASSUMPTIONS!$H$53))) -> 0 | J11: =IF( J$4 <= 6, 0, IF( J$4 <= 24, ASSUMPTIONS!$H$51, IF(J$4 <=36, ASSUMPTIONS!$H$52, ASSUMPTIONS!$H$53))) -> 0 | K11: =IF( K$4 <= 6, 0, IF( K$4 <= 24, ASSUMPTIONS!$H$51, IF(K$4 <=36, ASSUMPTIONS!$H$52, ASSUMPTIONS!$H$53))) -> 150000 | L11: =IF( L$4 <= 6, 0, IF( L$4 <= 24, ASSUMPTIONS!$H$51, IF(L$4 <=36, ASSUMPTIONS!$H$52, ASSUMPTIONS!$H$53))) -> 150000 | ... BL11: =IF( BL$4 <= 6, 0, IF( BL$4 <= 24, ASSUMPTIONS!$H$51, IF(BL$4 <=36, ASSUMPTIONS!$H$52, ASSUMPTIONS!$H$53))) -> 900000
D12: Section B – Operational Losses
D13: Spoilage - Own Milk Production (litre) | E13: =E10 * ASSUMPTIONS!$H$14 -> 0 | F13: =F10 * ASSUMPTIONS!$H$14 -> 0 | G13: =G10 * ASSUMPTIONS!$H$14 -> 0 | H13: =H10 * ASSUMPTIONS!$H$14 -> 0 | I13: =I10 * ASSUMPTIONS!$H$14 -> 480 | J13: =J10 * ASSUMPTIONS!$H$14 -> 960 | K13: =K10 * ASSUMPTIONS!$H$14 -> 1440 | L13: =L10 * ASSUMPTIONS!$H$14 -> 1920 | ... BL13: =BL10 * ASSUMPTIONS!$H$14 -> 26880
D14: Total Own Milk Available (litre) | E14: =E10 - E13 -> 0 | F14: =F10 - F13 -> 0 | G14: =G10 - G13 -> 0 | H14: =H10 - H13 -> 0 | I14: =I10 - I13 -> 47520 | J14: =J10 - J13 -> 95040 | K14: =K10 - K13 -> 142560 | L14: =L10 - L13 -> 190080 | ... BL14: =BL10 - BL13 -> 2661120
D15: Processing Loss - Procured Milk (litre) | E15: =E11 * ASSUMPTIONS!$H$56 -> 0 | F15: =F11 * ASSUMPTIONS!$H$56 -> 0 | G15: =G11 * ASSUMPTIONS!$H$56 -> 0 | H15: =H11 * ASSUMPTIONS!$H$56 -> 0 | I15: =I11 * ASSUMPTIONS!$H$56 -> 0 | J15: =J11 * ASSUMPTIONS!$H$56 -> 0 | K15: =K11 * ASSUMPTIONS!$H$56 -> 7500 | L15: =L11 * ASSUMPTIONS!$H$56 -> 7500 | ... BL15: =BL11 * ASSUMPTIONS!$H$56 -> 45000
D16: Spoilage - Procured Milk (litre) | E16: =E11 * ASSUMPTIONS!$H$14 -> 0 | F16: =F11 * ASSUMPTIONS!$H$14 -> 0 | G16: =G11 * ASSUMPTIONS!$H$14 -> 0 | H16: =H11 * ASSUMPTIONS!$H$14 -> 0 | I16: =I11 * ASSUMPTIONS!$H$14 -> 0 | J16: =J11 * ASSUMPTIONS!$H$14 -> 0 | K16: =K11 * ASSUMPTIONS!$H$14 -> 1500 | L16: =L11 * ASSUMPTIONS!$H$14 -> 1500 | ... BL16: =BL11 * ASSUMPTIONS!$H$14 -> 9000
D17: Total Procured Milk Available (litre) | E17: =E11 - E15 - E16 -> 0 | F17: =F11 - F15 - F16 -> 0 | G17: =G11 - G15 - G16 -> 0 | H17: =H11 - H15 - H16 -> 0 | I17: =I11 - I15 - I16 -> 0 | J17: =J11 - J15 - J16 -> 0 | K17: =K11 - K15 - K16 -> 141000 | L17: =L11 - L15 - L16 -> 141000 | ... BL17: =BL11 - BL15 - BL16 -> 846000
D18: Section C – Product Allocation
D19: Fresh Milk | E19: =IF(E$4 <= 6, E$14, E$14) -> 0 | F19: =IF(F$4 <= 6, F$14, F$14) -> 0 | G19: =IF(G$4 <= 6, G$14, G$14) -> 0 | H19: =IF(H$4 <= 6, H$14, H$14) -> 0 | I19: =IF(I$4 <= 6, I$14, I$14) -> 47520 | J19: =IF(J$4 <= 6, J$14, J$14) -> 95040 | K19: =IF(K$4 <= 6, K$14, K$14) -> 142560 | L19: =IF(L$4 <= 6, L$14, L$14) -> 190080 | ... BL19: =IF(BL$4 <= 6, BL$14, BL$14) -> 2661120
D20: Yogurt | E20: =IF( E$4 <= 6, 0, E$17 * ASSUMPTIONS!$L$9) -> 0 | F20: =IF( F$4 <= 6, 0, F$17 * ASSUMPTIONS!$L$9) -> 0 | G20: =IF( G$4 <= 6, 0, G$17 * ASSUMPTIONS!$L$9) -> 0 | H20: =IF( H$4 <= 6, 0, H$17 * ASSUMPTIONS!$L$9) -> 0 | I20: =IF( I$4 <= 6, 0, I$17 * ASSUMPTIONS!$L$9) -> 0 | J20: =IF( J$4 <= 6, 0, J$17 * ASSUMPTIONS!$L$9) -> 0 | K20: =IF( K$4 <= 6, 0, K$17 * ASSUMPTIONS!$L$9) -> 14100 | L20: =IF( L$4 <= 6, 0, L$17 * ASSUMPTIONS!$L$9) -> 14100 | ... BL20: =IF( BL$4 <= 6, 0, BL$17 * ASSUMPTIONS!$L$9) -> 84600
D21: Thandai | E21: =IF( E$4 <= 6, 0, E$17 * ASSUMPTIONS!$L$10) -> 0 | F21: =IF( F$4 <= 6, 0, F$17 * ASSUMPTIONS!$L$10) -> 0 | G21: =IF( G$4 <= 6, 0, G$17 * ASSUMPTIONS!$L$10) -> 0 | H21: =IF( H$4 <= 6, 0, H$17 * ASSUMPTIONS!$L$10) -> 0 | I21: =IF( I$4 <= 6, 0, I$17 * ASSUMPTIONS!$L$10) -> 0 | J21: =IF( J$4 <= 6, 0, J$17 * ASSUMPTIONS!$L$10) -> 0 | K21: =IF( K$4 <= 6, 0, K$17 * ASSUMPTIONS!$L$10) -> 28200 | L21: =IF( L$4 <= 6, 0, L$17 * ASSUMPTIONS!$L$10) -> 28200 | ... BL21: =IF( BL$4 <= 6, 0, BL$17 * ASSUMPTIONS!$L$10) -> 169200
D22: SMP | E22: =IF( E$4 <= 6, 0, E$17 * ASSUMPTIONS!$L$12) -> 0 | F22: =IF( F$4 <= 6, 0, F$17 * ASSUMPTIONS!$L$12) -> 0 | G22: =IF( G$4 <= 6, 0, G$17 * ASSUMPTIONS!$L$12) -> 0 | H22: =IF( H$4 <= 6, 0, H$17 * ASSUMPTIONS!$L$12) -> 0 | I22: =IF( I$4 <= 6, 0, I$17 * ASSUMPTIONS!$L$12) -> 0 | J22: =IF( J$4 <= 6, 0, J$17 * ASSUMPTIONS!$L$12) -> 0 | K22: =IF( K$4 <= 6, 0, K$17 * ASSUMPTIONS!$L$12) -> 14100 | L22: =IF( L$4 <= 6, 0, L$17 * ASSUMPTIONS!$L$12) -> 14100 | ... BL22: =IF( BL$4 <= 6, 0, BL$17 * ASSUMPTIONS!$L$12) -> 84600
D23: Butter | E23: =IF( E$4 <= 6, 0, E$17 * ASSUMPTIONS!$L$12) -> 0 | F23: =IF( F$4 <= 6, 0, F$17 * ASSUMPTIONS!$L$12) -> 0 | G23: =IF( G$4 <= 6, 0, G$17 * ASSUMPTIONS!$L$12) -> 0 | H23: =IF( H$4 <= 6, 0, H$17 * ASSUMPTIONS!$L$12) -> 0 | I23: =IF( I$4 <= 6, 0, I$17 * ASSUMPTIONS!$L$12) -> 0 | J23: =IF( J$4 <= 6, 0, J$17 * ASSUMPTIONS!$L$12) -> 0 | K23: =IF( K$4 <= 6, 0, K$17 * ASSUMPTIONS!$L$12) -> 14100 | L23: =IF( L$4 <= 6, 0, L$17 * ASSUMPTIONS!$L$12) -> 14100 | ... BL23: =IF( BL$4 <= 6, 0, BL$17 * ASSUMPTIONS!$L$12) -> 84600
D24: A2 | E24: =IF( E$4 <= 6, 0, E$17 * ASSUMPTIONS!$L$11) -> 0 | F24: =IF( F$4 <= 6, 0, F$17 * ASSUMPTIONS!$L$11) -> 0 | G24: =IF( G$4 <= 6, 0, G$17 * ASSUMPTIONS!$L$11) -> 0 | H24: =IF( H$4 <= 6, 0, H$17 * ASSUMPTIONS!$L$11) -> 0 | I24: =IF( I$4 <= 6, 0, I$17 * ASSUMPTIONS!$L$11) -> 0 | J24: =IF( J$4 <= 6, 0, J$17 * ASSUMPTIONS!$L$11) -> 0 | K24: =IF( K$4 <= 6, 0, K$17 * ASSUMPTIONS!$L$11) -> 28200 | L24: =IF( L$4 <= 6, 0, L$17 * ASSUMPTIONS!$L$11) -> 28200 | ... BL24: =IF( BL$4 <= 6, 0, BL$17 * ASSUMPTIONS!$L$11) -> 169200
D25: Ghee | E25: =IF( E$4 <= 6, 0, E$17 * ASSUMPTIONS!$L$11) -> 0 | F25: =IF( F$4 <= 6, 0, F$17 * ASSUMPTIONS!$L$11) -> 0 | G25: =IF( G$4 <= 6, 0, G$17 * ASSUMPTIONS!$L$11) -> 0 | H25: =IF( H$4 <= 6, 0, H$17 * ASSUMPTIONS!$L$11) -> 0 | I25: =IF( I$4 <= 6, 0, I$17 * ASSUMPTIONS!$L$11) -> 0 | J25: =IF( J$4 <= 6, 0, J$17 * ASSUMPTIONS!$L$11) -> 0 | K25: =IF( K$4 <= 6, 0, K$17 * ASSUMPTIONS!$L$11) -> 28200 | L25: =IF( L$4 <= 6, 0, L$17 * ASSUMPTIONS!$L$11) -> 28200 | ... BL25: =IF( BL$4 <= 6, 0, BL$17 * ASSUMPTIONS!$L$11) -> 169200
D26: Curd | E26: =IF( E$4 <= 6, 0, E$17 * ASSUMPTIONS!$L$13) -> 0 | F26: =IF( F$4 <= 6, 0, F$17 * ASSUMPTIONS!$L$13) -> 0 | G26: =IF( G$4 <= 6, 0, G$17 * ASSUMPTIONS!$L$13) -> 0 | H26: =IF( H$4 <= 6, 0, H$17 * ASSUMPTIONS!$L$13) -> 0 | I26: =IF( I$4 <= 6, 0, I$17 * ASSUMPTIONS!$L$13) -> 0 | J26: =IF( J$4 <= 6, 0, J$17 * ASSUMPTIONS!$L$13) -> 0 | K26: =IF( K$4 <= 6, 0, K$17 * ASSUMPTIONS!$L$13) -> 28200 | L26: =IF( L$4 <= 6, 0, L$17 * ASSUMPTIONS!$L$13) -> 28200 | ... BL26: =IF( BL$4 <= 6, 0, BL$17 * ASSUMPTIONS!$L$13) -> 169200
D27: Peda | E27: =IF( E$4 <= 6, 0, E$17 * ASSUMPTIONS!$L$14) -> 0 | F27: =IF( F$4 <= 6, 0, F$17 * ASSUMPTIONS!$L$14) -> 0 | G27: =IF( G$4 <= 6, 0, G$17 * ASSUMPTIONS!$L$14) -> 0 | H27: =IF( H$4 <= 6, 0, H$17 * ASSUMPTIONS!$L$14) -> 0 | I27: =IF( I$4 <= 6, 0, I$17 * ASSUMPTIONS!$L$14) -> 0 | J27: =IF( J$4 <= 6, 0, J$17 * ASSUMPTIONS!$L$14) -> 0 | K27: =IF( K$4 <= 6, 0, K$17 * ASSUMPTIONS!$L$14) -> 28200 | L27: =IF( L$4 <= 6, 0, L$17 * ASSUMPTIONS!$L$14) -> 28200 | ... BL27: =IF( BL$4 <= 6, 0, BL$17 * ASSUMPTIONS!$L$14) -> 169200
D28: Section C – Conversion Engine
D29: Fresh Milk | E29: =E19 * ASSUMPTIONS!$K$17 -> 0 | F29: =F19 * ASSUMPTIONS!$K$17 -> 0 | G29: =G19 * ASSUMPTIONS!$K$17 -> 0 | H29: =H19 * ASSUMPTIONS!$K$17 -> 0 | I29: =I19 * ASSUMPTIONS!$K$17 -> 47520 | J29: =J19 * ASSUMPTIONS!$K$17 -> 95040 | K29: =K19 * ASSUMPTIONS!$K$17 -> 142560 | L29: =L19 * ASSUMPTIONS!$K$17 -> 190080 | ... BL29: =BL19 * ASSUMPTIONS!$K$17 -> 2661120
D30: Yogurt | E30: =E20 * ASSUMPTIONS!$K$19 -> 0 | F30: =F20 * ASSUMPTIONS!$K$19 -> 0 | G30: =G20 * ASSUMPTIONS!$K$19 -> 0 | H30: =H20 * ASSUMPTIONS!$K$19 -> 0 | I30: =I20 * ASSUMPTIONS!$K$19 -> 0 | J30: =J20 * ASSUMPTIONS!$K$19 -> 0 | K30: =K20 * ASSUMPTIONS!$K$19 -> 13536 | L30: =L20 * ASSUMPTIONS!$K$19 -> 13536 | ... BL30: =BL20 * ASSUMPTIONS!$K$19 -> 81216
D31: Thandai | E31: =E21 * ASSUMPTIONS!$K$20 -> 0 | F31: =F21 * ASSUMPTIONS!$K$20 -> 0 | G31: =G21 * ASSUMPTIONS!$K$20 -> 0 | H31: =H21 * ASSUMPTIONS!$K$20 -> 0 | I31: =I21 * ASSUMPTIONS!$K$20 -> 0 | J31: =J21 * ASSUMPTIONS!$K$20 -> 0 | K31: =K21 * ASSUMPTIONS!$K$20 -> 25380 | L31: =L21 * ASSUMPTIONS!$K$20 -> 25380 | ... BL31: =BL21 * ASSUMPTIONS!$K$20 -> 152280
D32: SMP | E32: =E22 * ASSUMPTIONS!$K$21 -> 0 | F32: =F22 * ASSUMPTIONS!$K$21 -> 0 | G32: =G22 * ASSUMPTIONS!$K$21 -> 0 | H32: =H22 * ASSUMPTIONS!$K$21 -> 0 | I32: =I22 * ASSUMPTIONS!$K$21 -> 0 | J32: =J22 * ASSUMPTIONS!$K$21 -> 0 | K32: =K22 * ASSUMPTIONS!$K$21 -> 1762.5 | L32: =L22 * ASSUMPTIONS!$K$21 -> 1762.5 | ... BL32: =BL22 * ASSUMPTIONS!$K$21 -> 10575
D33: Butter | E33: =E23 * ASSUMPTIONS!$K$22 -> 0 | F33: =F23 * ASSUMPTIONS!$K$22 -> 0 | G33: =G23 * ASSUMPTIONS!$K$22 -> 0 | H33: =H23 * ASSUMPTIONS!$K$22 -> 0 | I33: =I23 * ASSUMPTIONS!$K$22 -> 0 | J33: =J23 * ASSUMPTIONS!$K$22 -> 0 | K33: =K23 * ASSUMPTIONS!$K$22 -> 846 | L33: =L23 * ASSUMPTIONS!$K$22 -> 846 | ... BL33: =BL23 * ASSUMPTIONS!$K$22 -> 5076
D34: A2 | E34: =E24 * ASSUMPTIONS!$K$23 -> 0 | F34: =F24 * ASSUMPTIONS!$K$23 -> 0 | G34: =G24 * ASSUMPTIONS!$K$23 -> 0 | H34: =H24 * ASSUMPTIONS!$K$23 -> 0 | I34: =I24 * ASSUMPTIONS!$K$23 -> 0 | J34: =J24 * ASSUMPTIONS!$K$23 -> 0 | K34: =K24 * ASSUMPTIONS!$K$23 -> 2326.5 | L34: =L24 * ASSUMPTIONS!$K$23 -> 2326.5 | ... BL34: =BL24 * ASSUMPTIONS!$K$23 -> 13959
D35: Ghee | E35: =E25 * ASSUMPTIONS!$K$24 -> 0 | F35: =F25 * ASSUMPTIONS!$K$24 -> 0 | G35: =G25 * ASSUMPTIONS!$K$24 -> 0 | H35: =H25 * ASSUMPTIONS!$K$24 -> 0 | I35: =I25 * ASSUMPTIONS!$K$24 -> 0 | J35: =J25 * ASSUMPTIONS!$K$24 -> 0 | K35: =K25 * ASSUMPTIONS!$K$24 -> 1128 | L35: =L25 * ASSUMPTIONS!$K$24 -> 1128 | ... BL35: =BL25 * ASSUMPTIONS!$K$24 -> 6768
D36: Curd | E36: =E26 * ASSUMPTIONS!$K$25 -> 0 | F36: =F26 * ASSUMPTIONS!$K$25 -> 0 | G36: =G26 * ASSUMPTIONS!$K$25 -> 0 | H36: =H26 * ASSUMPTIONS!$K$25 -> 0 | I36: =I26 * ASSUMPTIONS!$K$25 -> 0 | J36: =J26 * ASSUMPTIONS!$K$25 -> 0 | K36: =K26 * ASSUMPTIONS!$K$25 -> 27072 | L36: =L26 * ASSUMPTIONS!$K$25 -> 27072 | ... BL36: =BL26 * ASSUMPTIONS!$K$25 -> 162432
D37: Peda | E37: =E27 * ASSUMPTIONS!$K$26 -> 0 | F37: =F27 * ASSUMPTIONS!$K$26 -> 0 | G37: =G27 * ASSUMPTIONS!$K$26 -> 0 | H37: =H27 * ASSUMPTIONS!$K$26 -> 0 | I37: =I27 * ASSUMPTIONS!$K$26 -> 0 | J37: =J27 * ASSUMPTIONS!$K$26 -> 0 | K37: =K27 * ASSUMPTIONS!$K$26 -> 5076 | L37: =L27 * ASSUMPTIONS!$K$26 -> 5076 | ... BL37: =BL27 * ASSUMPTIONS!$K$26 -> 30456

Sheet PRODUCT PRICING & REVENUE ENGIN
A1: =COVER!$B$12 -> Narayan Dairy Project
A2: Product Pricing & Revenue Engine
D4: Product | E4: Unit | F4: MRP | G4: Distributor Margin | H4: Retail Margin | I4: Wholesale Rate
D7: Section A – Product Master
D8: Fresh Milk | E8: Per Litre | F8: 65 | G8: 0.08 | H8: 0.16 | I8: =F8 * (1 - G8) * (1 - H8) -> 50.232
D9: Yogurt | E9: Per Kg | F9: 150 | G9: 0.1 | H9: 0.2 | I9: =F9 * (1 - G9) * (1 - H9) -> 108
D10: Thandai | E10: Per Litre | F10: 160 | G10: 0.1 | H10: 0.2 | I10: =F10 * (1 - G10) * (1 - H10) -> 115.2
D11: SMP | E11: Per Kg | F11: 320 | G11: 0.05 | H11: 0.1 | I11: =F11 * (1 - G11) * (1 - H11) -> 273.6
D12: Butter | E12: Per Kg | F12: 600 | G12: 0.06 | H12: 0.14 | I12: =F12 * (1 - G12) * (1 - H12) -> 485.04
D13: A2 Powder | E13: Per Kg | F13: 1200 | G13: 0.08 | H13: 0.18 | I13: =F13 * (1 - G13) * (1 - H13) -> 905.28
D14: Ghee | E14: Per Litre | F14: 900 | G14: 0.08 | H14: 0.18 | I14: =F14 * (1 - G14) * (1 - H14) -> 678.96
D15: Curd | E15: Per Kg | F15: 100 | G15: 0.08 | H15: 0.18 | I15: =F15 * (1 - G15) * (1 - H15) -> 75.44
D16: Peda | E16: Per Kg | F16: 600 | G16: 0.1 | H16: 0.2 | I16: =F16 * (1 - G16) * (1 - H16) -> 432
D18: Product / Year | E18: 1 | F18: 2 | G18: 3 | H18: 4 | I18: 5
D21: Section A – Price Escalation Factor Schedule
D22: Fresh Milk | E22: =1 -> 1 | F22: =E22 * (1 + ASSUMPTIONS!$E$56) -> 1.03 | G22: =F22 * (1 + ASSUMPTIONS!$E$56) -> 1.0609 | H22: =G22 * (1 + ASSUMPTIONS!$E$56) -> 1.092727 | I22: =H22 * (1 + ASSUMPTIONS!$E$56) -> 1.1255088
D23: Yogurt | E23: =1 -> 1 | F23: =E23 * ( 1 + ASSUMPTIONS!$E$57) -> 1.05 | G23: =F23 * ( 1 + ASSUMPTIONS!$E$57) -> 1.1025 | H23: =G23 * ( 1 + ASSUMPTIONS!$E$57) -> 1.157625 | I23: =H23 * ( 1 + ASSUMPTIONS!$E$57) -> 1.2155063
D24: Thandai | E24: =1 -> 1 | F24: =E24 * ( 1 + ASSUMPTIONS!$E$57) -> 1.05 | G24: =F24 * ( 1 + ASSUMPTIONS!$E$57) -> 1.1025 | H24: =G24 * ( 1 + ASSUMPTIONS!$E$57) -> 1.157625 | I24: =H24 * ( 1 + ASSUMPTIONS!$E$57) -> 1.2155063
D25: SMP | E25: =1 -> 1 | F25: =E25 * ( 1 + ASSUMPTIONS!$E$58) -> 1.06 | G25: =F25 * ( 1 + ASSUMPTIONS!$E$58) -> 1.1236 | H25: =G25 * ( 1 + ASSUMPTIONS!$E$58) -> 1.191016 | I25: =H25 * ( 1 + ASSUMPTIONS!$E$58) -> 1.262477
D26: Butter | E26: =1 -> 1 | F26: =E26 * ( 1 + ASSUMPTIONS!$E$57) -> 1.05 | G26: =F26 * ( 1 + ASSUMPTIONS!$E$57) -> 1.1025 | H26: =G26 * ( 1 + ASSUMPTIONS!$E$57) -> 1.157625 | I26: =H26 * ( 1 + ASSUMPTIONS!$E$57) -> 1.2155063
D27: A2 Powder | E27: =1 -> 1 | F27: =E27 * ( 1 + ASSUMPTIONS!$E$58) -> 1.06 | G27: =F27 * ( 1 + ASSUMPTIONS!$E$58) -> 1.1236 | H27: =G27 * ( 1 + ASSUMPTIONS!$E$58) -> 1.191016 | I27: =H27 * ( 1 + ASSUMPTIONS!$E$58) -> 1.262477
D28: Ghee | E28: =1 -> 1 | F28: =E28 * ( 1 + ASSUMPTIONS!$E$57) -> 1.05 | G28: =F28 * ( 1 + ASSUMPTIONS!$E$57) -> 1.1025 | H28: =G28 * ( 1 + ASSUMPTIONS!$E$57) -> 1.157625 | I28: =H28 * ( 1 + ASSUMPTIONS!$E$57) -> 1.2155063
D29: Curd | E29: =1 -> 1 | F29: =E29 * ( 1 + ASSUMPTIONS!$E$57) -> 1.05 | G29: =F29 * ( 1 + ASSUMPTIONS!$E$57) -> 1.1025 | H29: =G29 * ( 1 + ASSUMPTIONS!$E$57) -> 1.157625 | I29: =H29 * ( 1 + ASSUMPTIONS!$E$57) -> 1.2155063
D30: Peda | E30: =1 -> 1 | F30: =E30 * ( 1 + ASSUMPTIONS!$E$58) -> 1.06 | G30: =F30 * ( 1 + ASSUMPTIONS!$E$58) -> 1.1236 | H30: =G30 * ( 1 + ASSUMPTIONS!$E$58) -> 1.191016 | I30: =H30 * ( 1 + ASSUMPTIONS!$E$58) -> 1.262477
D33: Product / Month / Year | E33: 1 | F33: =E33+1 -> 2 | G33: =F33+1 -> 3 | H33: =G33+1 -> 4 | I33: =H33+1 -> 5 | J33: =I33+1 -> 6 | K33: =J33+1 -> 7 | L33: =K33+1 -> 8 | M33: =L33+1 -> 9 | ... BL33: =BK33+1 -> 60
E36: =INT((E33-1)/12)+1 -> 1 | F36: =INT((F33-1)/12)+1 -> 1 | G36: =INT((G33-1)/12)+1 -> 1 | H36: =INT((H33-1)/12)+1 -> 1 | I36: =INT((I33-1)/12)+1 -> 1 | J36: =INT((J33-1)/12)+1 -> 1 | K36: =INT((K33-1)/12)+1 -> 1 | L36: =INT((L33-1)/12)+1 -> 1 | ... BL36: =INT((BL33-1)/12)+1 -> 5
D38: Section B – Sellable Quantity
D39: Fresh Milk | E39: ='MILK FLOW ENGINE'!E29 -> 0 | F39: ='MILK FLOW ENGINE'!F29 -> 0 | G39: ='MILK FLOW ENGINE'!G29 -> 0 | H39: ='MILK FLOW ENGINE'!H29 -> 0 | I39: ='MILK FLOW ENGINE'!I29 -> 47520 | J39: ='MILK FLOW ENGINE'!J29 -> 95040 | K39: ='MILK FLOW ENGINE'!K29 -> 142560 | L39: ='MILK FLOW ENGINE'!L29 -> 190080 | ... BL39: ='MILK FLOW ENGINE'!BL29 -> 2661120
D40: Yogurt | E40: ='MILK FLOW ENGINE'!E30 -> 0 | F40: ='MILK FLOW ENGINE'!F30 -> 0 | G40: ='MILK FLOW ENGINE'!G30 -> 0 | H40: ='MILK FLOW ENGINE'!H30 -> 0 | I40: ='MILK FLOW ENGINE'!I30 -> 0 | J40: ='MILK FLOW ENGINE'!J30 -> 0 | K40: ='MILK FLOW ENGINE'!K30 -> 13536 | L40: ='MILK FLOW ENGINE'!L30 -> 13536 | ... BL40: ='MILK FLOW ENGINE'!BL30 -> 81216
D41: Thandai | E41: ='MILK FLOW ENGINE'!E31 -> 0 | F41: ='MILK FLOW ENGINE'!F31 -> 0 | G41: ='MILK FLOW ENGINE'!G31 -> 0 | H41: ='MILK FLOW ENGINE'!H31 -> 0 | I41: ='MILK FLOW ENGINE'!I31 -> 0 | J41: ='MILK FLOW ENGINE'!J31 -> 0 | K41: ='MILK FLOW ENGINE'!K31 -> 25380 | L41: ='MILK FLOW ENGINE'!L31 -> 25380 | ... BL41: ='MILK FLOW ENGINE'!BL31 -> 152280
D42: SMP | E42: ='MILK FLOW ENGINE'!E32 -> 0 | F42: ='MILK FLOW ENGINE'!F32 -> 0 | G42: ='MILK FLOW ENGINE'!G32 -> 0 | H42: ='MILK FLOW ENGINE'!H32 -> 0 | I42: ='MILK FLOW ENGINE'!I32 -> 0 | J42: ='MILK FLOW ENGINE'!J32 -> 0 | K42: ='MILK FLOW ENGINE'!K32 -> 1762.5 | L42: ='MILK FLOW ENGINE'!L32 -> 1762.5 | ... BL42: ='MILK FLOW ENGINE'!BL32 -> 10575
D43: Butter | E43: ='MILK FLOW ENGINE'!E33 -> 0 | F43: ='MILK FLOW ENGINE'!F33 -> 0 | G43: ='MILK FLOW ENGINE'!G33 -> 0 | H43: ='MILK FLOW ENGINE'!H33 -> 0 | I43: ='MILK FLOW ENGINE'!I33 -> 0 | J43: ='MILK FLOW ENGINE'!J33 -> 0 | K43: ='MILK FLOW ENGINE'!K33 -> 846 | L43: ='MILK FLOW ENGINE'!L33 -> 846 | ... BL43: ='MILK FLOW ENGINE'!BL33 -> 5076
D44: A2 Powder | E44: ='MILK FLOW ENGINE'!E34 -> 0 | F44: ='MILK FLOW ENGINE'!F34 -> 0 | G44: ='MILK FLOW ENGINE'!G34 -> 0 | H44: ='MILK FLOW ENGINE'!H34 -> 0 | I44: ='MILK FLOW ENGINE'!I34 -> 0 | J44: ='MILK FLOW ENGINE'!J34 -> 0 | K44: ='MILK FLOW ENGINE'!K34 -> 2326.5 | L44: ='MILK FLOW ENGINE'!L34 -> 2326.5 | ... BL44: ='MILK FLOW ENGINE'!BL34 -> 13959
D45: Ghee | E45: ='MILK FLOW ENGINE'!E35 -> 0 | F45: ='MILK FLOW ENGINE'!F35 -> 0 | G45: ='MILK FLOW ENGINE'!G35 -> 0 | H45: ='MILK FLOW ENGINE'!H35 -> 0 | I45: ='MILK FLOW ENGINE'!I35 -> 0 | J45: ='MILK FLOW ENGINE'!J35 -> 0 | K45: ='MILK FLOW ENGINE'!K35 -> 1128 | L45: ='MILK FLOW ENGINE'!L35 -> 1128 | ... BL45: ='MILK FLOW ENGINE'!BL35 -> 6768
D46: Curd | E46: ='MILK FLOW ENGINE'!E36 -> 0 | F46: ='MILK FLOW ENGINE'!F36 -> 0 | G46: ='MILK FLOW ENGINE'!G36 -> 0 | H46: ='MILK FLOW ENGINE'!H36 -> 0 | I46: ='MILK FLOW ENGINE'!I36 -> 0 | J46: ='MILK FLOW ENGINE'!J36 -> 0 | K46: ='MILK FLOW ENGINE'!K36 -> 27072 | L46: ='MILK FLOW ENGINE'!L36 -> 27072 | ... BL46: ='MILK FLOW ENGINE'!BL36 -> 162432
D47: Peda | E47: ='MILK FLOW ENGINE'!E37 -> 0 | F47: ='MILK FLOW ENGINE'!F37 -> 0 | G47: ='MILK FLOW ENGINE'!G37 -> 0 | H47: ='MILK FLOW ENGINE'!H37 -> 0 | I47: ='MILK FLOW ENGINE'!I37 -> 0 | J47: ='MILK FLOW ENGINE'!J37 -> 0 | K47: ='MILK FLOW ENGINE'!K37 -> 5076 | L47: ='MILK FLOW ENGINE'!L37 -> 5076 | ... BL47: ='MILK FLOW ENGINE'!BL37 -> 30456
D48: Section C – Revenue
D49: Fresh Milk | E49: {=IFS(AND(E$36 = $E$18, E$36 =ASSUMPTIONS!$E$60), $E22 * E39 * ((ASSUMPTIONS!$E$63 * $I8) + (ASSUMPTIONS!$E$64 * $F8)), AND(E$36 = $F$18, E$36 =ASSUMPTIONS!$F$60), $F22 * E39 * ((ASSUMPTIONS!$F$63 * $I8) + (ASSUMPTIONS!$F$64 * $F8)), AND(E$36 = $G$18, E$36 =ASSUMPTIONS!$G$60), $G22 * E39 * ((ASSUMPTIONS!$G$63 * $I8) + (ASSUMPTIONS!$G$64 * $F8)), AND(E$36 = $H$18, E$36 =ASSUMPTIONS!$H$60), $H22 * E39 * ((ASSUMPTIONS!$H$63 * $I8) + (ASSUMPTIONS!$H$64 * $F8)), TRUE, $I22 *E39 * ((ASSUMPTIONS!$I$63 * $I8) + (ASSUMPTIONS!$I$64 * $F8)) )} -> 0 | F49: {=IFS(AND(F$36 = $E$18, F$36 =ASSUMPTIONS!$E$60), $E22 * F39 * ((ASSUMPTIONS!$E$63 * $I8) + (ASSUMPTIONS!$E$64 * $F8)), AND(F$36 = $F$18, F$36 =ASSUMPTIONS!$F$60), $F22 * F39 * ((ASSUMPTIONS!$F$63 * $I8) + (ASSUMPTIONS!$F$64 * $F8)), AND(F$36 = $G$18, F$36 =ASSUMPTIONS!$G$60), $G22 * F39 * ((ASSUMPTIONS!$G$63 * $I8) + (ASSUMPTIONS!$G$64 * $F8)), AND(F$36 = $H$18, F$36 =ASSUMPTIONS!$H$60), $H22 * F39 * ((ASSUMPTIONS!$H$63 * $I8) + (ASSUMPTIONS!$H$64 * $F8)), TRUE, $I22 *F39 * ((ASSUMPTIONS!$I$63 * $I8) + (ASSUMPTIONS!$I$64 * $F8)) )} -> 0 | G49: {=IFS(AND(G$36 = $E$18, G$36 =ASSUMPTIONS!$E$60), $E22 * G39 * ((ASSUMPTIONS!$E$63 * $I8) + (ASSUMPTIONS!$E$64 * $F8)), AND(G$36 = $F$18, G$36 =ASSUMPTIONS!$F$60), $F22 * G39 * ((ASSUMPTIONS!$F$63 * $I8) + (ASSUMPTIONS!$F$64 * $F8)), AND(G$36 = $G$18, G$36 =ASSUMPTIONS!$G$60), $G22 * G39 * ((ASSUMPTIONS!$G$63 * $I8) + (ASSUMPTIONS!$G$64 * $F8)), AND(G$36 = $H$18, G$36 =ASSUMPTIONS!$H$60), $H22 * G39 * ((ASSUMPTIONS!$H$63 * $I8) + (ASSUMPTIONS!$H$64 * $F8)), TRUE, $I22 *G39 * ((ASSUMPTIONS!$I$63 * $I8) + (ASSUMPTIONS!$I$64 * $F8)) )} -> 0 | H49: {=IFS(AND(H$36 = $E$18, H$36 =ASSUMPTIONS!$E$60), $E22 * H39 * ((ASSUMPTIONS!$E$63 * $I8) + (ASSUMPTIONS!$E$64 * $F8)), AND(H$36 = $F$18, H$36 =ASSUMPTIONS!$F$60), $F22 * H39 * ((ASSUMPTIONS!$F$63 * $I8) + (ASSUMPTIONS!$F$64 * $F8)), AND(H$36 = $G$18, H$36 =ASSUMPTIONS!$G$60), $G22 * H39 * ((ASSUMPTIONS!$G$63 * $I8) + (ASSUMPTIONS!$G$64 * $F8)), AND(H$36 = $H$18, H$36 =ASSUMPTIONS!$H$60), $H22 * H39 * ((ASSUMPTIONS!$H$63 * $I8) + (ASSUMPTIONS!$H$64 * $F8)), TRUE, $I22 *H39 * ((ASSUMPTIONS!$I$63 * $I8) + (ASSUMPTIONS!$I$64 * $F8)) )} -> 0 | I49: {=IFS(AND(I$36 = $E$18, I$36 =ASSUMPTIONS!$E$60), $E22 * I39 * ((ASSUMPTIONS!$E$63 * $I8) + (ASSUMPTIONS!$E$64 * $F8)), AND(I$36 = $F$18, I$36 =ASSUMPTIONS!$F$60), $F22 * I39 * ((ASSUMPTIONS!$F$63 * $I8) + (ASSUMPTIONS!$F$64 * $F8)), AND(I$36 = $G$18, I$36 =ASSUMPTIONS!$G$60), $G22 * I39 * ((ASSUMPTIONS!$G$63 * $I8) + (ASSUMPTIONS!$G$64 * $F8)), AND(I$36 = $H$18, I$36 =ASSUMPTIONS!$H$60), $H22 * I39 * ((ASSUMPTIONS!$H$63 * $I8) + (ASSUMPTIONS!$H$64 * $F8)), TRUE, $I22 *I39 * ((ASSUMPTIONS!$I$63 * $I8) + (ASSUMPTIONS!$I$64 * $F8)) )} -> 2387024.6 | J49: {=IFS(AND(J$36 = $E$18, J$36 =ASSUMPTIONS!$E$60), $E22 * J39 * ((ASSUMPTIONS!$E$63 * $I8) + (ASSUMPTIONS!$E$64 * $F8)), AND(J$36 = $F$18, J$36 =ASSUMPTIONS!$F$60), $F22 * J39 * ((ASSUMPTIONS!$F$63 * $I8) + (ASSUMPTIONS!$F$64 * $F8)), AND(J$36 = $G$18, J$36 =ASSUMPTIONS!$G$60), $G22 * J39 * ((ASSUMPTIONS!$G$63 * $I8) + (ASSUMPTIONS!$G$64 * $F8)), AND(J$36 = $H$18, J$36 =ASSUMPTIONS!$H$60), $H22 * J39 * ((ASSUMPTIONS!$H$63 * $I8) + (ASSUMPTIONS!$H$64 * $F8)), TRUE, $I22 *J39 * ((ASSUMPTIONS!$I$63 * $I8) + (ASSUMPTIONS!$I$64 * $F8)) )} -> 4774049.3 | K49: {=IFS(AND(K$36 = $E$18, K$36 =ASSUMPTIONS!$E$60), $E22 * K39 * ((ASSUMPTIONS!$E$63 * $I8) + (ASSUMPTIONS!$E$64 * $F8)), AND(K$36 = $F$18, K$36 =ASSUMPTIONS!$F$60), $F22 * K39 * ((ASSUMPTIONS!$F$63 * $I8) + (ASSUMPTIONS!$F$64 * $F8)), AND(K$36 = $G$18, K$36 =ASSUMPTIONS!$G$60), $G22 * K39 * ((ASSUMPTIONS!$G$63 * $I8) + (ASSUMPTIONS!$G$64 * $F8)), AND(K$36 = $H$18, K$36 =ASSUMPTIONS!$H$60), $H22 * K39 * ((ASSUMPTIONS!$H$63 * $I8) + (ASSUMPTIONS!$H$64 * $F8)), TRUE, $I22 *K39 * ((ASSUMPTIONS!$I$63 * $I8) + (ASSUMPTIONS!$I$64 * $F8)) )} -> 7161073.9 | L49: {=IFS(AND(L$36 = $E$18, L$36 =ASSUMPTIONS!$E$60), $E22 * L39 * ((ASSUMPTIONS!$E$63 * $I8) + (ASSUMPTIONS!$E$64 * $F8)), AND(L$36 = $F$18, L$36 =ASSUMPTIONS!$F$60), $F22 * L39 * ((ASSUMPTIONS!$F$63 * $I8) + (ASSUMPTIONS!$F$64 * $F8)), AND(L$36 = $G$18, L$36 =ASSUMPTIONS!$G$60), $G22 * L39 * ((ASSUMPTIONS!$G$63 * $I8) + (ASSUMPTIONS!$G$64 * $F8)), AND(L$36 = $H$18, L$36 =ASSUMPTIONS!$H$60), $H22 * L39 * ((ASSUMPTIONS!$H$63 * $I8) + (ASSUMPTIONS!$H$64 * $F8)), TRUE, $I22 *L39 * ((ASSUMPTIONS!$I$63 * $I8) + (ASSUMPTIONS!$I$64 * $F8)) )} -> 9548098.6 | ... BL49: {=IFS(AND(BL$36 = $E$18, BL$36 =ASSUMPTIONS!$E$60), $E22 * BL39 * ((ASSUMPTIONS!$E$63 * $I8) + (ASSUMPTIONS!$E$64 * $F8)), AND(BL$36 = $F$18, BL$36 =ASSUMPTIONS!$F$60), $F22 * BL39 * ((ASSUMPTIONS!$F$63 * $I8) + (ASSUMPTIONS!$F$64 * $F8)), AND(BL$36 = $G$18, BL$36 =ASSUMPTIONS!$G$60), $G22 * BL39 * ((ASSUMPTIONS!$G$63 * $I8) + (ASSUMPTIONS!$G$64 * $F8)), AND(BL$36 = $H$18, BL$36 =ASSUMPTIONS!$H$60), $H22 * BL39 * ((ASSUMPTIONS!$H$63 * $I8) + (ASSUMPTIONS!$H$64 * $F8)), TRUE, $I22 *BL39 * ((ASSUMPTIONS!$I$63 * $I8) + (ASSUMPTIONS!$I$64 * $F8)) )} -> 1.7256649e+08
D50: Yogurt | E50: {=IFS(AND(E$36 = $E$18, E$36 =ASSUMPTIONS!$E$60), $E23 * E40 * ((ASSUMPTIONS!$E$63 * $I9) + (ASSUMPTIONS!$E$64 * $F9)), AND(E$36 = $F$18, E$36 =ASSUMPTIONS!$F$60), $F23 * E40 * ((ASSUMPTIONS!$F$63 * $I9) + (ASSUMPTIONS!$F$64 * $F9)), AND(E$36 = $G$18, E$36 =ASSUMPTIONS!$G$60), $G23 * E40 * ((ASSUMPTIONS!$G$63 * $I9) + (ASSUMPTIONS!$G$64 * $F9)), AND(E$36 = $H$18, E$36 =ASSUMPTIONS!$H$60), $H23 * E40 * ((ASSUMPTIONS!$H$63 * $I9) + (ASSUMPTIONS!$H$64 * $F9)), TRUE, $I23 *E40 * ((ASSUMPTIONS!$I$63 * $I9) + (ASSUMPTIONS!$I$64 * $F9)) )} -> 0 | F50: {=IFS(AND(F$36 = $E$18, F$36 =ASSUMPTIONS!$E$60), $E23 * F40 * ((ASSUMPTIONS!$E$63 * $I9) + (ASSUMPTIONS!$E$64 * $F9)), AND(F$36 = $F$18, F$36 =ASSUMPTIONS!$F$60), $F23 * F40 * ((ASSUMPTIONS!$F$63 * $I9) + (ASSUMPTIONS!$F$64 * $F9)), AND(F$36 = $G$18, F$36 =ASSUMPTIONS!$G$60), $G23 * F40 * ((ASSUMPTIONS!$G$63 * $I9) + (ASSUMPTIONS!$G$64 * $F9)), AND(F$36 = $H$18, F$36 =ASSUMPTIONS!$H$60), $H23 * F40 * ((ASSUMPTIONS!$H$63 * $I9) + (ASSUMPTIONS!$H$64 * $F9)), TRUE, $I23 *F40 * ((ASSUMPTIONS!$I$63 * $I9) + (ASSUMPTIONS!$I$64 * $F9)) )} -> 0 | G50: {=IFS(AND(G$36 = $E$18, G$36 =ASSUMPTIONS!$E$60), $E23 * G40 * ((ASSUMPTIONS!$E$63 * $I9) + (ASSUMPTIONS!$E$64 * $F9)), AND(G$36 = $F$18, G$36 =ASSUMPTIONS!$F$60), $F23 * G40 * ((ASSUMPTIONS!$F$63 * $I9) + (ASSUMPTIONS!$F$64 * $F9)), AND(G$36 = $G$18, G$36 =ASSUMPTIONS!$G$60), $G23 * G40 * ((ASSUMPTIONS!$G$63 * $I9) + (ASSUMPTIONS!$G$64 * $F9)), AND(G$36 = $H$18, G$36 =ASSUMPTIONS!$H$60), $H23 * G40 * ((ASSUMPTIONS!$H$63 * $I9) + (ASSUMPTIONS!$H$64 * $F9)), TRUE, $I23 *G40 * ((ASSUMPTIONS!$I$63 * $I9) + (ASSUMPTIONS!$I$64 * $F9)) )} -> 0 | H50: {=IFS(AND(H$36 = $E$18, H$36 =ASSUMPTIONS!$E$60), $E23 * H40 * ((ASSUMPTIONS!$E$63 * $I9) + (ASSUMPTIONS!$E$64 * $F9)), AND(H$36 = $F$18, H$36 =ASSUMPTIONS!$F$60), $F23 * H40 * ((ASSUMPTIONS!$F$63 * $I9) + (ASSUMPTIONS!$F$64 * $F9)), AND(H$36 = $G$18, H$36 =ASSUMPTIONS!$G$60), $G23 * H40 * ((ASSUMPTIONS!$G$63 * $I9) + (ASSUMPTIONS!$G$64 * $F9)), AND(H$36 = $H$18, H$36 =ASSUMPTIONS!$H$60), $H23 * H40 * ((ASSUMPTIONS!$H$63 * $I9) + (ASSUMPTIONS!$H$64 * $F9)), TRUE, $I23 *H40 * ((ASSUMPTIONS!$I$63 * $I9) + (ASSUMPTIONS!$I$64 * $F9)) )} -> 0 | I50: {=IFS(AND(I$36 = $E$18, I$36 =ASSUMPTIONS!$E$60), $E23 * I40 * ((ASSUMPTIONS!$E$63 * $I9) + (ASSUMPTIONS!$E$64 * $F9)), AND(I$36 = $F$18, I$36 =ASSUMPTIONS!$F$60), $F23 * I40 * ((ASSUMPTIONS!$F$63 * $I9) + (ASSUMPTIONS!$F$64 * $F9)), AND(I$36 = $G$18, I$36 =ASSUMPTIONS!$G$60), $G23 * I40 * ((ASSUMPTIONS!$G$63 * $I9) + (ASSUMPTIONS!$G$64 * $F9)), AND(I$36 = $H$18, I$36 =ASSUMPTIONS!$H$60), $H23 * I40 * ((ASSUMPTIONS!$H$63 * $I9) + (ASSUMPTIONS!$H$64 * $F9)), TRUE, $I23 *I40 * ((ASSUMPTIONS!$I$63 * $I9) + (ASSUMPTIONS!$I$64 * $F9)) )} -> 0 | J50: {=IFS(AND(J$36 = $E$18, J$36 =ASSUMPTIONS!$E$60), $E23 * J40 * ((ASSUMPTIONS!$E$63 * $I9) + (ASSUMPTIONS!$E$64 * $F9)), AND(J$36 = $F$18, J$36 =ASSUMPTIONS!$F$60), $F23 * J40 * ((ASSUMPTIONS!$F$63 * $I9) + (ASSUMPTIONS!$F$64 * $F9)), AND(J$36 = $G$18, J$36 =ASSUMPTIONS!$G$60), $G23 * J40 * ((ASSUMPTIONS!$G$63 * $I9) + (ASSUMPTIONS!$G$64 * $F9)), AND(J$36 = $H$18, J$36 =ASSUMPTIONS!$H$60), $H23 * J40 * ((ASSUMPTIONS!$H$63 * $I9) + (ASSUMPTIONS!$H$64 * $F9)), TRUE, $I23 *J40 * ((ASSUMPTIONS!$I$63 * $I9) + (ASSUMPTIONS!$I$64 * $F9)) )} -> 0 | K50: {=IFS(AND(K$36 = $E$18, K$36 =ASSUMPTIONS!$E$60), $E23 * K40 * ((ASSUMPTIONS!$E$63 * $I9) + (ASSUMPTIONS!$E$64 * $F9)), AND(K$36 = $F$18, K$36 =ASSUMPTIONS!$F$60), $F23 * K40 * ((ASSUMPTIONS!$F$63 * $I9) + (ASSUMPTIONS!$F$64 * $F9)), AND(K$36 = $G$18, K$36 =ASSUMPTIONS!$G$60), $G23 * K40 * ((ASSUMPTIONS!$G$63 * $I9) + (ASSUMPTIONS!$G$64 * $F9)), AND(K$36 = $H$18, K$36 =ASSUMPTIONS!$H$60), $H23 * K40 * ((ASSUMPTIONS!$H$63 * $I9) + (ASSUMPTIONS!$H$64 * $F9)), TRUE, $I23 *K40 * ((ASSUMPTIONS!$I$63 * $I9) + (ASSUMPTIONS!$I$64 * $F9)) )} -> 1461888 | L50: {=IFS(AND(L$36 = $E$18, L$36 =ASSUMPTIONS!$E$60), $E23 * L40 * ((ASSUMPTIONS!$E$63 * $I9) + (ASSUMPTIONS!$E$64 * $F9)), AND(L$36 = $F$18, L$36 =ASSUMPTIONS!$F$60), $F23 * L40 * ((ASSUMPTIONS!$F$63 * $I9) + (ASSUMPTIONS!$F$64 * $F9)), AND(L$36 = $G$18, L$36 =ASSUMPTIONS!$G$60), $G23 * L40 * ((ASSUMPTIONS!$G$63 * $I9) + (ASSUMPTIONS!$G$64 * $F9)), AND(L$36 = $H$18, L$36 =ASSUMPTIONS!$H$60), $H23 * L40 * ((ASSUMPTIONS!$H$63 * $I9) + (ASSUMPTIONS!$H$64 * $F9)), TRUE, $I23 *L40 * ((ASSUMPTIONS!$I$63 * $I9) + (ASSUMPTIONS!$I$64 * $F9)) )} -> 1461888 | ... BL50: {=IFS(AND(BL$36 = $E$18, BL$36 =ASSUMPTIONS!$E$60), $E23 * BL40 * ((ASSUMPTIONS!$E$63 * $I9) + (ASSUMPTIONS!$E$64 * $F9)), AND(BL$36 = $F$18, BL$36 =ASSUMPTIONS!$F$60), $F23 * BL40 * ((ASSUMPTIONS!$F$63 * $I9) + (ASSUMPTIONS!$F$64 * $F9)), AND(BL$36 = $G$18, BL$36 =ASSUMPTIONS!$G$60), $G23 * BL40 * ((ASSUMPTIONS!$G$63 * $I9) + (ASSUMPTIONS!$G$64 * $F9)), AND(BL$36 = $H$18, BL$36 =ASSUMPTIONS!$H$60), $H23 * BL40 * ((ASSUMPTIONS!$H$63 * $I9) + (ASSUMPTIONS!$H$64 * $F9)), TRUE, $I23 *BL40 * ((ASSUMPTIONS!$I$63 * $I9) + (ASSUMPTIONS!$I$64 * $F9)) )} -> 12734694
D51: Thandai | E51: {=IFS(AND(E$36 = $E$18, E$36 =ASSUMPTIONS!$E$60), $E24 * E41 * ((ASSUMPTIONS!$E$63 * $I10) + (ASSUMPTIONS!$E$64 * $F10)), AND(E$36 = $F$18, E$36 =ASSUMPTIONS!$F$60), $F24 * E41 * ((ASSUMPTIONS!$F$63 * $I10) + (ASSUMPTIONS!$F$64 * $F10)), AND(E$36 = $G$18, E$36 =ASSUMPTIONS!$G$60), $G24 * E41 * ((ASSUMPTIONS!$G$63 * $I10) + (ASSUMPTIONS!$G$64 * $F10)), AND(E$36 = $H$18, E$36 =ASSUMPTIONS!$H$60), $H24 * E41 * ((ASSUMPTIONS!$H$63 * $I10) + (ASSUMPTIONS!$H$64 * $F10)), TRUE, $I24 *E41 * ((ASSUMPTIONS!$I$63 * $I10) + (ASSUMPTIONS!$I$64 * $F10)) )} -> 0 | F51: {=IFS(AND(F$36 = $E$18, F$36 =ASSUMPTIONS!$E$60), $E24 * F41 * ((ASSUMPTIONS!$E$63 * $I10) + (ASSUMPTIONS!$E$64 * $F10)), AND(F$36 = $F$18, F$36 =ASSUMPTIONS!$F$60), $F24 * F41 * ((ASSUMPTIONS!$F$63 * $I10) + (ASSUMPTIONS!$F$64 * $F10)), AND(F$36 = $G$18, F$36 =ASSUMPTIONS!$G$60), $G24 * F41 * ((ASSUMPTIONS!$G$63 * $I10) + (ASSUMPTIONS!$G$64 * $F10)), AND(F$36 = $H$18, F$36 =ASSUMPTIONS!$H$60), $H24 * F41 * ((ASSUMPTIONS!$H$63 * $I10) + (ASSUMPTIONS!$H$64 * $F10)), TRUE, $I24 *F41 * ((ASSUMPTIONS!$I$63 * $I10) + (ASSUMPTIONS!$I$64 * $F10)) )} -> 0 | G51: {=IFS(AND(G$36 = $E$18, G$36 =ASSUMPTIONS!$E$60), $E24 * G41 * ((ASSUMPTIONS!$E$63 * $I10) + (ASSUMPTIONS!$E$64 * $F10)), AND(G$36 = $F$18, G$36 =ASSUMPTIONS!$F$60), $F24 * G41 * ((ASSUMPTIONS!$F$63 * $I10) + (ASSUMPTIONS!$F$64 * $F10)), AND(G$36 = $G$18, G$36 =ASSUMPTIONS!$G$60), $G24 * G41 * ((ASSUMPTIONS!$G$63 * $I10) + (ASSUMPTIONS!$G$64 * $F10)), AND(G$36 = $H$18, G$36 =ASSUMPTIONS!$H$60), $H24 * G41 * ((ASSUMPTIONS!$H$63 * $I10) + (ASSUMPTIONS!$H$64 * $F10)), TRUE, $I24 *G41 * ((ASSUMPTIONS!$I$63 * $I10) + (ASSUMPTIONS!$I$64 * $F10)) )} -> 0 | H51: {=IFS(AND(H$36 = $E$18, H$36 =ASSUMPTIONS!$E$60), $E24 * H41 * ((ASSUMPTIONS!$E$63 * $I10) + (ASSUMPTIONS!$E$64 * $F10)), AND(H$36 = $F$18, H$36 =ASSUMPTIONS!$F$60), $F24 * H41 * ((ASSUMPTIONS!$F$63 * $I10) + (ASSUMPTIONS!$F$64 * $F10)), AND(H$36 = $G$18, H$36 =ASSUMPTIONS!$G$60), $G24 * H41 * ((ASSUMPTIONS!$G$63 * $I10) + (ASSUMPTIONS!$G$64 * $F10)), AND(H$36 = $H$18, H$36 =ASSUMPTIONS!$H$60), $H24 * H41 * ((ASSUMPTIONS!$H$63 * $I10) + (ASSUMPTIONS!$H$64 * $F10)), TRUE, $I24 *H41 * ((ASSUMPTIONS!$I$63 * $I10) + (ASSUMPTIONS!$I$64 * $F10)) )} -> 0 | I51: {=IFS(AND(I$36 = $E$18, I$36 =ASSUMPTIONS!$E$60), $E24 * I41 * ((ASSUMPTIONS!$E$63 * $I10) + (ASSUMPTIONS!$E$64 * $F10)), AND(I$36 = $F$18, I$36 =ASSUMPTIONS!$F$60), $F24 * I41 * ((ASSUMPTIONS!$F$63 * $I10) + (ASSUMPTIONS!$F$64 * $F10)), AND(I$36 = $G$18, I$36 =ASSUMPTIONS!$G$60), $G24 * I41 * ((ASSUMPTIONS!$G$63 * $I10) + (ASSUMPTIONS!$G$64 * $F10)), AND(I$36 = $H$18, I$36 =ASSUMPTIONS!$H$60), $H24 * I41 * ((ASSUMPTIONS!$H$63 * $I10) + (ASSUMPTIONS!$H$64 * $F10)), TRUE, $I24 *I41 * ((ASSUMPTIONS!$I$63 * $I10) + (ASSUMPTIONS!$I$64 * $F10)) )} -> 0 | J51: {=IFS(AND(J$36 = $E$18, J$36 =ASSUMPTIONS!$E$60), $E24 * J41 * ((ASSUMPTIONS!$E$63 * $I10) + (ASSUMPTIONS!$E$64 * $F10)), AND(J$36 = $F$18, J$36 =ASSUMPTIONS!$F$60), $F24 * J41 * ((ASSUMPTIONS!$F$63 * $I10) + (ASSUMPTIONS!$F$64 * $F10)), AND(J$36 = $G$18, J$36 =ASSUMPTIONS!$G$60), $G24 * J41 * ((ASSUMPTIONS!$G$63 * $I10) + (ASSUMPTIONS!$G$64 * $F10)), AND(J$36 = $H$18, J$36 =ASSUMPTIONS!$H$60), $H24 * J41 * ((ASSUMPTIONS!$H$63 * $I10) + (ASSUMPTIONS!$H$64 * $F10)), TRUE, $I24 *J41 * ((ASSUMPTIONS!$I$63 * $I10) + (ASSUMPTIONS!$I$64 * $F10)) )} -> 0 | K51: {=IFS(AND(K$36 = $E$18, K$36 =ASSUMPTIONS!$E$60), $E24 * K41 * ((ASSUMPTIONS!$E$63 * $I10) + (ASSUMPTIONS!$E$64 * $F10)), AND(K$36 = $F$18, K$36 =ASSUMPTIONS!$F$60), $F24 * K41 * ((ASSUMPTIONS!$F$63 * $I10) + (ASSUMPTIONS!$F$64 * $F10)), AND(K$36 = $G$18, K$36 =ASSUMPTIONS!$G$60), $G24 * K41 * ((ASSUMPTIONS!$G$63 * $I10) + (ASSUMPTIONS!$G$64 * $F10)), AND(K$36 = $H$18, K$36 =ASSUMPTIONS!$H$60), $H24 * K41 * ((ASSUMPTIONS!$H$63 * $I10) + (ASSUMPTIONS!$H$64 * $F10)), TRUE, $I24 *K41 * ((ASSUMPTIONS!$I$63 * $I10) + (ASSUMPTIONS!$I$64 * $F10)) )} -> 2923776 | L51: {=IFS(AND(L$36 = $E$18, L$36 =ASSUMPTIONS!$E$60), $E24 * L41 * ((ASSUMPTIONS!$E$63 * $I10) + (ASSUMPTIONS!$E$64 * $F10)), AND(L$36 = $F$18, L$36 =ASSUMPTIONS!$F$60), $F24 * L41 * ((ASSUMPTIONS!$F$63 * $I10) + (ASSUMPTIONS!$F$64 * $F10)), AND(L$36 = $G$18, L$36 =ASSUMPTIONS!$G$60), $G24 * L41 * ((ASSUMPTIONS!$G$63 * $I10) + (ASSUMPTIONS!$G$64 * $F10)), AND(L$36 = $H$18, L$36 =ASSUMPTIONS!$H$60), $H24 * L41 * ((ASSUMPTIONS!$H$63 * $I10) + (ASSUMPTIONS!$H$64 * $F10)), TRUE, $I24 *L41 * ((ASSUMPTIONS!$I$63 * $I10) + (ASSUMPTIONS!$I$64 * $F10)) )} -> 2923776 | ... BL51: {=IFS(AND(BL$36 = $E$18, BL$36 =ASSUMPTIONS!$E$60), $E24 * BL41 * ((ASSUMPTIONS!$E$63 * $I10) + (ASSUMPTIONS!$E$64 * $F10)), AND(BL$36 = $F$18, BL$36 =ASSUMPTIONS!$F$60), $F24 * BL41 * ((ASSUMPTIONS!$F$63 * $I10) + (ASSUMPTIONS!$F$64 * $F10)), AND(BL$36 = $G$18, BL$36 =ASSUMPTIONS!$G$60), $G24 * BL41 * ((ASSUMPTIONS!$G$63 * $I10) + (ASSUMPTIONS!$G$64 * $F10)), AND(BL$36 = $H$18, BL$36 =ASSUMPTIONS!$H$60), $H24 * BL41 * ((ASSUMPTIONS!$H$63 * $I10) + (ASSUMPTIONS!$H$64 * $F10)), TRUE, $I24 *BL41 * ((ASSUMPTIONS!$I$63 * $I10) + (ASSUMPTIONS!$I$64 * $F10)) )} -> 25469387
...

Sheet COGS ENGINE
A1: =COVER!$B$12 -> Narayan Dairy Project
A2: COGS Engine
D4: Product / Year | E4: 1 | F4: 2 | G4: 3 | H4: 4 | I4: 5
D7: Section B – Salary Escalation Factor Schedule
D8: Milk Procurement | E8: =1 -> 1 | F8: =E8 * (1 + ASSUMPTIONS!$H$36) -> 1.04 | G8: =F8 * (1 + ASSUMPTIONS!$H$36) -> 1.0816 | H8: =G8 * (1 + ASSUMPTIONS!$H$36) -> 1.124864 | I8: =H8 * (1 + ASSUMPTIONS!$H$36) -> 1.1698586
D9: Feed | E9: =1 -> 1 | F9: =E9 * (1 + ASSUMPTIONS!$H$38) -> 1.06 | G9: =F9 * (1 + ASSUMPTIONS!$H$38) -> 1.1236 | H9: =G9 * (1 + ASSUMPTIONS!$H$38) -> 1.191016 | I9: =H9 * (1 + ASSUMPTIONS!$H$38) -> 1.262477
D10: Freight | E10: =1 -> 1 | F10: =E10 * (1 + ASSUMPTIONS!$H$40) -> 1.05 | G10: =F10 * (1 + ASSUMPTIONS!$H$40) -> 1.1025 | H10: =G10 * (1 + ASSUMPTIONS!$H$40) -> 1.157625 | I10: =H10 * (1 + ASSUMPTIONS!$H$40) -> 1.2155063
D12: Product / Month / Year | E12: 1 | F12: =E12+1 -> 2 | G12: =F12+1 -> 3 | H12: =G12+1 -> 4 | I12: =H12+1 -> 5 | J12: =I12+1 -> 6 | K12: =J12+1 -> 7 | L12: =K12+1 -> 8 | M12: =L12+1 -> 9 | ... BL12: =BK12+1 -> 60
E15: =INT((E12 - 1) / 12) +1 -> 1 | F15: =INT((F12 - 1) / 12) +1 -> 1 | G15: =INT((G12 - 1) / 12) +1 -> 1 | H15: =INT((H12 - 1) / 12) +1 -> 1 | I15: =INT((I12 - 1) / 12) +1 -> 1 | J15: =INT((J12 - 1) / 12) +1 -> 1 | K15: =INT((K12 - 1) / 12) +1 -> 1 | L15: =INT((L12 - 1) / 12) +1 -> 1 | ... BL15: =INT((BL12 - 1) / 12) +1 -> 5
D17: Section A – Raw Milk Cost
D18: Own Livestock | E18: ='MILK FLOW ENGINE'!E$8 -> 0 | F18: ='MILK FLOW ENGINE'!F$8 -> 0 | G18: ='MILK FLOW ENGINE'!G$8 -> 0 | H18: ='MILK FLOW ENGINE'!H$8 -> 0 | I18: ='MILK FLOW ENGINE'!I$8 -> 50 | J18: ='MILK FLOW ENGINE'!J$8 -> 100 | K18: ='MILK FLOW ENGINE'!K$8 -> 150 | L18: ='MILK FLOW ENGINE'!L$8 -> 200 | ... BL18: ='MILK FLOW ENGINE'!BL$8 -> 2800
D19: Own Milk Volume | E19: ='MILK FLOW ENGINE'!E10 -> 0 | F19: ='MILK FLOW ENGINE'!F10 -> 0 | G19: ='MILK FLOW ENGINE'!G10 -> 0 | H19: ='MILK FLOW ENGINE'!H10 -> 0 | I19: ='MILK FLOW ENGINE'!I10 -> 48000 | J19: ='MILK FLOW ENGINE'!J10 -> 96000 | K19: ='MILK FLOW ENGINE'!K10 -> 144000 | L19: ='MILK FLOW ENGINE'!L10 -> 192000 | ... BL19: ='MILK FLOW ENGINE'!BL10 -> 2688000
D20: Own Milk Cost per Litre | E20: =IF(E$15=$E$4, ASSUMPTIONS!$H$26 * $E$9, IF(E$15=$F$4, ASSUMPTIONS!$H$26 * $F$9, IF(E$15=$G$4, ASSUMPTIONS!$H$26 * $G$9, IF(E$15=$H$4, ASSUMPTIONS!$H$26 * $H$9, IF(E$15=$I$4, ASSUMPTIONS!$H$26 * $I$9, 0 ))))) -> 22 | F20: =IF(F$15=$E$4, ASSUMPTIONS!$H$26 * $E$9, IF(F$15=$F$4, ASSUMPTIONS!$H$26 * $F$9, IF(F$15=$G$4, ASSUMPTIONS!$H$26 * $G$9, IF(F$15=$H$4, ASSUMPTIONS!$H$26 * $H$9, IF(F$15=$I$4, ASSUMPTIONS!$H$26 * $I$9, 0 ))))) -> 22 | G20: =IF(G$15=$E$4, ASSUMPTIONS!$H$26 * $E$9, IF(G$15=$F$4, ASSUMPTIONS!$H$26 * $F$9, IF(G$15=$G$4, ASSUMPTIONS!$H$26 * $G$9, IF(G$15=$H$4, ASSUMPTIONS!$H$26 * $H$9, IF(G$15=$I$4, ASSUMPTIONS!$H$26 * $I$9, 0 ))))) -> 22 | H20: =IF(H$15=$E$4, ASSUMPTIONS!$H$26 * $E$9, IF(H$15=$F$4, ASSUMPTIONS!$H$26 * $F$9, IF(H$15=$G$4, ASSUMPTIONS!$H$26 * $G$9, IF(H$15=$H$4, ASSUMPTIONS!$H$26 * $H$9, IF(H$15=$I$4, ASSUMPTIONS!$H$26 * $I$9, 0 ))))) -> 22 | I20: =IF(I$15=$E$4, ASSUMPTIONS!$H$26 * $E$9, IF(I$15=$F$4, ASSUMPTIONS!$H$26 * $F$9, IF(I$15=$G$4, ASSUMPTIONS!$H$26 * $G$9, IF(I$15=$H$4, ASSUMPTIONS!$H$26 * $H$9, IF(I$15=$I$4, ASSUMPTIONS!$H$26 * $I$9, 0 ))))) -> 22 | J20: =IF(J$15=$E$4, ASSUMPTIONS!$H$26 * $E$9, IF(J$15=$F$4, ASSUMPTIONS!$H$26 * $F$9, IF(J$15=$G$4, ASSUMPTIONS!$H$26 * $G$9, IF(J$15=$H$4, ASSUMPTIONS!$H$26 * $H$9, IF(J$15=$I$4, ASSUMPTIONS!$H$26 * $I$9, 0 ))))) -> 22 | K20: =IF(K$15=$E$4, ASSUMPTIONS!$H$26 * $E$9, IF(K$15=$F$4, ASSUMPTIONS!$H$26 * $F$9, IF(K$15=$G$4, ASSUMPTIONS!$H$26 * $G$9, IF(K$15=$H$4, ASSUMPTIONS!$H$26 * $H$9, IF(K$15=$I$4, ASSUMPTIONS!$H$26 * $I$9, 0 ))))) -> 22 | L20: =IF(L$15=$E$4, ASSUMPTIONS!$H$26 * $E$9, IF(L$15=$F$4, ASSUMPTIONS!$H$26 * $F$9, IF(L$15=$G$4, ASSUMPTIONS!$H$26 * $G$9, IF(L$15=$H$4, ASSUMPTIONS!$H$26 * $H$9, IF(L$15=$I$4, ASSUMPTIONS!$H$26 * $I$9, 0 ))))) -> 22 | ... BL20: =IF(BL$15=$E$4, ASSUMPTIONS!$H$26 * $E$9, IF(BL$15=$F$4, ASSUMPTIONS!$H$26 * $F$9, IF(BL$15=$G$4, ASSUMPTIONS!$H$26 * $G$9, IF(BL$15=$H$4, ASSUMPTIONS!$H$26 * $H$9, IF(BL$15=$I$4, ASSUMPTIONS!$H$26 * $I$9, 0 ))))) -> 27.774493
D21: Own Milk Total Cost | E21: =E19 * E20 -> 0 | F21: =F19 * F20 -> 0 | G21: =G19 * G20 -> 0 | H21: =H19 * H20 -> 0 | I21: =I19 * I20 -> 1056000 | J21: =J19 * J20 -> 2112000 | K21: =K19 * K20 -> 3168000 | L21: =L19 * L20 -> 4224000 | ... BL21: =BL19 * BL20 -> 74657838
D22: Procured Milk Volume | E22: ='MILK FLOW ENGINE'!E11 -> 0 | F22: ='MILK FLOW ENGINE'!F11 -> 0 | G22: ='MILK FLOW ENGINE'!G11 -> 0 | H22: ='MILK FLOW ENGINE'!H11 -> 0 | I22: ='MILK FLOW ENGINE'!I11 -> 0 | J22: ='MILK FLOW ENGINE'!J11 -> 0 | K22: ='MILK FLOW ENGINE'!K11 -> 150000 | L22: ='MILK FLOW ENGINE'!L11 -> 150000 | ... BL22: ='MILK FLOW ENGINE'!BL11 -> 900000
D23: Procured Milk Cost per Litre | E23: =IF(E$15=$E$4, ASSUMPTIONS!$H$54 * $E$8, IF(E$15=$F$4, ASSUMPTIONS!$H$54 * $F$8, IF(E$15=$G$4, ASSUMPTIONS!$H$54 * $G$8, IF(E$15=$H$4, ASSUMPTIONS!$H$54 * $H$8, IF(E$15=$I$4, ASSUMPTIONS!$H$54 * $I$8, 0 ))))) -> 50 | F23: =IF(F$15=$E$4, ASSUMPTIONS!$H$54 * $E$8, IF(F$15=$F$4, ASSUMPTIONS!$H$54 * $F$8, IF(F$15=$G$4, ASSUMPTIONS!$H$54 * $G$8, IF(F$15=$H$4, ASSUMPTIONS!$H$54 * $H$8, IF(F$15=$I$4, ASSUMPTIONS!$H$54 * $I$8, 0 ))))) -> 50 | G23: =IF(G$15=$E$4, ASSUMPTIONS!$H$54 * $E$8, IF(G$15=$F$4, ASSUMPTIONS!$H$54 * $F$8, IF(G$15=$G$4, ASSUMPTIONS!$H$54 * $G$8, IF(G$15=$H$4, ASSUMPTIONS!$H$54 * $H$8, IF(G$15=$I$4, ASSUMPTIONS!$H$54 * $I$8, 0 ))))) -> 50 | H23: =IF(H$15=$E$4, ASSUMPTIONS!$H$54 * $E$8, IF(H$15=$F$4, ASSUMPTIONS!$H$54 * $F$8, IF(H$15=$G$4, ASSUMPTIONS!$H$54 * $G$8, IF(H$15=$H$4, ASSUMPTIONS!$H$54 * $H$8, IF(H$15=$I$4, ASSUMPTIONS!$H$54 * $I$8, 0 ))))) -> 50 | I23: =IF(I$15=$E$4, ASSUMPTIONS!$H$54 * $E$8, IF(I$15=$F$4, ASSUMPTIONS!$H$54 * $F$8, IF(I$15=$G$4, ASSUMPTIONS!$H$54 * $G$8, IF(I$15=$H$4, ASSUMPTIONS!$H$54 * $H$8, IF(I$15=$I$4, ASSUMPTIONS!$H$54 * $I$8, 0 ))))) -> 50 | J23: =IF(J$15=$E$4, ASSUMPTIONS!$H$54 * $E$8, IF(J$15=$F$4, ASSUMPTIONS!$H$54 * $F$8, IF(J$15=$G$4, ASSUMPTIONS!$H$54 * $G$8, IF(J$15=$H$4, ASSUMPTIONS!$H$54 * $H$8, IF(J$15=$I$4, ASSUMPTIONS!$H$54 * $I$8, 0 ))))) -> 50 | K23: =IF(K$15=$E$4, ASSUMPTIONS!$H$54 * $E$8, IF(K$15=$F$4, ASSUMPTIONS!$H$54 * $F$8, IF(K$15=$G$4, ASSUMPTIONS!$H$54 * $G$8, IF(K$15=$H$4, ASSUMPTIONS!$H$54 * $H$8, IF(K$15=$I$4, ASSUMPTIONS!$H$54 * $I$8, 0 ))))) -> 50 | L23: =IF(L$15=$E$4, ASSUMPTIONS!$H$54 * $E$8, IF(L$15=$F$4, ASSUMPTIONS!$H$54 * $F$8, IF(L$15=$G$4, ASSUMPTIONS!$H$54 * $G$8, IF(L$15=$H$4, ASSUMPTIONS!$H$54 * $H$8, IF(L$15=$I$4, ASSUMPTIONS!$H$54 * $I$8, 0 ))))) -> 50 | ... BL23: =IF(BL$15=$E$4, ASSUMPTIONS!$H$54 * $E$8, IF(BL$15=$F$4, ASSUMPTIONS!$H$54 * $F$8, IF(BL$15=$G$4, ASSUMPTIONS!$H$54 * $G$8, IF(BL$15=$H$4, ASSUMPTIONS!$H$54 * $H$8, IF(BL$15=$I$4, ASSUMPTIONS!$H$54 * $I$8, 0 ))))) -> 58.492928
D24: Procured Milk Total Cost | E24: =E22 * E23 -> 0 | F24: =F22 * F23 -> 0 | G24: =G22 * G23 -> 0 | H24: =H22 * H23 -> 0 | I24: =I22 * I23 -> 0 | J24: =J22 * J23 -> 0 | K24: =K22 * K23 -> 7500000 | L24: =L22 * L23 -> 7500000 | ... BL24: =BL22 * BL23 -> 52643635
D25: Section B – Packaging Cost
D26: Fresh Milk | E26: ='PRODUCT PRICING & REVENUE ENGIN'!E49 * ASSUMPTIONS!$L$17 -> 0 | F26: ='PRODUCT PRICING & REVENUE ENGIN'!F49 * ASSUMPTIONS!$L$17 -> 0 | G26: ='PRODUCT PRICING & REVENUE ENGIN'!G49 * ASSUMPTIONS!$L$17 -> 0 | H26: ='PRODUCT PRICING & REVENUE ENGIN'!H49 * ASSUMPTIONS!$L$17 -> 0 | I26: ='PRODUCT PRICING & REVENUE ENGIN'!I49 * ASSUMPTIONS!$L$17 -> 95480.986 | J26: ='PRODUCT PRICING & REVENUE ENGIN'!J49 * ASSUMPTIONS!$L$17 -> 190961.97 | K26: ='PRODUCT PRICING & REVENUE ENGIN'!K49 * ASSUMPTIONS!$L$17 -> 286442.96 | L26: ='PRODUCT PRICING & REVENUE ENGIN'!L49 * ASSUMPTIONS!$L$17 -> 381923.94 | ... BL26: ='PRODUCT PRICING & REVENUE ENGIN'!BL49 * ASSUMPTIONS!$L$17 -> 6902659.5
D27: Yogurt | E27: ='PRODUCT PRICING & REVENUE ENGIN'!E50 * ASSUMPTIONS!$L$19 -> 0 | F27: ='PRODUCT PRICING & REVENUE ENGIN'!F50 * ASSUMPTIONS!$L$19 -> 0 | G27: ='PRODUCT PRICING & REVENUE ENGIN'!G50 * ASSUMPTIONS!$L$19 -> 0 | H27: ='PRODUCT PRICING & REVENUE ENGIN'!H50 * ASSUMPTIONS!$L$19 -> 0 | I27: ='PRODUCT PRICING & REVENUE ENGIN'!I50 * ASSUMPTIONS!$L$19 -> 0 | J27: ='PRODUCT PRICING & REVENUE ENGIN'!J50 * ASSUMPTIONS!$L$19 -> 0 | K27: ='PRODUCT PRICING & REVENUE ENGIN'!K50 * ASSUMPTIONS!$L$19 -> 87713.28 | L27: ='PRODUCT PRICING & REVENUE ENGIN'!L50 * ASSUMPTIONS!$L$19 -> 87713.28 | ... BL27: ='PRODUCT PRICING & REVENUE ENGIN'!BL50 * ASSUMPTIONS!$L$19 -> 764081.62
D28: Thandai | E28: ='PRODUCT PRICING & REVENUE ENGIN'!E51 * ASSUMPTIONS!$L$20 -> 0 | F28: ='PRODUCT PRICING & REVENUE ENGIN'!F51 * ASSUMPTIONS!$L$20 -> 0 | G28: ='PRODUCT PRICING & REVENUE ENGIN'!G51 * ASSUMPTIONS!$L$20 -> 0 | H28: ='PRODUCT PRICING & REVENUE ENGIN'!H51 * ASSUMPTIONS!$L$20 -> 0 | I28: ='PRODUCT PRICING & REVENUE ENGIN'!I51 * ASSUMPTIONS!$L$20 -> 0 | J28: ='PRODUCT PRICING & REVENUE ENGIN'!J51 * ASSUMPTIONS!$L$20 -> 0 | K28: ='PRODUCT PRICING & REVENUE ENGIN'!K51 * ASSUMPTIONS!$L$20 -> 233902.08 | L28: ='PRODUCT PRICING & REVENUE ENGIN'!L51 * ASSUMPTIONS!$L$20 -> 233902.08 | ... BL28: ='PRODUCT PRICING & REVENUE ENGIN'!BL51 * ASSUMPTIONS!$L$20 -> 2037551
D29: SMP | E29: ='PRODUCT PRICING & REVENUE ENGIN'!E52 * ASSUMPTIONS!$L$21 -> 0 | F29: ='PRODUCT PRICING & REVENUE ENGIN'!F52 * ASSUMPTIONS!$L$21 -> 0 | G29: ='PRODUCT PRICING & REVENUE ENGIN'!G52 * ASSUMPTIONS!$L$21 -> 0 | H29: ='PRODUCT PRICING & REVENUE ENGIN'!H52 * ASSUMPTIONS!$L$21 -> 0 | I29: ='PRODUCT PRICING & REVENUE ENGIN'!I52 * ASSUMPTIONS!$L$21 -> 0 | J29: ='PRODUCT PRICING & REVENUE ENGIN'!J52 * ASSUMPTIONS!$L$21 -> 0 | K29: ='PRODUCT PRICING & REVENUE ENGIN'!K52 * ASSUMPTIONS!$L$21 -> 14466.6 | L29: ='PRODUCT PRICING & REVENUE ENGIN'!L52 * ASSUMPTIONS!$L$21 -> 14466.6 | ... BL29: ='PRODUCT PRICING & REVENUE ENGIN'!BL52 * ASSUMPTIONS!$L$21 -> 118874.58
D30: Butter | E30: ='PRODUCT PRICING & REVENUE ENGIN'!E53 * ASSUMPTIONS!$L$22 -> 0 | F30: ='PRODUCT PRICING & REVENUE ENGIN'!F53 * ASSUMPTIONS!$L$22 -> 0 | G30: ='PRODUCT PRICING & REVENUE ENGIN'!G53 * ASSUMPTIONS!$L$22 -> 0 | H30: ='PRODUCT PRICING & REVENUE ENGIN'!H53 * ASSUMPTIONS!$L$22 -> 0 | I30: ='PRODUCT PRICING & REVENUE ENGIN'!I53 * ASSUMPTIONS!$L$22 -> 0 | J30: ='PRODUCT PRICING & REVENUE ENGIN'!J53 * ASSUMPTIONS!$L$22 -> 0 | K30: ='PRODUCT PRICING & REVENUE ENGIN'!K53 * ASSUMPTIONS!$L$22 -> 16413.754 | L30: ='PRODUCT PRICING & REVENUE ENGIN'!L53 * ASSUMPTIONS!$L$22 -> 16413.754 | ... BL30: ='PRODUCT PRICING & REVENUE ENGIN'!BL53 * ASSUMPTIONS!$L$22 -> 133891.98
D31: A2 Powder | E31: ='PRODUCT PRICING & REVENUE ENGIN'!E54 * ASSUMPTIONS!$L$23 -> 0 | F31: ='PRODUCT PRICING & REVENUE ENGIN'!F54 * ASSUMPTIONS!$L$23 -> 0 | G31: ='PRODUCT PRICING & REVENUE ENGIN'!G54 * ASSUMPTIONS!$L$23 -> 0 | H31: ='PRODUCT PRICING & REVENUE ENGIN'!H54 * ASSUMPTIONS!$L$23 -> 0 | I31: ='PRODUCT PRICING & REVENUE ENGIN'!I54 * ASSUMPTIONS!$L$23 -> 0 | J31: ='PRODUCT PRICING & REVENUE ENGIN'!J54 * ASSUMPTIONS!$L$23 -> 0 | K31: ='PRODUCT PRICING & REVENUE ENGIN'!K54 * ASSUMPTIONS!$L$23 -> 105306.7 | L31: ='PRODUCT PRICING & REVENUE ENGIN'!L54 * ASSUMPTIONS!$L$23 -> 105306.7 | ... BL31: ='PRODUCT PRICING & REVENUE ENGIN'!BL54 * ASSUMPTIONS!$L$23 -> 927529.31
D32: Ghee | E32: ='PRODUCT PRICING & REVENUE ENGIN'!E55 * ASSUMPTIONS!$L$24 -> 0 | F32: ='PRODUCT PRICING & REVENUE ENGIN'!F55 * ASSUMPTIONS!$L$24 -> 0 | G32: ='PRODUCT PRICING & REVENUE ENGIN'!G55 * ASSUMPTIONS!$L$24 -> 0 | H32: ='PRODUCT PRICING & REVENUE ENGIN'!H55 * ASSUMPTIONS!$L$24 -> 0 | I32: ='PRODUCT PRICING & REVENUE ENGIN'!I55 * ASSUMPTIONS!$L$24 -> 0 | J32: ='PRODUCT PRICING & REVENUE ENGIN'!J55 * ASSUMPTIONS!$L$24 -> 0 | K32: ='PRODUCT PRICING & REVENUE ENGIN'!K55 * ASSUMPTIONS!$L$24 -> 38293.344 | L32: ='PRODUCT PRICING & REVENUE ENGIN'!L55 * ASSUMPTIONS!$L$24 -> 38293.344 | ... BL32: ='PRODUCT PRICING & REVENUE ENGIN'!BL55 * ASSUMPTIONS!$L$24 -> 324734.69
D33: Curd | E33: ='PRODUCT PRICING & REVENUE ENGIN'!E56 * ASSUMPTIONS!$L$25 -> 0 | F33: ='PRODUCT PRICING & REVENUE ENGIN'!F56 * ASSUMPTIONS!$L$25 -> 0 | G33: ='PRODUCT PRICING & REVENUE ENGIN'!G56 * ASSUMPTIONS!$L$25 -> 0 | H33: ='PRODUCT PRICING & REVENUE ENGIN'!H56 * ASSUMPTIONS!$L$25 -> 0 | I33: ='PRODUCT PRICING & REVENUE ENGIN'!I56 * ASSUMPTIONS!$L$25 -> 0 | J33: ='PRODUCT PRICING & REVENUE ENGIN'!J56 * ASSUMPTIONS!$L$25 -> 0 | K33: ='PRODUCT PRICING & REVENUE ENGIN'!K56 * ASSUMPTIONS!$L$25 -> 102115.58 | L33: ='PRODUCT PRICING & REVENUE ENGIN'!L56 * ASSUMPTIONS!$L$25 -> 102115.58 | ... BL33: ='PRODUCT PRICING & REVENUE ENGIN'!BL56 * ASSUMPTIONS!$L$25 -> 865959.17
D34: Peda | E34: ='PRODUCT PRICING & REVENUE ENGIN'!E57 * ASSUMPTIONS!$L$26 -> 0 | F34: ='PRODUCT PRICING & REVENUE ENGIN'!F57 * ASSUMPTIONS!$L$26 -> 0 | G34: ='PRODUCT PRICING & REVENUE ENGIN'!G57 * ASSUMPTIONS!$L$26 -> 0 | H34: ='PRODUCT PRICING & REVENUE ENGIN'!H57 * ASSUMPTIONS!$L$26 -> 0 | I34: ='PRODUCT PRICING & REVENUE ENGIN'!I57 * ASSUMPTIONS!$L$26 -> 0 | J34: ='PRODUCT PRICING & REVENUE ENGIN'!J57 * ASSUMPTIONS!$L$26 -> 0 | K34: ='PRODUCT PRICING & REVENUE ENGIN'!K57 * ASSUMPTIONS!$L$26 -> 153498.24 | L34: ='PRODUCT PRICING & REVENUE ENGIN'!L57 * ASSUMPTIONS!$L$26 -> 153498.24 | ... BL34: ='PRODUCT PRICING & REVENUE ENGIN'!BL57 * ASSUMPTIONS!$L$26 -> 1388813.9
D35: Section C – Feed Cost | E35: =IF(E$15=$E$4, E18 * ASSUMPTIONS!$H$27 * $E$9, IF(E$15=$F$4, E18 * ASSUMPTIONS!$H$27 * $F$9, IF(E$15=$G$4, E18 * ASSUMPTIONS!$H$27 * $G$9, IF(E$15=$H$4, E18 * ASSUMPTIONS!$H$27 * $H$9, IF(E$15=$I$4, E18 * ASSUMPTIONS!$H$27 * $I$9, 0 ))))) -> 0 | F35: =IF(F$15=$E$4, F18 * ASSUMPTIONS!$H$27 * $E$9, IF(F$15=$F$4, F18 * ASSUMPTIONS!$H$27 * $F$9, IF(F$15=$G$4, F18 * ASSUMPTIONS!$H$27 * $G$9, IF(F$15=$H$4, F18 * ASSUMPTIONS!$H$27 * $H$9, IF(F$15=$I$4, F18 * ASSUMPTIONS!$H$27 * $I$9, 0 ))))) -> 0 | G35: =IF(G$15=$E$4, G18 * ASSUMPTIONS!$H$27 * $E$9, IF(G$15=$F$4, G18 * ASSUMPTIONS!$H$27 * $F$9, IF(G$15=$G$4, G18 * ASSUMPTIONS!$H$27 * $G$9, IF(G$15=$H$4, G18 * ASSUMPTIONS!$H$27 * $H$9, IF(G$15=$I$4, G18 * ASSUMPTIONS!$H$27 * $I$9, 0 ))))) -> 0 | H35: =IF(H$15=$E$4, H18 * ASSUMPTIONS!$H$27 * $E$9, IF(H$15=$F$4, H18 * ASSUMPTIONS!$H$27 * $F$9, IF(H$15=$G$4, H18 * ASSUMPTIONS!$H$27 * $G$9, IF(H$15=$H$4, H18 * ASSUMPTIONS!$H$27 * $H$9, IF(H$15=$I$4, H18 * ASSUMPTIONS!$H$27 * $I$9, 0 ))))) -> 0 | I35: =IF(I$15=$E$4, I18 * ASSUMPTIONS!$H$27 * $E$9, IF(I$15=$F$4, I18 * ASSUMPTIONS!$H$27 * $F$9, IF(I$15=$G$4, I18 * ASSUMPTIONS!$H$27 * $G$9, IF(I$15=$H$4, I18 * ASSUMPTIONS!$H$27 * $H$9, IF(I$15=$I$4, I18 * ASSUMPTIONS!$H$27 * $I$9, 0 ))))) -> 550000 | J35: =IF(J$15=$E$4, J18 * ASSUMPTIONS!$H$27 * $E$9, IF(J$15=$F$4, J18 * ASSUMPTIONS!$H$27 * $F$9, IF(J$15=$G$4, J18 * ASSUMPTIONS!$H$27 * $G$9, IF(J$15=$H$4, J18 * ASSUMPTIONS!$H$27 * $H$9, IF(J$15=$I$4, J18 * ASSUMPTIONS!$H$27 * $I$9, 0 ))))) -> 1100000 | K35: =IF(K$15=$E$4, K18 * ASSUMPTIONS!$H$27 * $E$9, IF(K$15=$F$4, K18 * ASSUMPTIONS!$H$27 * $F$9, IF(K$15=$G$4, K18 * ASSUMPTIONS!$H$27 * $G$9, IF(K$15=$H$4, K18 * ASSUMPTIONS!$H$27 * $H$9, IF(K$15=$I$4, K18 * ASSUMPTIONS!$H$27 * $I$9, 0 ))))) -> 1650000 | L35: =IF(L$15=$E$4, L18 * ASSUMPTIONS!$H$27 * $E$9, IF(L$15=$F$4, L18 * ASSUMPTIONS!$H$27 * $F$9, IF(L$15=$G$4, L18 * ASSUMPTIONS!$H$27 * $G$9, IF(L$15=$H$4, L18 * ASSUMPTIONS!$H$27 * $H$9, IF(L$15=$I$4, L18 * ASSUMPTIONS!$H$27 * $I$9, 0 ))))) -> 2200000 | ... BL35: =IF(BL$15=$E$4, BL18 * ASSUMPTIONS!$H$27 * $E$9, IF(BL$15=$F$4, BL18 * ASSUMPTIONS!$H$27 * $F$9, IF(BL$15=$G$4, BL18 * ASSUMPTIONS!$H$27 * $G$9, IF(BL$15=$H$4, BL18 * ASSUMPTIONS!$H$27 * $H$9, IF(BL$15=$I$4, BL18 * ASSUMPTIONS!$H$27 * $I$9, 0 ))))) -> 38884290
