Workbook

Sheet COVER
B10: Venture Wolf — SaaS & Software Financial Model (India) Dynamic 60-Month Forecast
B18: Confidential - Generated for internal venture analysis.

Sheet ASSUMPTIONS
B2: ACTIVE SCENARIO: | C2: Base
B4: Particulars | C4: Worst | D4: Base | E4: Best
B5: 1. MACRO-ECONOMIC & TAX (INDIA)
B6: Corporate Tax Rate (%) | C6: 0.3 | D6: 0.25 | E6: 0.2
B7: DPIIT Tax Holiday Active (1=Yes, 0=No) | C7: 0 | D7: 1 | E7: 1
B8: Employer PF Burden (%) | C8: 0.15 | D8: 0.12 | E8: 0.1
B9: 2. REVENUE DRIVERS
B10: Initial Customer Count | C10: 500 | D10: 1000 | E10: 2000
B11: Avg. Monthly Revenue Per User (₹) | C11: 2000 | D11: 2500 | E11: 3500
B12: MoM Growth Rate (%) | C12: 0.05 | D12: 0.15 | E12: 0.25
B13: Monthly Churn Rate (%) | C13: 0.1 | D13: 0.05 | E13: 0.02
B14: 3. COST & OPEX DRIVERS
B15: Direct COGS Margin (%) | C15: 0.45 | D15: 0.3 | E15: 0.2
B16: Annual Payroll Inflation (%) | C16: 0.15 | D16: 0.1 | E16: 0.08
B17: Marketing Spend (% of Revenue) | C17: 0.05 | D17: 0.1 | E17: 0.15
B18: 4. WORKING CAPITAL
B19: Accounts Receivable (Days) | C19: 45 | D19: 30 | E19: 15
B20: Inventory Days (if applicable) | C20: 20 | D20: 12 | E20: 5
B21: Accounts Payable (Days) | C21: 15 | D21: 30 | E21: 45

Sheet FUNDING_REQUIREMENT
B2: Funding Requirement (Tranche Breakdown)
B4: Use of Funds | C4: Amount (₹)
B5: CapEx & Hardware | C5: 5000000
B6: Working Capital Buffer | C6: 3000000
B7: Marketing Launch | C7: 1500000
B8: Contingency | C8: 500000
B9: Total Funding Required | C9: =SUM(C5:C8)

Sheet SUBSCRIBER_FUNNEL
B2: Subscriber Funnel & Growth
B4: Particulars | C4: Month 1 | D4: Month 2 | E4: Month 3 | F4: Month 4 | G4: Month 5 | H4: Month 6 | I4: Month 7 | J4: Month 8 | K4: Month 9 | L4: Month 10 | M4: Month 11 | N4: Month 12 | O4: Month 13 | P4: Month 14 | Q4: Month 15 | R4: Month 16 | S4: Month 17 | T4: Month 18 | U4: Month 19 | V4: Month 20 | W4: Month 21 | X4: Month 22 | Y4: Month 23 | Z4: Month 24 | AA4: Month 25 | AB4: Month 26 | AC4: Month 27 | AD4: Month 28 | AE4: Month 29 | AF4: Month 30 | AG4: Month 31 | AH4: Month 32 | AI4: Month 33 | AJ4: Month 34 | AK4: Month 35 | AL4: Month 36 | AM4: Month 37 | AN4: Month 38 | AO4: Month 39 | AP4: Month 40 | AQ4: Month 41 | AR4: Month 42 | AS4: Month 43 | AT4: Month 44 | AU4: Month 45 | AV4: Month 46 | AW4: Month 47 | AX4: Month 48 | AY4: Month 49 | AZ4: Month 50 | BA4: Month 51 | BB4: Month 52 | BC4: Month 53 | BD4: Month 54 | BE4: Month 55 | BF4: Month 56 | BG4: Month 57 | BH4: Month 58 | BI4: Month 59 | BJ4: Month 60
B5: Starting Subscribers | C5: 0 | D5: =C8 | E5: =D8 | F5: =E8 | G5: =F8 | H5: =G8 | I5: =H8 | J5: =I8 | K5: =J8 | ... BJ5: =BI8
B6: New Subscribers | C6: =INDEX(ASSUMPTIONS!$C$10:$E$10, 1, MATCH(ASSUMPTIONS!$C$2, ASSUMPTIONS!$C$4:$E$4, 0)) / 2500 | D6: =C6 * (1 + INDEX(ASSUMPTIONS!$C$12:$E$12, 1, MATCH(ASSUMPTIONS!$C$2, ASSUMPTIONS!$C$4:$E$4, 0))) | E6: =D6 * (1 + INDEX(ASSUMPTIONS!$C$12:$E$12, 1, MATCH(ASSUMPTIONS!$C$2, ASSUMPTIONS!$C$4:$E$4, 0))) | F6: =E6 * (1 + INDEX(ASSUMPTIONS!$C$12:$E$12, 1, MATCH(ASSUMPTIONS!$C$2, ASSUMPTIONS!$C$4:$E$4, 0))) | G6: =F6 * (1 + INDEX(ASSUMPTIONS!$C$12:$E$12, 1, MATCH(ASSUMPTIONS!$C$2, ASSUMPTIONS!$C$4:$E$4, 0))) | H6: =G6 * (1 + INDEX(ASSUMPTIONS!$C$12:$E$12, 1, MATCH(ASSUMPTIONS!$C$2, ASSUMPTIONS!$C$4:$E$4, 0))) | I6: =H6 * (1 + INDEX(ASSUMPTIONS!$C$12:$E$12, 1, MATCH(ASSUMPTIONS!$C$2, ASSUMPTIONS!$C$4:$E$4, 0))) | J6: =I6 * (1 + INDEX(ASSUMPTIONS!$C$12:$E$12, 1, MATCH(ASSUMPTIONS!$C$2, ASSUMPTIONS!$C$4:$E$4, 0))) | K6: =J6 * (1 + INDEX(ASSUMPTIONS!$C$12:$E$12, 1, MATCH(ASSUMPTIONS!$C$2, ASSUMPTIONS!$C$4:$E$4, 0))) | ... BJ6: =BI6 * (1 + INDEX(ASSUMPTIONS!$C$12:$E$12, 1, MATCH(ASSUMPTIONS!$C$2, ASSUMPTIONS!$C$4:$E$4, 0)))
B7: Churned Subscribers | C7: =C5 * INDEX(ASSUMPTIONS!$C$13:$E$13, 1, MATCH(ASSUMPTIONS!$C$2, ASSUMPTIONS!$C$4:$E$4, 0)) | D7: =D5 * INDEX(ASSUMPTIONS!$C$13:$E$13, 1, MATCH(ASSUMPTIONS!$C$2, ASSUMPTIONS!$C$4:$E$4, 0)) | E7: =E5 * INDEX(ASSUMPTIONS!$C$13:$E$13, 1, MATCH(ASSUMPTIONS!$C$2, ASSUMPTIONS!$C$4:$E$4, 0)) | F7: =F5 * INDEX(ASSUMPTIONS!$C$13:$E$13, 1, MATCH(ASSUMPTIONS!$C$2, ASSUMPTIONS!$C$4:$E$4, 0)) | G7: =G5 * INDEX(ASSUMPTIONS!$C$13:$E$13, 1, MATCH(ASSUMPTIONS!$C$2, ASSUMPTIONS!$C$4:$E$4, 0)) | H7: =H5 * INDEX(ASSUMPTIONS!$C$13:$E$13, 1, MATCH(ASSUMPTIONS!$C$2, ASSUMPTIONS!$C$4:$E$4, 0)) | I7: =I5 * INDEX(ASSUMPTIONS!$C$13:$E$13, 1, MATCH(ASSUMPTIONS!$C$2, ASSUMPTIONS!$C$4:$E$4, 0)) | J7: =J5 * INDEX(ASSUMPTIONS!$C$13:$E$13, 1, MATCH(ASSUMPTIONS!$C$2, ASSUMPTIONS!$C$4:$E$4, 0)) | ... BJ7: =BJ5 * INDEX(ASSUMPTIONS!$C$13:$E$13, 1, MATCH(ASSUMPTIONS!$C$2, ASSUMPTIONS!$C$4:$E$4, 0))
B8: Ending Subscribers | C8: =C5 + C6 - C7 | D8: =D5 + D6 - D7 | E8: =E5 + E6 - E7 | F8: =F5 + F6 - F7 | G8: =G5 + G6 - G7 | H8: =H5 + H6 - H7 | I8: =I5 + I6 - I7 | J8: =J5 + J6 - J7 | ... BJ8: =BJ5 + BJ6 - BJ7

Sheet REVENUE_ENGINE
B2: MRR & Revenue Engine
B4: Particulars | C4: Month 1 | D4: Month 2 | E4: Month 3 | F4: Month 4 | G4: Month 5 | H4: Month 6 | I4: Month 7 | J4: Month 8 | K4: Month 9 | L4: Month 10 | M4: Month 11 | N4: Month 12 | O4: Month 13 | P4: Month 14 | Q4: Month 15 | R4: Month 16 | S4: Month 17 | T4: Month 18 | U4: Month 19 | V4: Month 20 | W4: Month 21 | X4: Month 22 | Y4: Month 23 | Z4: Month 24 | AA4: Month 25 | AB4: Month 26 | AC4: Month 27 | AD4: Month 28 | AE4: Month 29 | AF4: Month 30 | AG4: Month 31 | AH4: Month 32 | AI4: Month 33 | AJ4: Month 34 | AK4: Month 35 | AL4: Month 36 | AM4: Month 37 | AN4: Month 38 | AO4: Month 39 | AP4: Month 40 | AQ4: Month 41 | AR4: Month 42 | AS4: Month 43 | AT4: Month 44 | AU4: Month 45 | AV4: Month 46 | AW4: Month 47 | AX4: Month 48 | AY4: Month 49 | AZ4: Month 50 | BA4: Month 51 | BB4: Month 52 | BC4: Month 53 | BD4: Month 54 | BE4: Month 55 | BF4: Month 56 | BG4: Month 57 | BH4: Month 58 | BI4: Month 59 | BJ4: Month 60
B5: ARPU (Average Revenue Per User) (₹) | C5: 2500 | D5: 2500 | E5: 2500 | F5: 2500 | G5: 2500 | H5: 2500 | I5: 2500 | J5: 2500 | K5: 2500 | L5: 2500 | M5: 2500 | N5: 2500 | O5: 2500 | P5: 2500 | Q5: 2500 | R5: 2500 | S5: 2500 | T5: 2500 | U5: 2500 | V5: 2500 | W5: 2500 | X5: 2500 | Y5: 2500 | Z5: 2500 | AA5: 2500 | AB5: 2500 | AC5: 2500 | AD5: 2500 | AE5: 2500 | AF5: 2500 | AG5: 2500 | AH5: 2500 | AI5: 2500 | AJ5: 2500 | AK5: 2500 | AL5: 2500 | AM5: 2500 | AN5: 2500 | AO5: 2500 | AP5: 2500 | AQ5: 2500 | AR5: 2500 | AS5: 2500 | AT5: 2500 | AU5: 2500 | AV5: 2500 | AW5: 2500 | AX5: 2500 | AY5: 2500 | AZ5: 2500 | BA5: 2500 | BB5: 2500 | BC5: 2500 | BD5: 2500 | BE5: 2500 | BF5: 2500 | BG5: 2500 | BH5: 2500 | BI5: 2500 | BJ5: 2500
B6: Total MRR (Total Revenue) (₹) | C6: ='SUBSCRIBER_FUNNEL'!C8 * C5 | D6: ='SUBSCRIBER_FUNNEL'!D8 * D5 | E6: ='SUBSCRIBER_FUNNEL'!E8 * E5 | F6: ='SUBSCRIBER_FUNNEL'!F8 * F5 | G6: ='SUBSCRIBER_FUNNEL'!G8 * G5 | H6: ='SUBSCRIBER_FUNNEL'!H8 * H5 | I6: ='SUBSCRIBER_FUNNEL'!I8 * I5 | J6: ='SUBSCRIBER_FUNNEL'!J8 * J5 | ... BJ6: ='SUBSCRIBER_FUNNEL'!BJ8 * BJ5

Sheet COGS_ENGINE
B2: Cloud Infrastructure & Variable COGS
B4: Particulars | C4: Month 1 | D4: Month 2 | E4: Month 3 | F4: Month 4 | G4: Month 5 | H4: Month 6 | I4: Month 7 | J4: Month 8 | K4: Month 9 | L4: Month 10 | M4: Month 11 | N4: Month 12 | O4: Month 13 | P4: Month 14 | Q4: Month 15 | R4: Month 16 | S4: Month 17 | T4: Month 18 | U4: Month 19 | V4: Month 20 | W4: Month 21 | X4: Month 22 | Y4: Month 23 | Z4: Month 24 | AA4: Month 25 | AB4: Month 26 | AC4: Month 27 | AD4: Month 28 | AE4: Month 29 | AF4: Month 30 | AG4: Month 31 | AH4: Month 32 | AI4: Month 33 | AJ4: Month 34 | AK4: Month 35 | AL4: Month 36 | AM4: Month 37 | AN4: Month 38 | AO4: Month 39 | AP4: Month 40 | AQ4: Month 41 | AR4: Month 42 | AS4: Month 43 | AT4: Month 44 | AU4: Month 45 | AV4: Month 46 | AW4: Month 47 | AX4: Month 48 | AY4: Month 49 | AZ4: Month 50 | BA4: Month 51 | BB4: Month 52 | BC4: Month 53 | BD4: Month 54 | BE4: Month 55 | BF4: Month 56 | BG4: Month 57 | BH4: Month 58 | BI4: Month 59 | BJ4: Month 60
B5: Cloud & Server Hosting (₹) | C5: =10000 + (50 * 'SUBSCRIBER_FUNNEL'!C8) | D5: =10000 + (50 * 'SUBSCRIBER_FUNNEL'!D8) | E5: =10000 + (50 * 'SUBSCRIBER_FUNNEL'!E8) | F5: =10000 + (50 * 'SUBSCRIBER_FUNNEL'!F8) | G5: =10000 + (50 * 'SUBSCRIBER_FUNNEL'!G8) | H5: =10000 + (50 * 'SUBSCRIBER_FUNNEL'!H8) | I5: =10000 + (50 * 'SUBSCRIBER_FUNNEL'!I8) | J5: =10000 + (50 * 'SUBSCRIBER_FUNNEL'!J8) | ... BJ5: =10000 + (50 * 'SUBSCRIBER_FUNNEL'!BJ8)
B6: Payment Gateway Fees (2%) (₹) | C6: =0.02 * 'REVENUE_ENGINE'!C6 | D6: =0.02 * 'REVENUE_ENGINE'!D6 | E6: =0.02 * 'REVENUE_ENGINE'!E6 | F6: =0.02 * 'REVENUE_ENGINE'!F6 | G6: =0.02 * 'REVENUE_ENGINE'!G6 | H6: =0.02 * 'REVENUE_ENGINE'!H6 | I6: =0.02 * 'REVENUE_ENGINE'!I6 | J6: =0.02 * 'REVENUE_ENGINE'!J6 | ... BJ6: =0.02 * 'REVENUE_ENGINE'!BJ6
B7: Total COGS (₹) | C7: =C5 + C6 | D7: =D5 + D6 | E7: =E5 + E6 | F7: =F5 + F6 | G7: =G5 + G6 | H7: =H5 + H6 | I7: =I5 + I6 | J7: =J5 + J6 | ... BJ7: =BJ5 + BJ6

Sheet HR_AND_OPEX
B2: HR & Operating Expenses (OpEx)
B4: Particulars | C4: Month 1 | D4: Month 2 | E4: Month 3 | F4: Month 4 | G4: Month 5 | H4: Month 6 | I4: Month 7 | J4: Month 8 | K4: Month 9 | L4: Month 10 | M4: Month 11 | N4: Month 12 | O4: Month 13 | P4: Month 14 | Q4: Month 15 | R4: Month 16 | S4: Month 17 | T4: Month 18 | U4: Month 19 | V4: Month 20 | W4: Month 21 | X4: Month 22 | Y4: Month 23 | Z4: Month 24 | AA4: Month 25 | AB4: Month 26 | AC4: Month 27 | AD4: Month 28 | AE4: Month 29 | AF4: Month 30 | AG4: Month 31 | AH4: Month 32 | AI4: Month 33 | AJ4: Month 34 | AK4: Month 35 | AL4: Month 36 | AM4: Month 37 | AN4: Month 38 | AO4: Month 39 | AP4: Month 40 | AQ4: Month 41 | AR4: Month 42 | AS4: Month 43 | AT4: Month 44 | AU4: Month 45 | AV4: Month 46 | AW4: Month 47 | AX4: Month 48 | AY4: Month 49 | AZ4: Month 50 | BA4: Month 51 | BB4: Month 52 | BC4: Month 53 | BD4: Month 54 | BE4: Month 55 | BF4: Month 56 | BG4: Month 57 | BH4: Month 58 | BI4: Month 59 | BJ4: Month 60
B5: Engineering & Product (₹) | C5: =300000 * ((1 + INDEX(ASSUMPTIONS!$C$16:$E$16, 1, MATCH(ASSUMPTIONS!$C$2, ASSUMPTIONS!$C$4:$E$4, 0))) ^ 0) | D5: =300000 * ((1 + INDEX(ASSUMPTIONS!$C$16:$E$16, 1, MATCH(ASSUMPTIONS!$C$2, ASSUMPTIONS!$C$4:$E$4, 0))) ^ 0) | E5: =300000 * ((1 + INDEX(ASSUMPTIONS!$C$16:$E$16, 1, MATCH(ASSUMPTIONS!$C$2, ASSUMPTIONS!$C$4:$E$4, 0))) ^ 0) | F5: =300000 * ((1 + INDEX(ASSUMPTIONS!$C$16:$E$16, 1, MATCH(ASSUMPTIONS!$C$2, ASSUMPTIONS!$C$4:$E$4, 0))) ^ 0) | G5: =300000 * ((1 + INDEX(ASSUMPTIONS!$C$16:$E$16, 1, MATCH(ASSUMPTIONS!$C$2, ASSUMPTIONS!$C$4:$E$4, 0))) ^ 0) | H5: =300000 * ((1 + INDEX(ASSUMPTIONS!$C$16:$E$16, 1, MATCH(ASSUMPTIONS!$C$2, ASSUMPTIONS!$C$4:$E$4, 0))) ^ 0) | I5: =300000 * ((1 + INDEX(ASSUMPTIONS!$C$16:$E$16, 1, MATCH(ASSUMPTIONS!$C$2, ASSUMPTIONS!$C$4:$E$4, 0))) ^ 0) | J5: =300000 * ((1 + INDEX(ASSUMPTIONS!$C$16:$E$16, 1, MATCH(ASSUMPTIONS!$C$2, ASSUMPTIONS!$C$4:$E$4, 0))) ^ 0) | ... N5: =300000 * ((1 + INDEX(ASSUMPTIONS!$C$16:$E$16, 1, MATCH(ASSUMPTIONS!$C$2, ASSUMPTIONS!$C$4:$E$4, 0))) ^ 0) | O5: =300000 * ((1 + INDEX(ASSUMPTIONS!$C$16:$E$16, 1, MATCH(ASSUMPTIONS!$C$2, ASSUMPTIONS!$C$4:$E$4, 0))) ^ 1) | P5: =300000 * ((1 + INDEX(ASSUMPTIONS!$C$16:$E$16, 1, MATCH(ASSUMPTIONS!$C$2, ASSUMPTIONS!$C$4:$E$4, 0))) ^ 1) | Q5: =300000 * ((1 + INDEX(ASSUMPTIONS!$C$16:$E$16, 1, MATCH(ASSUMPTIONS!$C$2, ASSUMPTIONS!$C$4:$E$4, 0))) ^ 1) | R5: =300000 * ((1 + INDEX(ASSUMPTIONS!$C$16:$E$16, 1, MATCH(ASSUMPTIONS!$C$2, ASSUMPTIONS!$C$4:$E$4, 0))) ^ 1) | S5: =300000 * ((1 + INDEX(ASSUMPTIONS!$C$16:$E$16, 1, MATCH(ASSUMPTIONS!$C$2, ASSUMPTIONS!$C$4:$E$4, 0))) ^ 1) | T5: =300000 * ((1 + INDEX(ASSUMPTIONS!$C$16:$E$16, 1, MATCH(ASSUMPTIONS!$C$2, ASSUMPTIONS!$C$4:$E$4, 0))) ^ 1) | U5: =300000 * ((1 + INDEX(ASSUMPTIONS!$C$16:$E$16, 1, MATCH(ASSUMPTIONS!$C$2, ASSUMPTIONS!$C$4:$E$4, 0))) ^ 1) | V5: =300000 * ((1 + INDEX(ASSUMPTIONS!$C$16:$E$16, 1, MATCH(ASSUMPTIONS!$C$2, ASSUMPTIONS!$C$4:$E$4, 0))) ^ 1) | ... Z5: =300000 * ((1 + INDEX(ASSUMPTIONS!$C$16:$E$16, 1, MATCH(ASSUMPTIONS!$C$2, ASSUMPTIONS!$C$4:$E$4, 0))) ^ 1) | AA5: =300000 * ((1 + INDEX(ASSUMPTIONS!$C$16:$E$16, 1, MATCH(ASSUMPTIONS!$C$2, ASSUMPTIONS!$C$4:$E$4, 0))) ^ 2) | AB5: =300000 * ((1 + INDEX(ASSUMPTIONS!$C$16:$E$16, 1, MATCH(ASSUMPTIONS!$C$2, ASSUMPTIONS!$C$4:$E$4, 0))) ^ 2) | AC5: =300000 * ((1 + INDEX(ASSUMPTIONS!$C$16:$E$16, 1, MATCH(ASSUMPTIONS!$C$2, ASSUMPTIONS!$C$4:$E$4, 0))) ^ 2) | AD5: =300000 * ((1 + INDEX(ASSUMPTIONS!$C$16:$E$16, 1, MATCH(ASSUMPTIONS!$C$2, ASSUMPTIONS!$C$4:$E$4, 0))) ^ 2) | AE5: =300000 * ((1 + INDEX(ASSUMPTIONS!$C$16:$E$16, 1, MATCH(ASSUMPTIONS!$C$2, ASSUMPTIONS!$C$4:$E$4, 0))) ^ 2) | AF5: =300000 * ((1 + INDEX(ASSUMPTIONS!$C$16:$E$16, 1, MATCH(ASSUMPTIONS!$C$2, ASSUMPTIONS!$C$4:$E$4, 0))) ^ 2) | AG5: =300000 * ((1 + INDEX(ASSUMPTIONS!$C$16:$E$16, 1, MATCH(ASSUMPTIONS!$C$2, ASSUMPTIONS!$C$4:$E$4, 0))) ^ 2) | AH5: =300000 * ((1 + INDEX(ASSUMPTIONS!$C$16:$E$16, 1, MATCH(ASSUMPTIONS!$C$2, ASSUMPTIONS!$C$4:$E$4, 0))) ^ 2) | ... AL5: =300000 * ((1 + INDEX(ASSUMPTIONS!$C$16:$E$16, 1, MATCH(ASSUMPTIONS!$C$2, ASSUMPTIONS!$C$4:$E$4, 0))) ^ 2) | AM5: =300000 * ((1 + INDEX(ASSUMPTIONS!$C$16:$E$16, 1, MATCH(ASSUMPTIONS!$C$2, ASSUMPTIONS!$C$4:$E$4, 0))) ^ 3) | AN5: =300000 * ((1 + INDEX(ASSUMPTIONS!$C$16:$E$16, 1, MATCH(ASSUMPTIONS!$C$2, ASSUMPTIONS!$C$4:$E$4, 0))) ^ 3) | AO5: =300000 * ((1 + INDEX(ASSUMPTIONS!$C$16:$E$16, 1, MATCH(ASSUMPTIONS!$C$2, ASSUMPTIONS!$C$4:$E$4, 0))) ^ 3) | AP5: =300000 * ((1 + INDEX(ASSUMPTIONS!$C$16:$E$16, 1, MATCH(ASSUMPTIONS!$C$2, ASSUMPTIONS!$C$4:$E$4, 0))) ^ 3) | AQ5: =300000 * ((1 + INDEX(ASSUMPTIONS!$C$16:$E$16, 1, MATCH(ASSUMPTIONS!$C$2, ASSUMPTIONS!$C$4:$E$4, 0))) ^ 3) | AR5: =300000 * ((1 + INDEX(ASSUMPTIONS!$C$16:$E$16, 1, MATCH(ASSUMPTIONS!$C$2, ASSUMPTIONS!$C$4:$E$4, 0))) ^ 3) | AS5: =300000 * ((1 + INDEX(ASSUMPTIONS!$C$16:$E$16, 1, MATCH(ASSUMPTIONS!$C$2, ASSUMPTIONS!$C$4:$E$4, 0))) ^ 3) | AT5: =300000 * ((1 + INDEX(ASSUMPTIONS!$C$16:$E$16, 1, MATCH(ASSUMPTIONS!$C$2, ASSUMPTIONS!$C$4:$E$4, 0))) ^ 3) | ... AX5: =300000 * ((1 + INDEX(ASSUMPTIONS!$C$16:$E$16, 1, MATCH(ASSUMPTIONS!$C$2, ASSUMPTIONS!$C$4:$E$4, 0))) ^ 3) | AY5: =300000 * ((1 + INDEX(ASSUMPTIONS!$C$16:$E$16, 1, MATCH(ASSUMPTIONS!$C$2, ASSUMPTIONS!$C$4:$E$4, 0))) ^ 4) | AZ5: =300000 * ((1 + INDEX(ASSUMPTIONS!$C$16:$E$16, 1, MATCH(ASSUMPTIONS!$C$2, ASSUMPTIONS!$C$4:$E$4, 0))) ^ 4) | BA5: =300000 * ((1 + INDEX(ASSUMPTIONS!$C$16:$E$16, 1, MATCH(ASSUMPTIONS!$C$2, ASSUMPTIONS!$C$4:$E$4, 0))) ^ 4) | BB5: =300000 * ((1 + INDEX(ASSUMPTIONS!$C$16:$E$16, 1, MATCH(ASSUMPTIONS!$C$2, ASSUMPTIONS!$C$4:$E$4, 0))) ^ 4) | BC5: =300000 * ((1 + INDEX(ASSUMPTIONS!$C$16:$E$16, 1, MATCH(ASSUMPTIONS!$C$2, ASSUMPTIONS!$C$4:$E$4, 0))) ^ 4) | BD5: =300000 * ((1 + INDEX(ASSUMPTIONS!$C$16:$E$16, 1, MATCH(ASSUMPTIONS!$C$2, ASSUMPTIONS!$C$4:$E$4, 0))) ^ 4) | BE5: =300000 * ((1 + INDEX(ASSUMPTIONS!$C$16:$E$16, 1, MATCH(ASSUMPTIONS!$C$2, ASSUMPTIONS!$C$4:$E$4, 0))) ^ 4) | BF5: =300000 * ((1 + INDEX(ASSUMPTIONS!$C$16:$E$16, 1, MATCH(ASSUMPTIONS!$C$2, ASSUMPTIONS!$C$4:$E$4, 0))) ^ 4) | ... BJ5: =300000 * ((1 + INDEX(ASSUMPTIONS!$C$16:$E$16, 1, MATCH(ASSUMPTIONS!$C$2, ASSUMPTIONS!$C$4:$E$4, 0))) ^ 4)
B6: Sales & Marketing (CAC) (₹) | C6: ='REVENUE_ENGINE'!C6 * INDEX(ASSUMPTIONS!$C$17:$E$17, 1, MATCH(ASSUMPTIONS!$C$2, ASSUMPTIONS!$C$4:$E$4, 0)) | D6: ='REVENUE_ENGINE'!D6 * INDEX(ASSUMPTIONS!$C$17:$E$17, 1, MATCH(ASSUMPTIONS!$C$2, ASSUMPTIONS!$C$4:$E$4, 0)) | E6: ='REVENUE_ENGINE'!E6 * INDEX(ASSUMPTIONS!$C$17:$E$17, 1, MATCH(ASSUMPTIONS!$C$2, ASSUMPTIONS!$C$4:$E$4, 0)) | F6: ='REVENUE_ENGINE'!F6 * INDEX(ASSUMPTIONS!$C$17:$E$17, 1, MATCH(ASSUMPTIONS!$C$2, ASSUMPTIONS!$C$4:$E$4, 0)) | G6: ='REVENUE_ENGINE'!G6 * INDEX(ASSUMPTIONS!$C$17:$E$17, 1, MATCH(ASSUMPTIONS!$C$2, ASSUMPTIONS!$C$4:$E$4, 0)) | H6: ='REVENUE_ENGINE'!H6 * INDEX(ASSUMPTIONS!$C$17:$E$17, 1, MATCH(ASSUMPTIONS!$C$2, ASSUMPTIONS!$C$4:$E$4, 0)) | I6: ='REVENUE_ENGINE'!I6 * INDEX(ASSUMPTIONS!$C$17:$E$17, 1, MATCH(ASSUMPTIONS!$C$2, ASSUMPTIONS!$C$4:$E$4, 0)) | J6: ='REVENUE_ENGINE'!J6 * INDEX(ASSUMPTIONS!$C$17:$E$17, 1, MATCH(ASSUMPTIONS!$C$2, ASSUMPTIONS!$C$4:$E$4, 0)) | ... BJ6: ='REVENUE_ENGINE'!BJ6 * INDEX(ASSUMPTIONS!$C$17:$E$17, 1, MATCH(ASSUMPTIONS!$C$2, ASSUMPTIONS!$C$4:$E$4, 0))
B7: Customer Success (₹) | C7: =100000 * ((1 + INDEX(ASSUMPTIONS!$C$16:$E$16, 1, MATCH(ASSUMPTIONS!$C$2, ASSUMPTIONS!$C$4:$E$4, 0))) ^ 0) | D7: =100000 * ((1 + INDEX(ASSUMPTIONS!$C$16:$E$16, 1, MATCH(ASSUMPTIONS!$C$2, ASSUMPTIONS!$C$4:$E$4, 0))) ^ 0) | E7: =100000 * ((1 + INDEX(ASSUMPTIONS!$C$16:$E$16, 1, MATCH(ASSUMPTIONS!$C$2, ASSUMPTIONS!$C$4:$E$4, 0))) ^ 0) | F7: =100000 * ((1 + INDEX(ASSUMPTIONS!$C$16:$E$16, 1, MATCH(ASSUMPTIONS!$C$2, ASSUMPTIONS!$C$4:$E$4, 0))) ^ 0) | G7: =100000 * ((1 + INDEX(ASSUMPTIONS!$C$16:$E$16, 1, MATCH(ASSUMPTIONS!$C$2, ASSUMPTIONS!$C$4:$E$4, 0))) ^ 0) | H7: =100000 * ((1 + INDEX(ASSUMPTIONS!$C$16:$E$16, 1, MATCH(ASSUMPTIONS!$C$2, ASSUMPTIONS!$C$4:$E$4, 0))) ^ 0) | I7: =100000 * ((1 + INDEX(ASSUMPTIONS!$C$16:$E$16, 1, MATCH(ASSUMPTIONS!$C$2, ASSUMPTIONS!$C$4:$E$4, 0))) ^ 0) | J7: =100000 * ((1 + INDEX(ASSUMPTIONS!$C$16:$E$16, 1, MATCH(ASSUMPTIONS!$C$2, ASSUMPTIONS!$C$4:$E$4, 0))) ^ 0) | ... N7: =100000 * ((1 + INDEX(ASSUMPTIONS!$C$16:$E$16, 1, MATCH(ASSUMPTIONS!$C$2, ASSUMPTIONS!$C$4:$E$4, 0))) ^ 0) | O7: =100000 * ((1 + INDEX(ASSUMPTIONS!$C$16:$E$16, 1, MATCH(ASSUMPTIONS!$C$2, ASSUMPTIONS!$C$4:$E$4, 0))) ^ 1) | P7: =100000 * ((1 + INDEX(ASSUMPTIONS!$C$16:$E$16, 1, MATCH(ASSUMPTIONS!$C$2, ASSUMPTIONS!$C$4:$E$4, 0))) ^ 1) | Q7: =100000 * ((1 + INDEX(ASSUMPTIONS!$C$16:$E$16, 1, MATCH(ASSUMPTIONS!$C$2, ASSUMPTIONS!$C$4:$E$4, 0))) ^ 1) | R7: =100000 * ((1 + INDEX(ASSUMPTIONS!$C$16:$E$16, 1, MATCH(ASSUMPTIONS!$C$2, ASSUMPTIONS!$C$4:$E$4, 0))) ^ 1) | S7: =100000 * ((1 + INDEX(ASSUMPTIONS!$C$16:$E$16, 1, MATCH(ASSUMPTIONS!$C$2, ASSUMPTIONS!$C$4:$E$4, 0))) ^ 1) | T7: =100000 * ((1 + INDEX(ASSUMPTIONS!$C$16:$E$16, 1, MATCH(ASSUMPTIONS!$C$2, ASSUMPTIONS!$C$4:$E$4, 0))) ^ 1) | U7: =100000 * ((1 + INDEX(ASSUMPTIONS!$C$16:$E$16, 1, MATCH(ASSUMPTIONS!$C$2, ASSUMPTIONS!$C$4:$E$4, 0))) ^ 1) | V7: =100000 * ((1 + INDEX(ASSUMPTIONS!$C$16:$E$16, 1, MATCH(ASSUMPTIONS!$C$2, ASSUMPTIONS!$C$4:$E$4, 0))) ^ 1) | ... Z7: =100000 * ((1 + INDEX(ASSUMPTIONS!$C$16:$E$16, 1, MATCH(ASSUMPTIONS!$C$2, ASSUMPTIONS!$C$4:$E$4, 0))) ^ 1) | AA7: =100000 * ((1 + INDEX(ASSUMPTIONS!$C$16:$E$16, 1, MATCH(ASSUMPTIONS!$C$2, ASSUMPTIONS!$C$4:$E$4, 0))) ^ 2) | AB7: =100000 * ((1 + INDEX(ASSUMPTIONS!$C$16:$E$16, 1, MATCH(ASSUMPTIONS!$C$2, ASSUMPTIONS!$C$4:$E$4, 0))) ^ 2) | AC7: =100000 * ((1 + INDEX(ASSUMPTIONS!$C$16:$E$16, 1, MATCH(ASSUMPTIONS!$C$2, ASSUMPTIONS!$C$4:$E$4, 0))) ^ 2) | AD7: =100000 * ((1 + INDEX(ASSUMPTIONS!$C$16:$E$16, 1, MATCH(ASSUMPTIONS!$C$2, ASSUMPTIONS!$C$4:$E$4, 0))) ^ 2) | AE7: =100000 * ((1 + INDEX(ASSUMPTIONS!$C$16:$E$16, 1, MATCH(ASSUMPTIONS!$C$2, ASSUMPTIONS!$C$4:$E$4, 0))) ^ 2) | AF7: =100000 * ((1 + INDEX(ASSUMPTIONS!$C$16:$E$16, 1, MATCH(ASSUMPTIONS!$C$2, ASSUMPTIONS!$C$4:$E$4, 0))) ^ 2) | AG7: =100000 * ((1 + INDEX(ASSUMPTIONS!$C$16:$E$16, 1, MATCH(ASSUMPTIONS!$C$2, ASSUMPTIONS!$C$4:$E$4, 0))) ^ 2) | AH7: =100000 * ((1 + INDEX(ASSUMPTIONS!$C$16:$E$16, 1, MATCH(ASSUMPTIONS!$C$2, ASSUMPTIONS!$C$4:$E$4, 0))) ^ 2) | ... AL7: =100000 * ((1 + INDEX(ASSUMPTIONS!$C$16:$E$16, 1, MATCH(ASSUMPTIONS!$C$2, ASSUMPTIONS!$C$4:$E$4, 0))) ^ 2) | AM7: =100000 * ((1 + INDEX(ASSUMPTIONS!$C$16:$E$16, 1, MATCH(ASSUMPTIONS!$C$2, ASSUMPTIONS!$C$4:$E$4, 0))) ^ 3) | AN7: =100000 * ((1 + INDEX(ASSUMPTIONS!$C$16:$E$16, 1, MATCH(ASSUMPTIONS!$C$2, ASSUMPTIONS!$C$4:$E$4, 0))) ^ 3) | AO7: =100000 * ((1 + INDEX(ASSUMPTIONS!$C$16:$E$16, 1, MATCH(ASSUMPTIONS!$C$2, ASSUMPTIONS!$C$4:$E$4, 0))) ^ 3) | AP7: =100000 * ((1 + INDEX(ASSUMPTIONS!$C$16:$E$16, 1, MATCH(ASSUMPTIONS!$C$2, ASSUMPTIONS!$C$4:$E$4, 0))) ^ 3) | AQ7: =100000 * ((1 + INDEX(ASSUMPTIONS!$C$16:$E$16, 1, MATCH(ASSUMPTIONS!$C$2, ASSUMPTIONS!$C$4:$E$4, 0))) ^ 3) | AR7: =100000 * ((1 + INDEX(ASSUMPTIONS!$C$16:$E$16, 1, MATCH(ASSUMPTIONS!$C$2, ASSUMPTIONS!$C$4:$E$4, 0))) ^ 3) | AS7: =100000 * ((1 + INDEX(ASSUMPTIONS!$C$16:$E$16, 1, MATCH(ASSUMPTIONS!$C$2, ASSUMPTIONS!$C$4:$E$4, 0))) ^ 3) | AT7: =100000 * ((1 + INDEX(ASSUMPTIONS!$C$16:$E$16, 1, MATCH(ASSUMPTIONS!$C$2, ASSUMPTIONS!$C$4:$E$4, 0))) ^ 3) | ... AX7: =100000 * ((1 + INDEX(ASSUMPTIONS!$C$16:$E$16, 1, MATCH(ASSUMPTIONS!$C$2, ASSUMPTIONS!$C$4:$E$4, 0))) ^ 3) | AY7: =100000 * ((1 + INDEX(ASSUMPTIONS!$C$16:$E$16, 1, MATCH(ASSUMPTIONS!$C$2, ASSUMPTIONS!$C$4:$E$4, 0))) ^ 4) | AZ7: =100000 * ((1 + INDEX(ASSUMPTIONS!$C$16:$E$16, 1, MATCH(ASSUMPTIONS!$C$2, ASSUMPTIONS!$C$4:$E$4, 0))) ^ 4) | BA7: =100000 * ((1 + INDEX(ASSUMPTIONS!$C$16:$E$16, 1, MATCH(ASSUMPTIONS!$C$2, ASSUMPTIONS!$C$4:$E$4, 0))) ^ 4) | BB7: =100000 * ((1 + INDEX(ASSUMPTIONS!$C$16:$E$16, 1, MATCH(ASSUMPTIONS!$C$2, ASSUMPTIONS!$C$4:$E$4, 0))) ^ 4) | BC7: =100000 * ((1 + INDEX(ASSUMPTIONS!$C$16:$E$16, 1, MATCH(ASSUMPTIONS!$C$2, ASSUMPTIONS!$C$4:$E$4, 0))) ^ 4) | BD7: =100000 * ((1 + INDEX(ASSUMPTIONS!$C$16:$E$16, 1, MATCH(ASSUMPTIONS!$C$2, ASSUMPTIONS!$C$4:$E$4, 0))) ^ 4) | BE7: =100000 * ((1 + INDEX(ASSUMPTIONS!$C$16:$E$16, 1, MATCH(ASSUMPTIONS!$C$2, ASSUMPTIONS!$C$4:$E$4, 0))) ^ 4) | BF7: =100000 * ((1 + INDEX(ASSUMPTIONS!$C$16:$E$16, 1, MATCH(ASSUMPTIONS!$C$2, ASSUMPTIONS!$C$4:$E$4, 0))) ^ 4) | ... BJ7: =100000 * ((1 + INDEX(ASSUMPTIONS!$C$16:$E$16, 1, MATCH(ASSUMPTIONS!$C$2, ASSUMPTIONS!$C$4:$E$4, 0))) ^ 4)
B8: Founders (₹) | C8: =150000 * ((1 + INDEX(ASSUMPTIONS!$C$16:$E$16, 1, MATCH(ASSUMPTIONS!$C$2, ASSUMPTIONS!$C$4:$E$4, 0))) ^ 0) | D8: =150000 * ((1 + INDEX(ASSUMPTIONS!$C$16:$E$16, 1, MATCH(ASSUMPTIONS!$C$2, ASSUMPTIONS!$C$4:$E$4, 0))) ^ 0) | E8: =150000 * ((1 + INDEX(ASSUMPTIONS!$C$16:$E$16, 1, MATCH(ASSUMPTIONS!$C$2, ASSUMPTIONS!$C$4:$E$4, 0))) ^ 0) | F8: =150000 * ((1 + INDEX(ASSUMPTIONS!$C$16:$E$16, 1, MATCH(ASSUMPTIONS!$C$2, ASSUMPTIONS!$C$4:$E$4, 0))) ^ 0) | G8: =150000 * ((1 + INDEX(ASSUMPTIONS!$C$16:$E$16, 1, MATCH(ASSUMPTIONS!$C$2, ASSUMPTIONS!$C$4:$E$4, 0))) ^ 0) | H8: =150000 * ((1 + INDEX(ASSUMPTIONS!$C$16:$E$16, 1, MATCH(ASSUMPTIONS!$C$2, ASSUMPTIONS!$C$4:$E$4, 0))) ^ 0) | I8: =150000 * ((1 + INDEX(ASSUMPTIONS!$C$16:$E$16, 1, MATCH(ASSUMPTIONS!$C$2, ASSUMPTIONS!$C$4:$E$4, 0))) ^ 0) | J8: =150000 * ((1 + INDEX(ASSUMPTIONS!$C$16:$E$16, 1, MATCH(ASSUMPTIONS!$C$2, ASSUMPTIONS!$C$4:$E$4, 0))) ^ 0) | ... N8: =150000 * ((1 + INDEX(ASSUMPTIONS!$C$16:$E$16, 1, MATCH(ASSUMPTIONS!$C$2, ASSUMPTIONS!$C$4:$E$4, 0))) ^ 0) | O8: =150000 * ((1 + INDEX(ASSUMPTIONS!$C$16:$E$16, 1, MATCH(ASSUMPTIONS!$C$2, ASSUMPTIONS!$C$4:$E$4, 0))) ^ 1) | P8: =150000 * ((1 + INDEX(ASSUMPTIONS!$C$16:$E$16, 1, MATCH(ASSUMPTIONS!$C$2, ASSUMPTIONS!$C$4:$E$4, 0))) ^ 1) | Q8: =150000 * ((1 + INDEX(ASSUMPTIONS!$C$16:$E$16, 1, MATCH(ASSUMPTIONS!$C$2, ASSUMPTIONS!$C$4:$E$4, 0))) ^ 1) | R8: =150000 * ((1 + INDEX(ASSUMPTIONS!$C$16:$E$16, 1, MATCH(ASSUMPTIONS!$C$2, ASSUMPTIONS!$C$4:$E$4, 0))) ^ 1) | S8: =150000 * ((1 + INDEX(ASSUMPTIONS!$C$16:$E$16, 1, MATCH(ASSUMPTIONS!$C$2, ASSUMPTIONS!$C$4:$E$4, 0))) ^ 1) | T8: =150000 * ((1 + INDEX(ASSUMPTIONS!$C$16:$E$16, 1, MATCH(ASSUMPTIONS!$C$2, ASSUMPTIONS!$C$4:$E$4, 0))) ^ 1) | U8: =150000 * ((1 + INDEX(ASSUMPTIONS!$C$16:$E$16, 1, MATCH(ASSUMPTIONS!$C$2, ASSUMPTIONS!$C$4:$E$4, 0))) ^ 1) | V8: =150000 * ((1 + INDEX(ASSUMPTIONS!$C$16:$E$16, 1, MATCH(ASSUMPTIONS!$C$2, ASSUMPTIONS!$C$4:$E$4, 0))) ^ 1) | ... Z8: =150000 * ((1 + INDEX(ASSUMPTIONS!$C$16:$E$16, 1, MATCH(ASSUMPTIONS!$C$2, ASSUMPTIONS!$C$4:$E$4, 0))) ^ 1) | AA8: =150000 * ((1 + INDEX(ASSUMPTIONS!$C$16:$E$16, 1, MATCH(ASSUMPTIONS!$C$2, ASSUMPTIONS!$C$4:$E$4, 0))) ^ 2) | AB8: =150000 * ((1 + INDEX(ASSUMPTIONS!$C$16:$E$16, 1, MATCH(ASSUMPTIONS!$C$2, ASSUMPTIONS!$C$4:$E$4, 0))) ^ 2) | AC8: =150000 * ((1 + INDEX(ASSUMPTIONS!$C$16:$E$16, 1, MATCH(ASSUMPTIONS!$C$2, ASSUMPTIONS!$C$4:$E$4, 0))) ^ 2) | AD8: =150000 * ((1 + INDEX(ASSUMPTIONS!$C$16:$E$16, 1, MATCH(ASSUMPTIONS!$C$2, ASSUMPTIONS!$C$4:$E$4, 0))) ^ 2) | AE8: =150000 * ((1 + INDEX(ASSUMPTIONS!$C$16:$E$16, 1, MATCH(ASSUMPTIONS!$C$2, ASSUMPTIONS!$C$4:$E$4, 0))) ^ 2) | AF8: =150000 * ((1 + INDEX(ASSUMPTIONS!$C$16:$E$16, 1, MATCH(ASSUMPTIONS!$C$2, ASSUMPTIONS!$C$4:$E$4, 0))) ^ 2) | AG8: =150000 * ((1 + INDEX(ASSUMPTIONS!$C$16:$E$16, 1, MATCH(ASSUMPTIONS!$C$2, ASSUMPTIONS!$C$4:$E$4, 0))) ^ 2) | AH8: =150000 * ((1 + INDEX(ASSUMPTIONS!$C$16:$E$16, 1, MATCH(ASSUMPTIONS!$C$2, ASSUMPTIONS!$C$4:$E$4, 0))) ^ 2) | ... AL8: =150000 * ((1 + INDEX(ASSUMPTIONS!$C$16:$E$16, 1, MATCH(ASSUMPTIONS!$C$2, ASSUMPTIONS!$C$4:$E$4, 0))) ^ 2) | AM8: =150000 * ((1 + INDEX(ASSUMPTIONS!$C$16:$E$16, 1, MATCH(ASSUMPTIONS!$C$2, ASSUMPTIONS!$C$4:$E$4, 0))) ^ 3) | AN8: =150000 * ((1 + INDEX(ASSUMPTIONS!$C$16:$E$16, 1, MATCH(ASSUMPTIONS!$C$2, ASSUMPTIONS!$C$4:$E$4, 0))) ^ 3) | AO8: =150000 * ((1 + INDEX(ASSUMPTIONS!$C$16:$E$16, 1, MATCH(ASSUMPTIONS!$C$2, ASSUMPTIONS!$C$4:$E$4, 0))) ^ 3) | AP8: =150000 * ((1 + INDEX(ASSUMPTIONS!$C$16:$E$16, 1, MATCH(ASSUMPTIONS!$C$2, ASSUMPTIONS!$C$4:$E$4, 0))) ^ 3) | AQ8: =150000 * ((1 + INDEX(ASSUMPTIONS!$C$16:$E$16, 1, MATCH(ASSUMPTIONS!$C$2, ASSUMPTIONS!$C$4:$E$4, 0))) ^ 3) | AR8: =150000 * ((1 + INDEX(ASSUMPTIONS!$C$16:$E$16, 1, MATCH(ASSUMPTIONS!$C$2, ASSUMPTIONS!$C$4:$E$4, 0))) ^ 3) | AS8: =150000 * ((1 + INDEX(ASSUMPTIONS!$C$16:$E$16, 1, MATCH(ASSUMPTIONS!$C$2, ASSUMPTIONS!$C$4:$E$4, 0))) ^ 3) | AT8: =150000 * ((1 + INDEX(ASSUMPTIONS!$C$16:$E$16, 1, MATCH(ASSUMPTIONS!$C$2, ASSUMPTIONS!$C$4:$E$4, 0))) ^ 3) | ... AX8: =150000 * ((1 + INDEX(ASSUMPTIONS!$C$16:$E$16, 1, MATCH(ASSUMPTIONS!$C$2, ASSUMPTIONS!$C$4:$E$4, 0))) ^ 3) | AY8: =150000 * ((1 + INDEX(ASSUMPTIONS!$C$16:$E$16, 1, MATCH(ASSUMPTIONS!$C$2, ASSUMPTIONS!$C$4:$E$4, 0))) ^ 4) | AZ8: =150000 * ((1 + INDEX(ASSUMPTIONS!$C$16:$E$16, 1, MATCH(ASSUMPTIONS!$C$2, ASSUMPTIONS!$C$4:$E$4, 0))) ^ 4) | BA8: =150000 * ((1 + INDEX(ASSUMPTIONS!$C$16:$E$16, 1, MATCH(ASSUMPTIONS!$C$2, ASSUMPTIONS!$C$4:$E$4, 0))) ^ 4) | BB8: =150000 * ((1 + INDEX(ASSUMPTIONS!$C$16:$E$16, 1, MATCH(ASSUMPTIONS!$C$2, ASSUMPTIONS!$C$4:$E$4, 0))) ^ 4) | BC8: =150000 * ((1 + INDEX(ASSUMPTIONS!$C$16:$E$16, 1, MATCH(ASSUMPTIONS!$C$2, ASSUMPTIONS!$C$4:$E$4, 0))) ^ 4) | BD8: =150000 * ((1 + INDEX(ASSUMPTIONS!$C$16:$E$16, 1, MATCH(ASSUMPTIONS!$C$2, ASSUMPTIONS!$C$4:$E$4, 0))) ^ 4) | BE8: =150000 * ((1 + INDEX(ASSUMPTIONS!$C$16:$E$16, 1, MATCH(ASSUMPTIONS!$C$2, ASSUMPTIONS!$C$4:$E$4, 0))) ^ 4) | BF8: =150000 * ((1 + INDEX(ASSUMPTIONS!$C$16:$E$16, 1, MATCH(ASSUMPTIONS!$C$2, ASSUMPTIONS!$C$4:$E$4, 0))) ^ 4) | ... BJ8: =150000 * ((1 + INDEX(ASSUMPTIONS!$C$16:$E$16, 1, MATCH(ASSUMPTIONS!$C$2, ASSUMPTIONS!$C$4:$E$4, 0))) ^ 4)
B9: Admin & Legal (₹) | C9: =50000 * ((1 + INDEX(ASSUMPTIONS!$C$16:$E$16, 1, MATCH(ASSUMPTIONS!$C$2, ASSUMPTIONS!$C$4:$E$4, 0))) ^ 0) | D9: =50000 * ((1 + INDEX(ASSUMPTIONS!$C$16:$E$16, 1, MATCH(ASSUMPTIONS!$C$2, ASSUMPTIONS!$C$4:$E$4, 0))) ^ 0) | E9: =50000 * ((1 + INDEX(ASSUMPTIONS!$C$16:$E$16, 1, MATCH(ASSUMPTIONS!$C$2, ASSUMPTIONS!$C$4:$E$4, 0))) ^ 0) | F9: =50000 * ((1 + INDEX(ASSUMPTIONS!$C$16:$E$16, 1, MATCH(ASSUMPTIONS!$C$2, ASSUMPTIONS!$C$4:$E$4, 0))) ^ 0) | G9: =50000 * ((1 + INDEX(ASSUMPTIONS!$C$16:$E$16, 1, MATCH(ASSUMPTIONS!$C$2, ASSUMPTIONS!$C$4:$E$4, 0))) ^ 0) | H9: =50000 * ((1 + INDEX(ASSUMPTIONS!$C$16:$E$16, 1, MATCH(ASSUMPTIONS!$C$2, ASSUMPTIONS!$C$4:$E$4, 0))) ^ 0) | I9: =50000 * ((1 + INDEX(ASSUMPTIONS!$C$16:$E$16, 1, MATCH(ASSUMPTIONS!$C$2, ASSUMPTIONS!$C$4:$E$4, 0))) ^ 0) | J9: =50000 * ((1 + INDEX(ASSUMPTIONS!$C$16:$E$16, 1, MATCH(ASSUMPTIONS!$C$2, ASSUMPTIONS!$C$4:$E$4, 0))) ^ 0) | ... N9: =50000 * ((1 + INDEX(ASSUMPTIONS!$C$16:$E$16, 1, MATCH(ASSUMPTIONS!$C$2, ASSUMPTIONS!$C$4:$E$4, 0))) ^ 0) | O9: =50000 * ((1 + INDEX(ASSUMPTIONS!$C$16:$E$16, 1, MATCH(ASSUMPTIONS!$C$2, ASSUMPTIONS!$C$4:$E$4, 0))) ^ 1) | P9: =50000 * ((1 + INDEX(ASSUMPTIONS!$C$16:$E$16, 1, MATCH(ASSUMPTIONS!$C$2, ASSUMPTIONS!$C$4:$E$4, 0))) ^ 1) | Q9: =50000 * ((1 + INDEX(ASSUMPTIONS!$C$16:$E$16, 1, MATCH(ASSUMPTIONS!$C$2, ASSUMPTIONS!$C$4:$E$4, 0))) ^ 1) | R9: =50000 * ((1 + INDEX(ASSUMPTIONS!$C$16:$E$16, 1, MATCH(ASSUMPTIONS!$C$2, ASSUMPTIONS!$C$4:$E$4, 0))) ^ 1) | S9: =50000 * ((1 + INDEX(ASSUMPTIONS!$C$16:$E$16, 1, MATCH(ASSUMPTIONS!$C$2, ASSUMPTIONS!$C$4:$E$4, 0))) ^ 1) | T9: =50000 * ((1 + INDEX(ASSUMPTIONS!$C$16:$E$16, 1, MATCH(ASSUMPTIONS!$C$2, ASSUMPTIONS!$C$4:$E$4, 0))) ^ 1) | U9: =50000 * ((1 + INDEX(ASSUMPTIONS!$C$16:$E$16, 1, MATCH(ASSUMPTIONS!$C$2, ASSUMPTIONS!$C$4:$E$4, 0))) ^ 1) | V9: =50000 * ((1 + INDEX(ASSUMPTIONS!$C$16:$E$16, 1, MATCH(ASSUMPTIONS!$C$2, ASSUMPTIONS!$C$4:$E$4, 0))) ^ 1) | ... Z9: =50000 * ((1 + INDEX(ASSUMPTIONS!$C$16:$E$16, 1, MATCH(ASSUMPTIONS!$C$2, ASSUMPTIONS!$C$4:$E$4, 0))) ^ 1) | AA9: =50000 * ((1 + INDEX(ASSUMPTIONS!$C$16:$E$16, 1, MATCH(ASSUMPTIONS!$C$2, ASSUMPTIONS!$C$4:$E$4, 0))) ^ 2) | AB9: =50000 * ((1 + INDEX(ASSUMPTIONS!$C$16:$E$16, 1, MATCH(ASSUMPTIONS!$C$2, ASSUMPTIONS!$C$4:$E$4, 0))) ^ 2) | AC9: =50000 * ((1 + INDEX(ASSUMPTIONS!$C$16:$E$16, 1, MATCH(ASSUMPTIONS!$C$2, ASSUMPTIONS!$C$4:$E$4, 0))) ^ 2) | AD9: =50000 * ((1 + INDEX(ASSUMPTIONS!$C$16:$E$16, 1, MATCH(ASSUMPTIONS!$C$2, ASSUMPTIONS!$C$4:$E$4, 0))) ^ 2) | AE9: =50000 * ((1 + INDEX(ASSUMPTIONS!$C$16:$E$16, 1, MATCH(ASSUMPTIONS!$C$2, ASSUMPTIONS!$C$4:$E$4, 0))) ^ 2) | AF9: =50000 * ((1 + INDEX(ASSUMPTIONS!$C$16:$E$16, 1, MATCH(ASSUMPTIONS!$C$2, ASSUMPTIONS!$C$4:$E$4, 0))) ^ 2) | AG9: =50000 * ((1 + INDEX(ASSUMPTIONS!$C$16:$E$16, 1, MATCH(ASSUMPTIONS!$C$2, ASSUMPTIONS!$C$4:$E$4, 0))) ^ 2) | AH9: =50000 * ((1 + INDEX(ASSUMPTIONS!$C$16:$E$16, 1, MATCH(ASSUMPTIONS!$C$2, ASSUMPTIONS!$C$4:$E$4, 0))) ^ 2) | ... AL9: =50000 * ((1 + INDEX(ASSUMPTIONS!$C$16:$E$16, 1, MATCH(ASSUMPTIONS!$C$2, ASSUMPTIONS!$C$4:$E$4, 0))) ^ 2) | AM9: =50000 * ((1 + INDEX(ASSUMPTIONS!$C$16:$E$16, 1, MATCH(ASSUMPTIONS!$C$2, ASSUMPTIONS!$C$4:$E$4, 0))) ^ 3) | AN9: =50000 * ((1 + INDEX(ASSUMPTIONS!$C$16:$E$16, 1, MATCH(ASSUMPTIONS!$C$2, ASSUMPTIONS!$C$4:$E$4, 0))) ^ 3) | AO9: =50000 * ((1 + INDEX(ASSUMPTIONS!$C$16:$E$16, 1, MATCH(ASSUMPTIONS!$C$2, ASSUMPTIONS!$C$4:$E$4, 0))) ^ 3) | AP9: =50000 * ((1 + INDEX(ASSUMPTIONS!$C$16:$E$16, 1, MATCH(ASSUMPTIONS!$C$2, ASSUMPTIONS!$C$4:$E$4, 0))) ^ 3) | AQ9: =50000 * ((1 + INDEX(ASSUMPTIONS!$C$16:$E$16, 1, MATCH(ASSUMPTIONS!$C$2, ASSUMPTIONS!$C$4:$E$4, 0))) ^ 3) | AR9: =50000 * ((1 + INDEX(ASSUMPTIONS!$C$16:$E$16, 1, MATCH(ASSUMPTIONS!$C$2, ASSUMPTIONS!$C$4:$E$4, 0))) ^ 3) | AS9: =50000 * ((1 + INDEX(ASSUMPTIONS!$C$16:$E$16, 1, MATCH(ASSUMPTIONS!$C$2, ASSUMPTIONS!$C$4:$E$4, 0))) ^ 3) | AT9: =50000 * ((1 + INDEX(ASSUMPTIONS!$C$16:$E$16, 1, MATCH(ASSUMPTIONS!$C$2, ASSUMPTIONS!$C$4:$E$4, 0))) ^ 3) | ... AX9: =50000 * ((1 + INDEX(ASSUMPTIONS!$C$16:$E$16, 1, MATCH(ASSUMPTIONS!$C$2, ASSUMPTIONS!$C$4:$E$4, 0))) ^ 3) | AY9: =50000 * ((1 + INDEX(ASSUMPTIONS!$C$16:$E$16, 1, MATCH(ASSUMPTIONS!$C$2, ASSUMPTIONS!$C$4:$E$4, 0))) ^ 4) | AZ9: =50000 * ((1 + INDEX(ASSUMPTIONS!$C$16:$E$16, 1, MATCH(ASSUMPTIONS!$C$2, ASSUMPTIONS!$C$4:$E$4, 0))) ^ 4) | BA9: =50000 * ((1 + INDEX(ASSUMPTIONS!$C$16:$E$16, 1, MATCH(ASSUMPTIONS!$C$2, ASSUMPTIONS!$C$4:$E$4, 0))) ^ 4) | BB9: =50000 * ((1 + INDEX(ASSUMPTIONS!$C$16:$E$16, 1, MATCH(ASSUMPTIONS!$C$2, ASSUMPTIONS!$C$4:$E$4, 0))) ^ 4) | BC9: =50000 * ((1 + INDEX(ASSUMPTIONS!$C$16:$E$16, 1, MATCH(ASSUMPTIONS!$C$2, ASSUMPTIONS!$C$4:$E$4, 0))) ^ 4) | BD9: =50000 * ((1 + INDEX(ASSUMPTIONS!$C$16:$E$16, 1, MATCH(ASSUMPTIONS!$C$2, ASSUMPTIONS!$C$4:$E$4, 0))) ^ 4) | BE9: =50000 * ((1 + INDEX(ASSUMPTIONS!$C$16:$E$16, 1, MATCH(ASSUMPTIONS!$C$2, ASSUMPTIONS!$C$4:$E$4, 0))) ^ 4) | BF9: =50000 * ((1 + INDEX(ASSUMPTIONS!$C$16:$E$16, 1, MATCH(ASSUMPTIONS!$C$2, ASSUMPTIONS!$C$4:$E$4, 0))) ^ 4) | ... BJ9: =50000 * ((1 + INDEX(ASSUMPTIONS!$C$16:$E$16, 1, MATCH(ASSUMPTIONS!$C$2, ASSUMPTIONS!$C$4:$E$4, 0))) ^ 4)
B10: Total OpEx (Incl. PF Burden) (₹) | C10: =((C5 + C6 + C7 + C8 + C9) * (1 + INDEX(ASSUMPTIONS!$C$8:$E$8, 1, MATCH(ASSUMPTIONS!$C$2, ASSUMPTIONS!$C$4:$E$4, 0)))) | D10: =((D5 + D6 + D7 + D8 + D9) * (1 + INDEX(ASSUMPTIONS!$C$8:$E$8, 1, MATCH(ASSUMPTIONS!$C$2, ASSUMPTIONS!$C$4:$E$4, 0)))) | E10: =((E5 + E6 + E7 + E8 + E9) * (1 + INDEX(ASSUMPTIONS!$C$8:$E$8, 1, MATCH(ASSUMPTIONS!$C$2, ASSUMPTIONS!$C$4:$E$4, 0)))) | F10: =((F5 + F6 + F7 + F8 + F9) * (1 + INDEX(ASSUMPTIONS!$C$8:$E$8, 1, MATCH(ASSUMPTIONS!$C$2, ASSUMPTIONS!$C$4:$E$4, 0)))) | G10: =((G5 + G6 + G7 + G8 + G9) * (1 + INDEX(ASSUMPTIONS!$C$8:$E$8, 1, MATCH(ASSUMPTIONS!$C$2, ASSUMPTIONS!$C$4:$E$4, 0)))) | H10: =((H5 + H6 + H7 + H8 + H9) * (1 + INDEX(ASSUMPTIONS!$C$8:$E$8, 1, MATCH(ASSUMPTIONS!$C$2, ASSUMPTIONS!$C$4:$E$4, 0)))) | I10: =((I5 + I6 + I7 + I8 + I9) * (1 + INDEX(ASSUMPTIONS!$C$8:$E$8, 1, MATCH(ASSUMPTIONS!$C$2, ASSUMPTIONS!$C$4:$E$4, 0)))) | J10: =((J5 + J6 + J7 + J8 + J9) * (1 + INDEX(ASSUMPTIONS!$C$8:$E$8, 1, MATCH(ASSUMPTIONS!$C$2, ASSUMPTIONS!$C$4:$E$4, 0)))) | ... BJ10: =((BJ5 + BJ6 + BJ7 + BJ8 + BJ9) * (1 + INDEX(ASSUMPTIONS!$C$8:$E$8, 1, MATCH(ASSUMPTIONS!$C$2, ASSUMPTIONS!$C$4:$E$4, 0))))

Sheet CAPEX_AND_DEPRECIATION
B2: CapEx & Depreciation Schedule
B4: Particulars | C4: Month 1 | D4: Month 2 | E4: Month 3 | F4: Month 4 | G4: Month 5 | H4: Month 6 | I4: Month 7 | J4: Month 8 | K4: Month 9 | L4: Month 10 | M4: Month 11 | N4: Month 12 | O4: Month 13 | P4: Month 14 | Q4: Month 15 | R4: Month 16 | S4: Month 17 | T4: Month 18 | U4: Month 19 | V4: Month 20 | W4: Month 21 | X4: Month 22 | Y4: Month 23 | Z4: Month 24 | AA4: Month 25 | AB4: Month 26 | AC4: Month 27 | AD4: Month 28 | AE4: Month 29 | AF4: Month 30 | AG4: Month 31 | AH4: Month 32 | AI4: Month 33 | AJ4: Month 34 | AK4: Month 35 | AL4: Month 36 | AM4: Month 37 | AN4: Month 38 | AO4: Month 39 | AP4: Month 40 | AQ4: Month 41 | AR4: Month 42 | AS4: Month 43 | AT4: Month 44 | AU4: Month 45 | AV4: Month 46 | AW4: Month 47 | AX4: Month 48 | AY4: Month 49 | AZ4: Month 50 | BA4: Month 51 | BB4: Month 52 | BC4: Month 53 | BD4: Month 54 | BE4: Month 55 | BF4: Month 56 | BG4: Month 57 | BH4: Month 58 | BI4: Month 59 | BJ4: Month 60
B5: Opening Asset Balance (₹) | C5: 0 | D5: =C8 | E5: =D8 | F5: =E8 | G5: =F8 | H5: =G8 | I5: =H8 | J5: =I8 | K5: =J8 | ... BJ5: =BI8
B6: New CapEx Additions (₹) | C6: ='FUNDING_REQUIREMENT'!$C$5 | D6: 0 | E6: 0 | F6: 0 | G6: 0 | H6: 0 | I6: 0 | J6: 0 | K6: 0 | L6: 0 | M6: 0 | N6: 0 | O6: 0 | P6: 0 | Q6: 0 | R6: 0 | S6: 0 | T6: 0 | U6: 0 | V6: 0 | W6: 0 | X6: 0 | Y6: 0 | Z6: 0 | AA6: 0 | AB6: 0 | AC6: 0 | AD6: 0 | AE6: 0 | AF6: 0 | AG6: 0 | AH6: 0 | AI6: 0 | AJ6: 0 | AK6: 0 | AL6: 0 | AM6: 0 | AN6: 0 | AO6: 0 | AP6: 0 | AQ6: 0 | AR6: 0 | AS6: 0 | AT6: 0 | AU6: 0 | AV6: 0 | AW6: 0 | AX6: 0 | AY6: 0 | AZ6: 0 | BA6: 0 | BB6: 0 | BC6: 0 | BD6: 0 | BE6: 0 | BF6: 0 | BG6: 0 | BH6: 0 | BI6: 0 | BJ6: 0
B7: Depreciation Expense (₹) | C7: =(C5 + C6) / 60 | D7: =(D5 + D6) / 60 | E7: =(E5 + E6) / 60 | F7: =(F5 + F6) / 60 | G7: =(G5 + G6) / 60 | H7: =(H5 + H6) / 60 | I7: =(I5 + I6) / 60 | J7: =(J5 + J6) / 60 | ... BJ7: =(BJ5 + BJ6) / 60
B8: Closing Asset Balance (₹) | C8: =C5 + C6 - C7 | D8: =D5 + D6 - D7 | E8: =E5 + E6 - E7 | F8: =F5 + F6 - F7 | G8: =G5 + G6 - G7 | H8: =H5 + H6 - H7 | I8: =I5 + I6 - I7 | J8: =J5 + J6 - J7 | ... BJ8: =BJ5 + BJ6 - BJ7

Sheet WORKING_CAPITAL
B2: Working Capital Schedule
B4: Particulars | C4: Month 1 | D4: Month 2 | E4: Month 3 | F4: Month 4 | G4: Month 5 | H4: Month 6 | I4: Month 7 | J4: Month 8 | K4: Month 9 | L4: Month 10 | M4: Month 11 | N4: Month 12 | O4: Month 13 | P4: Month 14 | Q4: Month 15 | R4: Month 16 | S4: Month 17 | T4: Month 18 | U4: Month 19 | V4: Month 20 | W4: Month 21 | X4: Month 22 | Y4: Month 23 | Z4: Month 24 | AA4: Month 25 | AB4: Month 26 | AC4: Month 27 | AD4: Month 28 | AE4: Month 29 | AF4: Month 30 | AG4: Month 31 | AH4: Month 32 | AI4: Month 33 | AJ4: Month 34 | AK4: Month 35 | AL4: Month 36 | AM4: Month 37 | AN4: Month 38 | AO4: Month 39 | AP4: Month 40 | AQ4: Month 41 | AR4: Month 42 | AS4: Month 43 | AT4: Month 44 | AU4: Month 45 | AV4: Month 46 | AW4: Month 47 | AX4: Month 48 | AY4: Month 49 | AZ4: Month 50 | BA4: Month 51 | BB4: Month 52 | BC4: Month 53 | BD4: Month 54 | BE4: Month 55 | BF4: Month 56 | BG4: Month 57 | BH4: Month 58 | BI4: Month 59 | BJ4: Month 60
B5: Accounts Receivable (₹) | C5: ='MONTHLY_P_AND_L'!C5 * (30/365) | D5: ='MONTHLY_P_AND_L'!D5 * (30/365) | E5: ='MONTHLY_P_AND_L'!E5 * (30/365) | F5: ='MONTHLY_P_AND_L'!F5 * (30/365) | G5: ='MONTHLY_P_AND_L'!G5 * (30/365) | H5: ='MONTHLY_P_AND_L'!H5 * (30/365) | I5: ='MONTHLY_P_AND_L'!I5 * (30/365) | J5: ='MONTHLY_P_AND_L'!J5 * (30/365) | ... BJ5: ='MONTHLY_P_AND_L'!BJ5 * (30/365)
B6: Accounts Payable (₹) | C6: ='MONTHLY_P_AND_L'!C8 * (15/365) | D6: ='MONTHLY_P_AND_L'!D8 * (15/365) | E6: ='MONTHLY_P_AND_L'!E8 * (15/365) | F6: ='MONTHLY_P_AND_L'!F8 * (15/365) | G6: ='MONTHLY_P_AND_L'!G8 * (15/365) | H6: ='MONTHLY_P_AND_L'!H8 * (15/365) | I6: ='MONTHLY_P_AND_L'!I8 * (15/365) | J6: ='MONTHLY_P_AND_L'!J8 * (15/365) | ... BJ6: ='MONTHLY_P_AND_L'!BJ8 * (15/365)
B7: Net Working Capital (₹) | C7: =C5 - C6 | D7: =D5 - D6 | E7: =E5 - E6 | F7: =F5 - F6 | G7: =G5 - G6 | H7: =H5 - H6 | I7: =I5 - I6 | J7: =J5 - J6 | ... BJ7: =BJ5 - BJ6
B8: Change in Working Capital (₹) | C8: =C7 | D8: =D7 - C7 | E8: =E7 - D7 | F8: =F7 - E7 | G8: =G7 - F7 | H8: =H7 - G7 | I8: =I7 - H7 | J8: =J7 - I7 | K8: =K7 - J7 | ... BJ8: =BJ7 - BI7

Sheet MONTHLY_P_AND_L
B2: Monthly Profit & Loss
B4: Particulars | C4: Month 1 | D4: Month 2 | E4: Month 3 | F4: Month 4 | G4: Month 5 | H4: Month 6 | I4: Month 7 | J4: Month 8 | K4: Month 9 | L4: Month 10 | M4: Month 11 | N4: Month 12 | O4: Month 13 | P4: Month 14 | Q4: Month 15 | R4: Month 16 | S4: Month 17 | T4: Month 18 | U4: Month 19 | V4: Month 20 | W4: Month 21 | X4: Month 22 | Y4: Month 23 | Z4: Month 24 | AA4: Month 25 | AB4: Month 26 | AC4: Month 27 | AD4: Month 28 | AE4: Month 29 | AF4: Month 30 | AG4: Month 31 | AH4: Month 32 | AI4: Month 33 | AJ4: Month 34 | AK4: Month 35 | AL4: Month 36 | AM4: Month 37 | AN4: Month 38 | AO4: Month 39 | AP4: Month 40 | AQ4: Month 41 | AR4: Month 42 | AS4: Month 43 | AT4: Month 44 | AU4: Month 45 | AV4: Month 46 | AW4: Month 47 | AX4: Month 48 | AY4: Month 49 | AZ4: Month 50 | BA4: Month 51 | BB4: Month 52 | BC4: Month 53 | BD4: Month 54 | BE4: Month 55 | BF4: Month 56 | BG4: Month 57 | BH4: Month 58 | BI4: Month 59 | BJ4: Month 60
B5: Total Revenue | C5: ='REVENUE_ENGINE'!C6 | D5: ='REVENUE_ENGINE'!D6 | E5: ='REVENUE_ENGINE'!E6 | F5: ='REVENUE_ENGINE'!F6 | G5: ='REVENUE_ENGINE'!G6 | H5: ='REVENUE_ENGINE'!H6 | I5: ='REVENUE_ENGINE'!I6 | J5: ='REVENUE_ENGINE'!J6 | ... BJ5: ='REVENUE_ENGINE'!BJ6
B6: Total COGS | C6: ='COGS_ENGINE'!C7 | D6: ='COGS_ENGINE'!D7 | E6: ='COGS_ENGINE'!E7 | F6: ='COGS_ENGINE'!F7 | G6: ='COGS_ENGINE'!G7 | H6: ='COGS_ENGINE'!H7 | I6: ='COGS_ENGINE'!I7 | J6: ='COGS_ENGINE'!J7 | ... BJ6: ='COGS_ENGINE'!BJ7
B7: Gross Profit | C7: =C5 - C6 | D7: =D5 - D6 | E7: =E5 - E6 | F7: =F5 - F6 | G7: =G5 - G6 | H7: =H5 - H6 | I7: =I5 - I6 | J7: =J5 - J6 | ... BJ7: =BJ5 - BJ6
B8: Total OpEx | C8: ='HR_AND_OPEX'!C10 | D8: ='HR_AND_OPEX'!D10 | E8: ='HR_AND_OPEX'!E10 | F8: ='HR_AND_OPEX'!F10 | G8: ='HR_AND_OPEX'!G10 | H8: ='HR_AND_OPEX'!H10 | I8: ='HR_AND_OPEX'!I10 | J8: ='HR_AND_OPEX'!J10 | ... BJ8: ='HR_AND_OPEX'!BJ10
B9: EBITDA | C9: =C7 - C8 | D9: =D7 - D8 | E9: =E7 - E8 | F9: =F7 - F8 | G9: =G7 - G8 | H9: =H7 - H8 | I9: =I7 - I8 | J9: =J7 - J8 | ... BJ9: =BJ7 - BJ8
B10: Depreciation & Amortization | C10: ='CAPEX_AND_DEPRECIATION'!C7 | D10: ='CAPEX_AND_DEPRECIATION'!D7 | E10: ='CAPEX_AND_DEPRECIATION'!E7 | F10: ='CAPEX_AND_DEPRECIATION'!F7 | G10: ='CAPEX_AND_DEPRECIATION'!G7 | H10: ='CAPEX_AND_DEPRECIATION'!H7 | I10: ='CAPEX_AND_DEPRECIATION'!I7 | J10: ='CAPEX_AND_DEPRECIATION'!J7 | ... BJ10: ='CAPEX_AND_DEPRECIATION'!BJ7
B11: EBIT | C11: =C9 - C10 | D11: =D9 - D10 | E11: =E9 - E10 | F11: =F9 - F10 | G11: =G9 - G10 | H11: =H9 - H10 | I11: =I9 - I10 | J11: =J9 - J10 | ... BJ11: =BJ9 - BJ10
B12: Interest Expense | C12: =(5000000 * 0.12) / 12 | D12: =(5000000 * 0.12) / 12 | E12: =(5000000 * 0.12) / 12 | F12: =(5000000 * 0.12) / 12 | G12: =(5000000 * 0.12) / 12 | H12: =(5000000 * 0.12) / 12 | I12: =(5000000 * 0.12) / 12 | J12: =(5000000 * 0.12) / 12 | ... BJ12: =(5000000 * 0.12) / 12
B13: Profit Before Tax (PBT) | C13: =C11 - C12 | D13: =D11 - D12 | E13: =E11 - E12 | F13: =F11 - F12 | G13: =G11 - G12 | H13: =H11 - H12 | I13: =I11 - I12 | J13: =J11 - J12 | ... BJ13: =BJ11 - BJ12
B14: Corporate Tax | C14: =IF(INDEX(ASSUMPTIONS!$C$7:$E$7, 1, MATCH(ASSUMPTIONS!$C$2, ASSUMPTIONS!$C$4:$E$4, 0))=1, 0, MAX(0, C13 * INDEX(ASSUMPTIONS!$C$6:$E$6, 1, MATCH(ASSUMPTIONS!$C$2, ASSUMPTIONS!$C$4:$E$4, 0)))) | D14: =IF(INDEX(ASSUMPTIONS!$C$7:$E$7, 1, MATCH(ASSUMPTIONS!$C$2, ASSUMPTIONS!$C$4:$E$4, 0))=1, 0, MAX(0, D13 * INDEX(ASSUMPTIONS!$C$6:$E$6, 1, MATCH(ASSUMPTIONS!$C$2, ASSUMPTIONS!$C$4:$E$4, 0)))) | E14: =IF(INDEX(ASSUMPTIONS!$C$7:$E$7, 1, MATCH(ASSUMPTIONS!$C$2, ASSUMPTIONS!$C$4:$E$4, 0))=1, 0, MAX(0, E13 * INDEX(ASSUMPTIONS!$C$6:$E$6, 1, MATCH(ASSUMPTIONS!$C$2, ASSUMPTIONS!$C$4:$E$4, 0)))) | F14: =IF(INDEX(ASSUMPTIONS!$C$7:$E$7, 1, MATCH(ASSUMPTIONS!$C$2, ASSUMPTIONS!$C$4:$E$4, 0))=1, 0, MAX(0, F13 * INDEX(ASSUMPTIONS!$C$6:$E$6, 1, MATCH(ASSUMPTIONS!$C$2, ASSUMPTIONS!$C$4:$E$4, 0)))) | G14: =IF(INDEX(ASSUMPTIONS!$C$7:$E$7, 1, MATCH(ASSUMPTIONS!$C$2, ASSUMPTIONS!$C$4:$E$4, 0))=1, 0, MAX(0, G13 * INDEX(ASSUMPTIONS!$C$6:$E$6, 1, MATCH(ASSUMPTIONS!$C$2, ASSUMPTIONS!$C$4:$E$4, 0)))) | H14: =IF(INDEX(ASSUMPTIONS!$C$7:$E$7, 1, MATCH(ASSUMPTIONS!$C$2, ASSUMPTIONS!$C$4:$E$4, 0))=1, 0, MAX(0, H13 * INDEX(ASSUMPTIONS!$C$6:$E$6, 1, MATCH(ASSUMPTIONS!$C$2, ASSUMPTIONS!$C$4:$E$4, 0)))) | I14: =IF(INDEX(ASSUMPTIONS!$C$7:$E$7, 1, MATCH(ASSUMPTIONS!$C$2, ASSUMPTIONS!$C$4:$E$4, 0))=1, 0, MAX(0, I13 * INDEX(ASSUMPTIONS!$C$6:$E$6, 1, MATCH(ASSUMPTIONS!$C$2, ASSUMPTIONS!$C$4:$E$4, 0)))) | J14: =IF(INDEX(ASSUMPTIONS!$C$7:$E$7, 1, MATCH(ASSUMPTIONS!$C$2, ASSUMPTIONS!$C$4:$E$4, 0))=1, 0, MAX(0, J13 * INDEX(ASSUMPTIONS!$C$6:$E$6, 1, MATCH(ASSUMPTIONS!$C$2, ASSUMPTIONS!$C$4:$E$4, 0)))) | ... AL14: =IF(INDEX(ASSUMPTIONS!$C$7:$E$7, 1, MATCH(ASSUMPTIONS!$C$2, ASSUMPTIONS!$C$4:$E$4, 0))=1, 0, MAX(0, AL13 * INDEX(ASSUMPTIONS!$C$6:$E$6, 1, MATCH(ASSUMPTIONS!$C$2, ASSUMPTIONS!$C$4:$E$4, 0)))) | AM14: =MAX(0, AM13 * INDEX(ASSUMPTIONS!$C$6:$E$6, 1, MATCH(ASSUMPTIONS!$C$2, ASSUMPTIONS!$C$4:$E$4, 0))) | AN14: =MAX(0, AN13 * INDEX(ASSUMPTIONS!$C$6:$E$6, 1, MATCH(ASSUMPTIONS!$C$2, ASSUMPTIONS!$C$4:$E$4, 0))) | AO14: =MAX(0, AO13 * INDEX(ASSUMPTIONS!$C$6:$E$6, 1, MATCH(ASSUMPTIONS!$C$2, ASSUMPTIONS!$C$4:$E$4, 0))) | AP14: =MAX(0, AP13 * INDEX(ASSUMPTIONS!$C$6:$E$6, 1, MATCH(ASSUMPTIONS!$C$2, ASSUMPTIONS!$C$4:$E$4, 0))) | AQ14: =MAX(0, AQ13 * INDEX(ASSUMPTIONS!$C$6:$E$6, 1, MATCH(ASSUMPTIONS!$C$2, ASSUMPTIONS!$C$4:$E$4, 0))) | AR14: =MAX(0, AR13 * INDEX(ASSUMPTIONS!$C$6:$E$6, 1, MATCH(ASSUMPTIONS!$C$2, ASSUMPTIONS!$C$4:$E$4, 0))) | AS14: =MAX(0, AS13 * INDEX(ASSUMPTIONS!$C$6:$E$6, 1, MATCH(ASSUMPTIONS!$C$2, ASSUMPTIONS!$C$4:$E$4, 0))) | AT14: =MAX(0, AT13 * INDEX(ASSUMPTIONS!$C$6:$E$6, 1, MATCH(ASSUMPTIONS!$C$2, ASSUMPTIONS!$C$4:$E$4, 0))) | ... BJ14: =MAX(0, BJ13 * INDEX(ASSUMPTIONS!$C$6:$E$6, 1, MATCH(ASSUMPTIONS!$C$2, ASSUMPTIONS!$C$4:$E$4, 0)))
B15: Net Income (PAT) | C15: =C13 - C14 | D15: =D13 - D14 | E15: =E13 - E14 | F15: =F13 - F14 | G15: =G13 - G14 | H15: =H13 - H14 | I15: =I13 - I14 | J15: =J13 - J14 | ... BJ15: =BJ13 - BJ14

Sheet MONTHLY_CASH_FLOW
B2: Monthly Cash Flow Statement
B4: Particulars | C4: Month 1 | D4: Month 2 | E4: Month 3 | F4: Month 4 | G4: Month 5 | H4: Month 6 | I4: Month 7 | J4: Month 8 | K4: Month 9 | L4: Month 10 | M4: Month 11 | N4: Month 12 | O4: Month 13 | P4: Month 14 | Q4: Month 15 | R4: Month 16 | S4: Month 17 | T4: Month 18 | U4: Month 19 | V4: Month 20 | W4: Month 21 | X4: Month 22 | Y4: Month 23 | Z4: Month 24 | AA4: Month 25 | AB4: Month 26 | AC4: Month 27 | AD4: Month 28 | AE4: Month 29 | AF4: Month 30 | AG4: Month 31 | AH4: Month 32 | AI4: Month 33 | AJ4: Month 34 | AK4: Month 35 | AL4: Month 36 | AM4: Month 37 | AN4: Month 38 | AO4: Month 39 | AP4: Month 40 | AQ4: Month 41 | AR4: Month 42 | AS4: Month 43 | AT4: Month 44 | AU4: Month 45 | AV4: Month 46 | AW4: Month 47 | AX4: Month 48 | AY4: Month 49 | AZ4: Month 50 | BA4: Month 51 | BB4: Month 52 | BC4: Month 53 | BD4: Month 54 | BE4: Month 55 | BF4: Month 56 | BG4: Month 57 | BH4: Month 58 | BI4: Month 59 | BJ4: Month 60
B5: Net Income (₹) | C5: ='MONTHLY_P_AND_L'!C15 | D5: ='MONTHLY_P_AND_L'!D15 | E5: ='MONTHLY_P_AND_L'!E15 | F5: ='MONTHLY_P_AND_L'!F15 | G5: ='MONTHLY_P_AND_L'!G15 | H5: ='MONTHLY_P_AND_L'!H15 | I5: ='MONTHLY_P_AND_L'!I15 | J5: ='MONTHLY_P_AND_L'!J15 | ... BJ5: ='MONTHLY_P_AND_L'!BJ15
B6: Add Back: Depreciation (₹) | C6: ='CAPEX_AND_DEPRECIATION'!C7 | D6: ='CAPEX_AND_DEPRECIATION'!D7 | E6: ='CAPEX_AND_DEPRECIATION'!E7 | F6: ='CAPEX_AND_DEPRECIATION'!F7 | G6: ='CAPEX_AND_DEPRECIATION'!G7 | H6: ='CAPEX_AND_DEPRECIATION'!H7 | I6: ='CAPEX_AND_DEPRECIATION'!I7 | J6: ='CAPEX_AND_DEPRECIATION'!J7 | ... BJ6: ='CAPEX_AND_DEPRECIATION'!BJ7
B7: Less: Change in Working Capital (₹) | C7: ='WORKING_CAPITAL'!C8 | D7: ='WORKING_CAPITAL'!D8 | E7: ='WORKING_CAPITAL'!E8 | F7: ='WORKING_CAPITAL'!F8 | G7: ='WORKING_CAPITAL'!G8 | H7: ='WORKING_CAPITAL'!H8 | I7: ='WORKING_CAPITAL'!I8 | J7: ='WORKING_CAPITAL'!J8 | ... BJ7: ='WORKING_CAPITAL'!BJ8
B8: Operating Cash Flow (₹) | C8: =C5 + C6 - C7 | D8: =D5 + D6 - D7 | E8: =E5 + E6 - E7 | F8: =F5 + F6 - F7 | G8: =G5 + G6 - G7 | H8: =H5 + H6 - H7 | I8: =I5 + I6 - I7 | J8: =J5 + J6 - J7 | ... BJ8: =BJ5 + BJ6 - BJ7
B9: Less: CapEx Additions (₹) | C9: ='CAPEX_AND_DEPRECIATION'!C6 | D9: ='CAPEX_AND_DEPRECIATION'!D6 | E9: ='CAPEX_AND_DEPRECIATION'!E6 | F9: ='CAPEX_AND_DEPRECIATION'!F6 | G9: ='CAPEX_AND_DEPRECIATION'!G6 | H9: ='CAPEX_AND_DEPRECIATION'!H6 | I9: ='CAPEX_AND_DEPRECIATION'!I6 | J9: ='CAPEX_AND_DEPRECIATION'!J6 | ... BJ9: ='CAPEX_AND_DEPRECIATION'!BJ6
B10: Investing Cash Flow (₹) | C10: =-C9 | D10: =-D9 | E10: =-E9 | F10: =-F9 | G10: =-G9 | H10: =-H9 | I10: =-I9 | J10: =-J9 | ... BJ10: =-BJ9
B11: Add: Equity Funding (₹) | C11: ='FUNDING_REQUIREMENT'!$C$9 | D11: 0 | E11: 0 | F11: 0 | G11: 0 | H11: 0 | I11: 0 | J11: 0 | K11: 0 | L11: 0 | M11: 0 | N11: 0 | O11: 0 | P11: 0 | Q11: 0 | R11: 0 | S11: 0 | T11: 0 | U11: 0 | V11: 0 | W11: 0 | X11: 0 | Y11: 0 | Z11: 0 | AA11: 0 | AB11: 0 | AC11: 0 | AD11: 0 | AE11: 0 | AF11: 0 | AG11: 0 | AH11: 0 | AI11: 0 | AJ11: 0 | AK11: 0 | AL11: 0 | AM11: 0 | AN11: 0 | AO11: 0 | AP11: 0 | AQ11: 0 | AR11: 0 | AS11: 0 | AT11: 0 | AU11: 0 | AV11: 0 | AW11: 0 | AX11: 0 | AY11: 0 | AZ11: 0 | BA11: 0 | BB11: 0 | BC11: 0 | BD11: 0 | BE11: 0 | BF11: 0 | BG11: 0 | BH11: 0 | BI11: 0 | BJ11: 0
B12: Financing Cash Flow (₹) | C12: =C11 | D12: =D11 | E12: =E11 | F12: =F11 | G12: =G11 | H12: =H11 | I12: =I11 | J12: =J11 | ... BJ12: =BJ11
B13: Net Cash Flow for Month (₹) | C13: =C8 + C10 + C12 | D13: =D8 + D10 + D12 | E13: =E8 + E10 + E12 | F13: =F8 + F10 + F12 | G13: =G8 + G10 + G12 | H13: =H8 + H10 + H12 | I13: =I8 + I10 + I12 | J13: =J8 + J10 + J12 | ... BJ13: =BJ8 + BJ10 + BJ12
B14: Closing Cash Balance (₹) | C14: =C13 | D14: =C14 + D13 | E14: =D14 + E13 | F14: =E14 + F13 | G14: =F14 + G13 | H14: =G14 + H13 | I14: =H14 + I13 | J14: =I14 + J13 | K14: =J14 + K13 | ... BJ14: =BI14 + BJ13

Sheet QUARTERLY_SUMMARY
B2: Venture Wolf India — Master Quarterly Dashboard (Full Metrics)
B4: BASE CASE
B5: Particulars | C5: Q1 | D5: Q2 | E5: Q3 | F5: Q4 | G5: Q5 | H5: Q6 | I5: Q7 | J5: Q8 | K5: Q9 | L5: Q10 | M5: Q11 | N5: Q12 | O5: Q13 | P5: Q14 | Q5: Q15 | R5: Q16 | S5: Q17 | T5: Q18 | U5: Q19 | V5: Q20
B6: 1. Total Revenue | C6: 262500 | D6: 275625 | E6: 289406.25 | F6: 303876.56 | G6: 319070.39 | H6: 335023.91 | I6: 351775.11 | J6: 369363.86 | K6: 387832.05 | L6: 407223.66 | M6: 427584.84 | N6: 448964.08 | O6: 471412.29 | P6: 494982.9 | Q6: 519732.04 | R6: 545718.65 | S6: 573004.58 | T6: 601654.81 | U6: 631737.55 | V6: 663324.43
B7: 2. Total COGS | C7: 78750 | D7: 82687.5 | E7: 86821.875 | F7: 91162.969 | G7: 95721.117 | H7: 100507.17 | I7: 105532.53 | J7: 110809.16 | K7: 116349.62 | L7: 122167.1 | M7: 128275.45 | N7: 134689.22 | O7: 141423.69 | P7: 148494.87 | Q7: 155919.61 | R7: 163715.59 | S7: 171901.37 | T7: 180496.44 | U7: 189521.26 | V7: 198997.33
B8: 3. Gross Profit | C8: =C6-C7 | D8: =D6-D7 | E8: =E6-E7 | F8: =F6-F7 | G8: =G6-G7 | H8: =H6-H7 | I8: =I6-I7 | J8: =J6-J7 | ... V8: =V6-V7
B9: A. Gross Margin % | C9: =IF(C6>0, C8/C6, 0) | D9: =IF(D6>0, D8/D6, 0) | E9: =IF(E6>0, E8/E6, 0) | F9: =IF(F6>0, F8/F6, 0) | G9: =IF(G6>0, G8/G6, 0) | H9: =IF(H6>0, H8/H6, 0) | I9: =IF(I6>0, I8/I6, 0) | J9: =IF(J6>0, J8/J6, 0) | ... V9: =IF(V6>0, V8/V6, 0)
B10: 4. Total Operating Expenses | C10: 26250 | D10: 27562.5 | E10: 28940.625 | F10: 30387.656 | G10: 31907.039 | H10: 33502.391 | I10: 35177.511 | J10: 36936.386 | K10: 38783.205 | L10: 40722.366 | M10: 42758.484 | N10: 44896.408 | O10: 47141.229 | P10: 49498.29 | Q10: 51973.204 | R10: 54571.865 | S10: 57300.458 | T10: 60165.481 | U10: 63173.755 | V10: 66332.443
B11: 5. EBITDA | C11: =C8-C10 | D11: =D8-D10 | E11: =E8-E10 | F11: =F8-F10 | G11: =G8-G10 | H11: =H8-H10 | I11: =I8-I10 | J11: =J8-J10 | ... V11: =V8-V10
B12: B. EBITDA % | C12: =IF(C6>0, C11/C6, 0) | D12: =IF(D6>0, D11/D6, 0) | E12: =IF(E6>0, E11/E6, 0) | F12: =IF(F6>0, F11/F6, 0) | G12: =IF(G6>0, G11/G6, 0) | H12: =IF(H6>0, H11/H6, 0) | I12: =IF(I6>0, I11/I6, 0) | J12: =IF(J6>0, J11/J6, 0) | ... V12: =IF(V6>0, V11/V6, 0)
B13: 6. Depreciation & Amortisation | C13: 125000 | D13: 125000 | E13: 125000 | F13: 125000 | G13: 125000 | H13: 125000 | I13: 125000 | J13: 125000 | K13: 125000 | L13: 125000 | M13: 125000 | N13: 125000 | O13: 125000 | P13: 125000 | Q13: 125000 | R13: 125000 | S13: 125000 | T13: 125000 | U13: 125000 | V13: 125000
B14: 7. EBIT | C14: =C11-C13 | D14: =D11-D13 | E14: =E11-E13 | F14: =F11-F13 | G14: =G11-G13 | H14: =H11-H13 | I14: =I11-I13 | J14: =J11-J13 | ... V14: =V11-V13
B15: 8. Interest | C15: 15000 | D15: 15000 | E15: 15000 | F15: 15000 | G15: 15000 | H15: 15000 | I15: 15000 | J15: 15000 | K15: 15000 | L15: 15000 | M15: 15000 | N15: 15000 | O15: 15000 | P15: 15000 | Q15: 15000 | R15: 15000 | S15: 15000 | T15: 15000 | U15: 15000 | V15: 15000
B16: 9. PBT | C16: =C14-C15 | D16: =D14-D15 | E16: =E14-E15 | F16: =F14-F15 | G16: =G14-G15 | H16: =H14-H15 | I16: =I14-I15 | J16: =J14-J15 | ... V16: =V14-V15
B17: 10. Taxes | C17: =IF(INDEX(ASSUMPTIONS!$C$7:$E$7, 1, MATCH(ASSUMPTIONS!$C$2, ASSUMPTIONS!$C$4:$E$4, 0))=1, 0, MAX(0, C16 * INDEX(ASSUMPTIONS!$C$6:$E$6, 1, MATCH(ASSUMPTIONS!$C$2, ASSUMPTIONS!$C$4:$E$4, 0)))) | D17: =IF(INDEX(ASSUMPTIONS!$C$7:$E$7, 1, MATCH(ASSUMPTIONS!$C$2, ASSUMPTIONS!$C$4:$E$4, 0))=1, 0, MAX(0, D16 * INDEX(ASSUMPTIONS!$C$6:$E$6, 1, MATCH(ASSUMPTIONS!$C$2, ASSUMPTIONS!$C$4:$E$4, 0)))) | E17: =IF(INDEX(ASSUMPTIONS!$C$7:$E$7, 1, MATCH(ASSUMPTIONS!$C$2, ASSUMPTIONS!$C$4:$E$4, 0))=1, 0, MAX(0, E16 * INDEX(ASSUMPTIONS!$C$6:$E$6, 1, MATCH(ASSUMPTIONS!$C$2, ASSUMPTIONS!$C$4:$E$4, 0)))) | F17: =IF(INDEX(ASSUMPTIONS!$C$7:$E$7, 1, MATCH(ASSUMPTIONS!$C$2, ASSUMPTIONS!$C$4:$E$4, 0))=1, 0, MAX(0, F16 * INDEX(ASSUMPTIONS!$C$6:$E$6, 1, MATCH(ASSUMPTIONS!$C$2, ASSUMPTIONS!$C$4:$E$4, 0)))) | G17: =IF(INDEX(ASSUMPTIONS!$C$7:$E$7, 1, MATCH(ASSUMPTIONS!$C$2, ASSUMPTIONS!$C$4:$E$4, 0))=1, 0, MAX(0, G16 * INDEX(ASSUMPTIONS!$C$6:$E$6, 1, MATCH(ASSUMPTIONS!$C$2, ASSUMPTIONS!$C$4:$E$4, 0)))) | H17: =IF(INDEX(ASSUMPTIONS!$C$7:$E$7, 1, MATCH(ASSUMPTIONS!$C$2, ASSUMPTIONS!$C$4:$E$4, 0))=1, 0, MAX(0, H16 * INDEX(ASSUMPTIONS!$C$6:$E$6, 1, MATCH(ASSUMPTIONS!$C$2, ASSUMPTIONS!$C$4:$E$4, 0)))) | I17: =IF(INDEX(ASSUMPTIONS!$C$7:$E$7, 1, MATCH(ASSUMPTIONS!$C$2, ASSUMPTIONS!$C$4:$E$4, 0))=1, 0, MAX(0, I16 * INDEX(ASSUMPTIONS!$C$6:$E$6, 1, MATCH(ASSUMPTIONS!$C$2, ASSUMPTIONS!$C$4:$E$4, 0)))) | J17: =IF(INDEX(ASSUMPTIONS!$C$7:$E$7, 1, MATCH(ASSUMPTIONS!$C$2, ASSUMPTIONS!$C$4:$E$4, 0))=1, 0, MAX(0, J16 * INDEX(ASSUMPTIONS!$C$6:$E$6, 1, MATCH(ASSUMPTIONS!$C$2, ASSUMPTIONS!$C$4:$E$4, 0)))) | ... N17: =IF(INDEX(ASSUMPTIONS!$C$7:$E$7, 1, MATCH(ASSUMPTIONS!$C$2, ASSUMPTIONS!$C$4:$E$4, 0))=1, 0, MAX(0, N16 * INDEX(ASSUMPTIONS!$C$6:$E$6, 1, MATCH(ASSUMPTIONS!$C$2, ASSUMPTIONS!$C$4:$E$4, 0)))) | O17: =MAX(0, O16 * INDEX(ASSUMPTIONS!$C$6:$E$6, 1, MATCH(ASSUMPTIONS!$C$2, ASSUMPTIONS!$C$4:$E$4, 0))) | P17: =MAX(0, P16 * INDEX(ASSUMPTIONS!$C$6:$E$6, 1, MATCH(ASSUMPTIONS!$C$2, ASSUMPTIONS!$C$4:$E$4, 0))) | Q17: =MAX(0, Q16 * INDEX(ASSUMPTIONS!$C$6:$E$6, 1, MATCH(ASSUMPTIONS!$C$2, ASSUMPTIONS!$C$4:$E$4, 0))) | R17: =MAX(0, R16 * INDEX(ASSUMPTIONS!$C$6:$E$6, 1, MATCH(ASSUMPTIONS!$C$2, ASSUMPTIONS!$C$4:$E$4, 0))) | S17: =MAX(0, S16 * INDEX(ASSUMPTIONS!$C$6:$E$6, 1, MATCH(ASSUMPTIONS!$C$2, ASSUMPTIONS!$C$4:$E$4, 0))) | T17: =MAX(0, T16 * INDEX(ASSUMPTIONS!$C$6:$E$6, 1, MATCH(ASSUMPTIONS!$C$2, ASSUMPTIONS!$C$4:$E$4, 0))) | U17: =MAX(0, U16 * INDEX(ASSUMPTIONS!$C$6:$E$6, 1, MATCH(ASSUMPTIONS!$C$2, ASSUMPTIONS!$C$4:$E$4, 0))) | V17: =MAX(0, V16 * INDEX(ASSUMPTIONS!$C$6:$E$6, 1, MATCH(ASSUMPTIONS!$C$2, ASSUMPTIONS!$C$4:$E$4, 0)))
B18: 11. PAT | C18: =C16-C17 | D18: =D16-D17 | E18: =E16-E17 | F18: =F16-F17 | G18: =G16-G17 | H18: =H16-H17 | I18: =I16-I17 | J18: =J16-J17 | ... V18: =V16-V17
B19: C. PAT % | C19: =IF(C6>0, C18/C6, 0) | D19: =IF(D6>0, D18/D6, 0) | E19: =IF(E6>0, E18/E6, 0) | F19: =IF(F6>0, F18/F6, 0) | G19: =IF(G6>0, G18/G6, 0) | H19: =IF(H6>0, H18/H6, 0) | I19: =IF(I6>0, I18/I6, 0) | J19: =IF(J6>0, J18/J6, 0) | ... V19: =IF(V6>0, V18/V6, 0)
B21: BEST CASE
B22: Particulars | C22: Q1 | D22: Q2 | E22: Q3 | F22: Q4 | G22: Q5 | H22: Q6 | I22: Q7 | J22: Q8 | K22: Q9 | L22: Q10 | M22: Q11 | N22: Q12 | O22: Q13 | P22: Q14 | Q22: Q15 | R22: Q16 | S22: Q17 | T22: Q18 | U22: Q19 | V22: Q20
B23: 1. Total Revenue | C23: 393750 | D23: 413437.5 | E23: 434109.38 | F23: 455814.84 | G23: 478605.59 | H23: 502535.87 | I23: 527662.66 | J23: 554045.79 | K23: 581748.08 | L23: 610835.49 | M23: 641377.26 | N23: 673446.12 | O23: 707118.43 | P23: 742474.35 | Q23: 779598.07 | R23: 818577.97 | S23: 859506.87 | T23: 902482.21 | U23: 947606.32 | V23: 994986.64
B24: 2. Total COGS | C24: 118125 | D24: 124031.25 | E24: 130232.81 | F24: 136744.45 | G24: 143581.68 | H24: 150760.76 | I24: 158298.8 | J24: 166213.74 | K24: 174524.42 | L24: 183250.65 | M24: 192413.18 | N24: 202033.84 | O24: 212135.53 | P24: 222742.3 | Q24: 233879.42 | R24: 245573.39 | S24: 257852.06 | T24: 270744.66 | U24: 284281.9 | V24: 298495.99
B25: 3. Gross Profit | C25: =C23-C24 | D25: =D23-D24 | E25: =E23-E24 | F25: =F23-F24 | G25: =G23-G24 | H25: =H23-H24 | I25: =I23-I24 | J25: =J23-J24 | ... V25: =V23-V24
B26: A. Gross Margin % | C26: =IF(C23>0, C25/C23, 0) | D26: =IF(D23>0, D25/D23, 0) | E26: =IF(E23>0, E25/E23, 0) | F26: =IF(F23>0, F25/F23, 0) | G26: =IF(G23>0, G25/G23, 0) | H26: =IF(H23>0, H25/H23, 0) | I26: =IF(I23>0, I25/I23, 0) | J26: =IF(J23>0, J25/J23, 0) | ... V26: =IF(V23>0, V25/V23, 0)
B27: 4. Total Operating Expenses | C27: 39375 | D27: 41343.75 | E27: 43410.938 | F27: 45581.484 | G27: 47860.559 | H27: 50253.587 | I27: 52766.266 | J27: 55404.579 | K27: 58174.808 | L27: 61083.549 | M27: 64137.726 | N27: 67344.612 | O27: 70711.843 | P27: 74247.435 | Q27: 77959.807 | R27: 81857.797 | S27: 85950.687 | T27: 90248.221 | U27: 94760.632 | V27: 99498.664
B28: 5. EBITDA | C28: =C25-C27 | D28: =D25-D27 | E28: =E25-E27 | F28: =F25-F27 | G28: =G25-G27 | H28: =H25-H27 | I28: =I25-I27 | J28: =J25-J27 | ... V28: =V25-V27
B29: B. EBITDA % | C29: =IF(C23>0, C28/C23, 0) | D29: =IF(D23>0, D28/D23, 0) | E29: =IF(E23>0, E28/E23, 0) | F29: =IF(F23>0, F28/F23, 0) | G29: =IF(G23>0, G28/G23, 0) | H29: =IF(H23>0, H28/H23, 0) | I29: =IF(I23>0, I28/I23, 0) | J29: =IF(J23>0, J28/J23, 0) | ... V29: =IF(V23>0, V28/V23, 0)
B30: 6. Depreciation & Amortisation | C30: 125000 | D30: 125000 | E30: 125000 | F30: 125000 | G30: 125000 | H30: 125000 | I30: 125000 | J30: 125000 | K30: 125000 | L30: 125000 | M30: 125000 | N30: 125000 | O30: 125000 | P30: 125000 | Q30: 125000 | R30: 125000 | S30: 125000 | T30: 125000 | U30: 125000 | V30: 125000
B31: 7. EBIT | C31: =C28-C30 | D31: =D28-D30 | E31: =E28-E30 | F31: =F28-F30 | G31: =G28-G30 | H31: =H28-H30 | I31: =I28-I30 | J31: =J28-J30 | ... V31: =V28-V30
B32: 8. Interest | C32: 15000 | D32: 15000 | E32: 15000 | F32: 15000 | G32: 15000 | H32: 15000 | I32: 15000 | J32: 15000 | K32: 15000 | L32: 15000 | M32: 15000 | N32: 15000 | O32: 15000 | P32: 15000 | Q32: 15000 | R32: 15000 | S32: 15000 | T32: 15000 | U32: 15000 | V32: 15000
B33: 9. PBT | C33: =C31-C32 | D33: =D31-D32 | E33: =E31-E32 | F33: =F31-F32 | G33: =G31-G32 | H33: =H31-H32 | I33: =I31-I32 | J33: =J31-J32 | ... V33: =V31-V32
B34: 10. Taxes | C34: =IF(INDEX(ASSUMPTIONS!$C$7:$E$7, 1, MATCH(ASSUMPTIONS!$C$2, ASSUMPTIONS!$C$4:$E$4, 0))=1, 0, MAX(0, C33 * INDEX(ASSUMPTIONS!$C$6:$E$6, 1, MATCH(ASSUMPTIONS!$C$2, ASSUMPTIONS!$C$4:$E$4, 0)))) | D34: =IF(INDEX(ASSUMPTIONS!$C$7:$E$7, 1, MATCH(ASSUMPTIONS!$C$2, ASSUMPTIONS!$C$4:$E$4, 0))=1, 0, MAX(0, D33 * INDEX(ASSUMPTIONS!$C$6:$E$6, 1, MATCH(ASSUMPTIONS!$C$2, ASSUMPTIONS!$C$4:$E$4, 0)))) | E34: =IF(INDEX(ASSUMPTIONS!$C$7:$E$7, 1, MATCH(ASSUMPTIONS!$C$2, ASSUMPTIONS!$C$4:$E$4, 0))=1, 0, MAX(0, E33 * INDEX(ASSUMPTIONS!$C$6:$E$6, 1, MATCH(ASSUMPTIONS!$C$2, ASSUMPTIONS!$C$4:$E$4, 0)))) | F34: =IF(INDEX(ASSUMPTIONS!$C$7:$E$7, 1, MATCH(ASSUMPTIONS!$C$2, ASSUMPTIONS!$C$4:$E$4, 0))=1, 0, MAX(0, F33 * INDEX(ASSUMPTIONS!$C$6:$E$6, 1, MATCH(ASSUMPTIONS!$C$2, ASSUMPTIONS!$C$4:$E$4, 0)))) | G34: =IF(INDEX(ASSUMPTIONS!$C$7:$E$7, 1, MATCH(ASSUMPTIONS!$C$2, ASSUMPTIONS!$C$4:$E$4, 0))=1, 0, MAX(0, G33 * INDEX(ASSUMPTIONS!$C$6:$E$6, 1, MATCH(ASSUMPTIONS!$C$2, ASSUMPTIONS!$C$4:$E$4, 0)))) | H34: =IF(INDEX(ASSUMPTIONS!$C$7:$E$7, 1, MATCH(ASSUMPTIONS!$C$2, ASSUMPTIONS!$C$4:$E$4, 0))=1, 0, MAX(0, H33 * INDEX(ASSUMPTIONS!$C$6:$E$6, 1, MATCH(ASSUMPTIONS!$C$2, ASSUMPTIONS!$C$4:$E$4, 0)))) | I34: =IF(INDEX(ASSUMPTIONS!$C$7:$E$7, 1, MATCH(ASSUMPTIONS!$C$2, ASSUMPTIONS!$C$4:$E$4, 0))=1, 0, MAX(0, I33 * INDEX(ASSUMPTIONS!$C$6:$E$6, 1, MATCH(ASSUMPTIONS!$C$2, ASSUMPTIONS!$C$4:$E$4, 0)))) | J34: =IF(INDEX(ASSUMPTIONS!$C$7:$E$7, 1, MATCH(ASSUMPTIONS!$C$2, ASSUMPTIONS!$C$4:$E$4, 0))=1, 0, MAX(0, J33 * INDEX(ASSUMPTIONS!$C$6:$E$6, 1, MATCH(ASSUMPTIONS!$C$2, ASSUMPTIONS!$C$4:$E$4, 0)))) | ... N34: =IF(INDEX(ASSUMPTIONS!$C$7:$E$7, 1, MATCH(ASSUMPTIONS!$C$2, ASSUMPTIONS!$C$4:$E$4, 0))=1, 0, MAX(0, N33 * INDEX(ASSUMPTIONS!$C$6:$E$6, 1, MATCH(ASSUMPTIONS!$C$2, ASSUMPTIONS!$C$4:$E$4, 0)))) | O34: =MAX(0, O33 * INDEX(ASSUMPTIONS!$C$6:$E$6, 1, MATCH(ASSUMPTIONS!$C$2, ASSUMPTIONS!$C$4:$E$4, 0))) | P34: =MAX(0, P33 * INDEX(ASSUMPTIONS!$C$6:$E$6, 1, MATCH(ASSUMPTIONS!$C$2, ASSUMPTIONS!$C$4:$E$4, 0))) | Q34: =MAX(0, Q33 * INDEX(ASSUMPTIONS!$C$6:$E$6, 1, MATCH(ASSUMPTIONS!$C$2, ASSUMPTIONS!$C$4:$E$4, 0))) | R34: =MAX(0, R33 * INDEX(ASSUMPTIONS!$C$6:$E$6, 1, MATCH(ASSUMPTIONS!$C$2, ASSUMPTIONS!$C$4:$E$4, 0))) | S34: =MAX(0, S33 * INDEX(ASSUMPTIONS!$C$6:$E$6, 1, MATCH(ASSUMPTIONS!$C$2, ASSUMPTIONS!$C$4:$E$4, 0))) | T34: =MAX(0, T33 * INDEX(ASSUMPTIONS!$C$6:$E$6, 1, MATCH(ASSUMPTIONS!$C$2, ASSUMPTIONS!$C$4:$E$4, 0))) | U34: =MAX(0, U33 * INDEX(ASSUMPTIONS!$C$6:$E$6, 1, MATCH(ASSUMPTIONS!$C$2, ASSUMPTIONS!$C$4:$E$4, 0))) | V34: =MAX(0, V33 * INDEX(ASSUMPTIONS!$C$6:$E$6, 1, MATCH(ASSUMPTIONS!$C$2, ASSUMPTIONS!$C$4:$E$4, 0)))
B35: 11. PAT | C35: =C33-C34 | D35: =D33-D34 | E35: =E33-E34 | F35: =F33-F34 | G35: =G33-G34 | H35: =H33-H34 | I35: =I33-I34 | J35: =J33-J34 | ... V35: =V33-V34
B36: C. PAT % | C36: =IF(C23>0, C35/C23, 0) | D36: =IF(D23>0, D35/D23, 0) | E36: =IF(E23>0, E35/E23, 0) | F36: =IF(F23>0, F35/F23, 0) | G36: =IF(G23>0, G35/G23, 0) | H36: =IF(H23>0, H35/H23, 0) | I36: =IF(I23>0, I35/I23, 0) | J36: =IF(J23>0, J35/J23, 0) | ... V36: =IF(V23>0, V35/V23, 0)
B38: WORST CASE
B39: Particulars | C39: Q1 | D39: Q2 | E39: Q3 | F39: Q4 | G39: Q5 | H39: Q6 | I39: Q7 | J39: Q8 | K39: Q9 | L39: Q10 | M39: Q11 | N39: Q12 | O39: Q13 | P39: Q14 | Q39: Q15 | R39: Q16 | S39: Q17 | T39: Q18 | U39: Q19 | V39: Q20
B40: 1. Total Revenue | C40: 157500 | D40: 165375 | E40: 173643.75 | F40: 182325.94 | G40: 191442.23 | H40: 201014.35 | I40: 211065.06 | J40: 221618.32 | K40: 232699.23 | L40: 244334.19 | M40: 256550.9 | N40: 269378.45 | O40: 282847.37 | P40: 296989.74 | Q40: 311839.23 | R40: 327431.19 | S40: 343802.75 | T40: 360992.89 | U40: 379042.53 | V40: 397994.66
